Workbook
Name __ISC01: #REF!
Name __ISC01: #REF!
Name __ISC2: #REF!
Name __ISC2: #REF!
Name __ISC3: #REF!+#REF!
Name __ISC3: #REF!+#REF!
Name __ISC567: #REF!
Name __ISC567: #REF!
Name _10000: #REF!
Name _10000: #REF!
Name _10000: #REF!
Name _10000: #REF!
Name _1080: #REF!
Name _1080: #REF!
Name _1080: #REF!
Name _1080: #REF!
Name _1090: #REF!
Name _1090: #REF!
Name _1090: #REF!
Name _1090: #REF!
Name _1100: #REF!
Name _1100: #REF!
Name _1100: #REF!
Name _1100: #REF!
Name _1110: #REF!
Name _1110: #REF!
Name _1110: #REF!
Name _1110: #REF!
Name _2: #REF!
Name _2: #REF!
Name _2: #REF!
Name _2: #REF!
Name _2010: #REF!
Name _2010: #REF!
Name _2010: #REF!
Name _2010: #REF!
Name _2080: #REF!
Name _2080: #REF!
Name _2080: #REF!
Name _2080: #REF!
Name _2090: #REF!
Name _2090: #REF!
Name _2090: #REF!
Name _2090: #REF!
Name _2100: #REF!
Name _2100: #REF!
Name _2100: #REF!
Name _2100: #REF!
Name _2110: #REF!
Name _2110: #REF!
Name _2110: #REF!
Name _2110: #REF!
Name _3080: #REF!
Name _3080: #REF!
Name _3080: #REF!
Name _3080: #REF!
Name _3090: #REF!
Name _3090: #REF!
Name _3090: #REF!
Name _3090: #REF!

Sheet E5t_fix
A1: Income Tax Schedules (Effective Tax Rates): Series for Stata Import | O1: After-tax income | AB1: Marginal tax rates
AA2: Non-monotonic marginal tax rates
A3: year | B3: ty1 | C3: ty2 | D3: ty3 | E3: ty4 | F3: ty5 | G3: ty6 | H3: ty7 | I3: ty8 | J3: ty9 | K3: ty10 | L3: ty11 | M3: ty12
A4: 2026 | B4: =TE5f!$C7 -> 0 | C4: =TE5f!$C8 -> 0 | D4: =TE5f!$C9 -> 0.05 | E4: =TE5f!$C10 -> 0.1 | F4: =TE5f!$C11 -> 0.15 | G4: =TE5f!$C12 -> 0.2 | H4: =TE5f!$C13 -> 0.4 | I4: =TE5f!$C14 -> 0.5 | J4: =TE5f!$C15 -> 0.6 | K4: =TE5f!$C16 -> 0.7 | L4: =TE5f!$C17 -> 0.8 | M4: =TE5f!$C18 -> 0.9 | O4: =(1-B4)*E4b!B4 -> 5 | P4: =(1-C4)*E5b!C4 -> 7 | Q4: =(1-D4)*E5b!D4 -> 9.5 | R4: =(1-E4)*E5b!E4 -> 10.8 | S4: =(1-F4)*E5b!F4 -> 12.75 | T4: =(1-G4)*E5b!G4 -> 16 | U4: =(1-H4)*E5b!H4 -> 30 | V4: =(1-I4)*E5b!I4 -> 50 | W4: =(1-J4)*E5b!J4 -> 80 | ... Z4: =(1-M4)*E5b!M4 -> 500 | AB4: =(E5b!C4-P4-(E5b!B4-O4))/(E5b!C4-E5b!B4) -> 0 | AC4: =(E5b!D4-Q4-(E5b!C4-P4))/(E5b!D4-E5b!C4) -> 0.16666667 | AD4: =(E5b!E4-R4-(E5b!D4-Q4))/(E5b!E4-E5b!D4) -> 0.35 | AE4: =(E5b!F4-S4-(E5b!E4-R4))/(E5b!F4-E5b!E4) -> 0.35 | AF4: =(E5b!G4-T4-(E5b!F4-S4))/(E5b!G4-E5b!F4) -> 0.35 | AG4: =(E5b!H4-U4-(E5b!G4-T4))/(E5b!H4-E5b!G4) -> 0.53333333 | AH4: =(E5b!I4-V4-(E5b!H4-U4))/(E5b!I4-E5b!H4) -> 0.6 | AI4: =(E5b!J4-W4-(E5b!I4-V4))/(E5b!J4-E5b!I4) -> 0.7 | ... AL4: =(E5b!M4-Z4-(E5b!L4-Y4))/(E5b!M4-E5b!L4) -> 0.925
A5: 2027 | B5: =B4+(B$13-B$4)/9 -> 0 | C5: =C4+(C$13-C$4)/9 -> 0 | D5: =D4+(D$13-D$4)/9 -> 0.061111111 | E5: =E4+(E$13-E$4)/9 -> 0.11111111 | F5: =F4+(F$13-F$4)/9 -> 0.16111111 | G5: =G4+(G$13-G$4)/9 -> 0.21111111 | H5: =H4+(H$13-H$4)/9 -> 0.4 | I5: =I4+(I$13-I$4)/9 -> 0.5 | ... M5: =M4+(M$13-M$4)/9 -> 0.9 | O5: =(1-B5)*E5b!B5 -> 4.8888889 | P5: =(1-C5)*E5b!C5 -> 6.8888889 | Q5: =(1-D5)*E5b!D5 -> 9.1802469 | R5: =(1-E5)*E5b!E5 -> 10.469136 | S5: =(1-F5)*E5b!F5 -> 12.583333 | T5: =(1-G5)*E5b!G5 -> 15.777778 | U5: =(1-H5)*E5b!H5 -> 30 | V5: =(1-I5)*E5b!I5 -> 50 | ... Z5: =(1-M5)*E5b!M5 -> 500 | AA5: 1 | AB5: =(E5b!C5-P5-(E5b!B5-O5))/(E5b!C5-E5b!B5) -> 0 | AC5: =(E5b!D5-Q5-(E5b!C5-P5))/(E5b!D5-E5b!C5) -> 0.20683761 | AD5: =(E5b!E5-R5-(E5b!D5-Q5))/(E5b!E5-E5b!D5) -> 0.35555556 | AE5: =(E5b!F5-S5-(E5b!E5-R5))/(E5b!F5-E5b!E5) -> 0.34386973 | AF5: =(E5b!G5-T5-(E5b!F5-S5))/(E5b!G5-E5b!F5) -> 0.36111111 | AG5: =(E5b!H5-U5-(E5b!G5-T5))/(E5b!H5-E5b!G5) -> 0.52592593 | AH5: =(E5b!I5-V5-(E5b!H5-U5))/(E5b!I5-E5b!H5) -> 0.6 | AI5: =(E5b!J5-W5-(E5b!I5-V5))/(E5b!J5-E5b!I5) -> 0.7 | ... AL5: =(E5b!M5-Z5-(E5b!L5-Y5))/(E5b!M5-E5b!L5) -> 0.925
A6: 2028 | B6: =B5+(B$13-B$4)/9 -> 0 | C6: =C5+(C$13-C$4)/9 -> 0 | D6: =D5+(D$13-D$4)/9 -> 0.072222222 | E6: =E5+(E$13-E$4)/9 -> 0.12222222 | F6: =F5+(F$13-F$4)/9 -> 0.17222222 | G6: =G5+(G$13-G$4)/9 -> 0.22222222 | H6: =H5+(H$13-H$4)/9 -> 0.4 | I6: =I5+(I$13-I$4)/9 -> 0.5 | ... M6: =M5+(M$13-M$4)/9 -> 0.9 | O6: =(1-B6)*E5b!B6 -> 4.7777778 | P6: =(1-C6)*E5b!C6 -> 6.7777778 | Q6: =(1-D6)*E5b!D6 -> 8.8654321 | R6: =(1-E6)*E5b!E6 -> 10.14321 | S6: =(1-F6)*E5b!F6 -> 12.416667 | T6: =(1-G6)*E5b!G6 -> 15.555556 | U6: =(1-H6)*E5b!H6 -> 30 | V6: =(1-I6)*E5b!I6 -> 50 | ... Z6: =(1-M6)*E5b!M6 -> 500 | AA6: 1 | AB6: =(E5b!C6-P6-(E5b!B6-O6))/(E5b!C6-E5b!B6) -> 0 | AC6: =(E5b!D6-Q6-(E5b!C6-P6))/(E5b!D6-E5b!C6) -> 0.24844444 | AD6: =(E5b!E6-R6-(E5b!D6-Q6))/(E5b!E6-E5b!D6) -> 0.36111111 | AE6: =(E5b!F6-S6-(E5b!E6-R6))/(E5b!F6-E5b!E6) -> 0.33996416 | AF6: =(E5b!G6-T6-(E5b!F6-S6))/(E5b!G6-E5b!F6) -> 0.37222222 | AG6: =(E5b!H6-U6-(E5b!G6-T6))/(E5b!H6-E5b!G6) -> 0.51851852 | AH6: =(E5b!I6-V6-(E5b!H6-U6))/(E5b!I6-E5b!H6) -> 0.6 | AI6: =(E5b!J6-W6-(E5b!I6-V6))/(E5b!J6-E5b!I6) -> 0.7 | ... AL6: =(E5b!M6-Z6-(E5b!L6-Y6))/(E5b!M6-E5b!L6) -> 0.925
A7: 2029 | B7: =B6+(B$13-B$4)/9 -> 0 | C7: =C6+(C$13-C$4)/9 -> 0 | D7: =D6+(D$13-D$4)/9 -> 0.083333333 | E7: =E6+(E$13-E$4)/9 -> 0.13333333 | F7: =F6+(F$13-F$4)/9 -> 0.18333333 | G7: =G6+(G$13-G$4)/9 -> 0.23333333 | H7: =H6+(H$13-H$4)/9 -> 0.4 | I7: =I6+(I$13-I$4)/9 -> 0.5 | ... M7: =M6+(M$13-M$4)/9 -> 0.9 | O7: =(1-B7)*E5b!B7 -> 4.6666667 | P7: =(1-C7)*E5b!C7 -> 6.6666667 | Q7: =(1-D7)*E5b!D7 -> 8.5555556 | R7: =(1-E7)*E5b!E7 -> 9.8222222 | S7: =(1-F7)*E5b!F7 -> 12.25 | T7: =(1-G7)*E5b!G7 -> 15.333333 | U7: =(1-H7)*E5b!H7 -> 30 | V7: =(1-I7)*E5b!I7 -> 50 | ... Z7: =(1-M7)*E5b!M7 -> 500 | AA7: 1 | AB7: =(E5b!C7-P7-(E5b!B7-O7))/(E5b!C7-E5b!B7) -> 0 | AC7: =(E5b!D7-Q7-(E5b!C7-P7))/(E5b!D7-E5b!C7) -> 0.29166667 | AD7: =(E5b!E7-R7-(E5b!D7-Q7))/(E5b!E7-E5b!D7) -> 0.36666667 | AE7: =(E5b!F7-S7-(E5b!E7-R7))/(E5b!F7-E5b!E7) -> 0.33787879 | AF7: =(E5b!G7-T7-(E5b!F7-S7))/(E5b!G7-E5b!F7) -> 0.38333333 | AG7: =(E5b!H7-U7-(E5b!G7-T7))/(E5b!H7-E5b!G7) -> 0.51111111 | AH7: =(E5b!I7-V7-(E5b!H7-U7))/(E5b!I7-E5b!H7) -> 0.6 | AI7: =(E5b!J7-W7-(E5b!I7-V7))/(E5b!J7-E5b!I7) -> 0.7 | ... AL7: =(E5b!M7-Z7-(E5b!L7-Y7))/(E5b!M7-E5b!L7) -> 0.925
A8: 2030 | B8: =B7+(B$13-B$4)/9 -> 0 | C8: =C7+(C$13-C$4)/9 -> 0 | D8: =D7+(D$13-D$4)/9 -> 0.094444444 | E8: =E7+(E$13-E$4)/9 -> 0.14444444 | F8: =F7+(F$13-F$4)/9 -> 0.19444444 | G8: =G7+(G$13-G$4)/9 -> 0.24444444 | H8: =H7+(H$13-H$4)/9 -> 0.4 | I8: =I7+(I$13-I$4)/9 -> 0.5 | ... M8: =M7+(M$13-M$4)/9 -> 0.9 | O8: =(1-B8)*E5b!B8 -> 4.5555556 | P8: =(1-C8)*E5b!C8 -> 6.5555556 | Q8: =(1-D8)*E5b!D8 -> 8.2506173 | R8: =(1-E8)*E5b!E8 -> 9.5061728 | S8: =(1-F8)*E5b!F8 -> 12.083333 | T8: =(1-G8)*E5b!G8 -> 15.111111 | U8: =(1-H8)*E5b!H8 -> 30 | V8: =(1-I8)*E5b!I8 -> 50 | ... Z8: =(1-M8)*E5b!M8 -> 500 | AA8: 1 | AB8: =(E5b!C8-P8-(E5b!B8-O8))/(E5b!C8-E5b!B8) -> 0 | AC8: =(E5b!D8-Q8-(E5b!C8-P8))/(E5b!D8-E5b!C8) -> 0.33671498 | AD8: =(E5b!E8-R8-(E5b!D8-Q8))/(E5b!E8-E5b!D8) -> 0.37222222 | AE8: =(E5b!F8-S8-(E5b!E8-R8))/(E5b!F8-E5b!E8) -> 0.33730159 | AF8: =(E5b!G8-T8-(E5b!F8-S8))/(E5b!G8-E5b!F8) -> 0.39444444 | AG8: =(E5b!H8-U8-(E5b!G8-T8))/(E5b!H8-E5b!G8) -> 0.5037037 | AH8: =(E5b!I8-V8-(E5b!H8-U8))/(E5b!I8-E5b!H8) -> 0.6 | AI8: =(E5b!J8-W8-(E5b!I8-V8))/(E5b!J8-E5b!I8) -> 0.7 | ... AL8: =(E5b!M8-Z8-(E5b!L8-Y8))/(E5b!M8-E5b!L8) -> 0.925
A9: 2031 | B9: =B8+(B$13-B$4)/9 -> 0 | C9: =C8+(C$13-C$4)/9 -> 0 | D9: =D8+(D$13-D$4)/9 -> 0.10555556 | E9: =E8+(E$13-E$4)/9 -> 0.15555556 | F9: =F8+(F$13-F$4)/9 -> 0.20555556 | G9: =G8+(G$13-G$4)/9 -> 0.25555556 | H9: =H8+(H$13-H$4)/9 -> 0.4 | I9: =I8+(I$13-I$4)/9 -> 0.5 | ... M9: =M8+(M$13-M$4)/9 -> 0.9 | O9: =(1-B9)*E5b!B9 -> 4.4444444 | P9: =(1-C9)*E5b!C9 -> 6.4444444 | Q9: =(1-D9)*E5b!D9 -> 7.9506173 | R9: =(1-E9)*E5b!E9 -> 9.1950617 | S9: =(1-F9)*E5b!F9 -> 11.916667 | T9: =(1-G9)*E5b!G9 -> 14.888889 | U9: =(1-H9)*E5b!H9 -> 30 | V9: =(1-I9)*E5b!I9 -> 50 | ... Z9: =(1-M9)*E5b!M9 -> 500 | AA9: 1 | AB9: =(E5b!C9-P9-(E5b!B9-O9))/(E5b!C9-E5b!B9) -> 0 | AC9: =(E5b!D9-Q9-(E5b!C9-P9))/(E5b!D9-E5b!C9) -> 0.38383838 | AD9: =(E5b!E9-R9-(E5b!D9-Q9))/(E5b!E9-E5b!D9) -> 0.37777778 | AE9: =(E5b!F9-S9-(E5b!E9-R9))/(E5b!F9-E5b!E9) -> 0.33798799 | AF9: =(E5b!G9-T9-(E5b!F9-S9))/(E5b!G9-E5b!F9) -> 0.40555556 | AG9: =(E5b!H9-U9-(E5b!G9-T9))/(E5b!H9-E5b!G9) -> 0.4962963 | AH9: =(E5b!I9-V9-(E5b!H9-U9))/(E5b!I9-E5b!H9) -> 0.6 | AI9: =(E5b!J9-W9-(E5b!I9-V9))/(E5b!J9-E5b!I9) -> 0.7 | ... AL9: =(E5b!M9-Z9-(E5b!L9-Y9))/(E5b!M9-E5b!L9) -> 0.925
A10: 2032 | B10: =B9+(B$13-B$4)/9 -> 0 | C10: =C9+(C$13-C$4)/9 -> 0 | D10: =D9+(D$13-D$4)/9 -> 0.11666667 | E10: =E9+(E$13-E$4)/9 -> 0.16666667 | F10: =F9+(F$13-F$4)/9 -> 0.21666667 | G10: =G9+(G$13-G$4)/9 -> 0.26666667 | H10: =H9+(H$13-H$4)/9 -> 0.4 | I10: =I9+(I$13-I$4)/9 -> 0.5 | ... M10: =M9+(M$13-M$4)/9 -> 0.9 | O10: =(1-B10)*E5b!B10 -> 4.3333333 | P10: =(1-C10)*E5b!C10 -> 6.3333333 | Q10: =(1-D10)*E5b!D10 -> 7.6555556 | R10: =(1-E10)*E5b!E10 -> 8.8888889 | S10: =(1-F10)*E5b!F10 -> 11.75 | T10: =(1-G10)*E5b!G10 -> 14.666667 | U10: =(1-H10)*E5b!H10 -> 30 | V10: =(1-I10)*E5b!I10 -> 50 | ... Z10: =(1-M10)*E5b!M10 -> 500 | AA10: 2 | AB10: =(E5b!C10-P10-(E5b!B10-O10))/(E5b!C10-E5b!B10) -> 0 | AC10: =(E5b!D10-Q10-(E5b!C10-P10))/(E5b!D10-E5b!C10) -> 0.43333333 | AD10: =(E5b!E10-R10-(E5b!D10-Q10))/(E5b!E10-E5b!D10) -> 0.38333333 | AE10: =(E5b!F10-S10-(E5b!E10-R10))/(E5b!F10-E5b!E10) -> 0.33974359 | AF10: =(E5b!G10-T10-(E5b!F10-S10))/(E5b!G10-E5b!F10) -> 0.41666667 | AG10: =(E5b!H10-U10-(E5b!G10-T10))/(E5b!H10-E5b!G10) -> 0.48888889 | AH10: =(E5b!I10-V10-(E5b!H10-U10))/(E5b!I10-E5b!H10) -> 0.6 | AI10: =(E5b!J10-W10-(E5b!I10-V10))/(E5b!J10-E5b!I10) -> 0.7 | ... AL10: =(E5b!M10-Z10-(E5b!L10-Y10))/(E5b!M10-E5b!L10) -> 0.925
A11: 2033 | B11: =B10+(B$13-B$4)/9 -> 0 | C11: =C10+(C$13-C$4)/9 -> 0 | D11: =D10+(D$13-D$4)/9 -> 0.12777778 | E11: =E10+(E$13-E$4)/9 -> 0.17777778 | F11: =F10+(F$13-F$4)/9 -> 0.22777778 | G11: =G10+(G$13-G$4)/9 -> 0.27777778 | H11: =H10+(H$13-H$4)/9 -> 0.4 | I11: =I10+(I$13-I$4)/9 -> 0.5 | ... M11: =M10+(M$13-M$4)/9 -> 0.9 | O11: =(1-B11)*E5b!B11 -> 4.2222222 | P11: =(1-C11)*E5b!C11 -> 6.2222222 | Q11: =(1-D11)*E5b!D11 -> 7.3654321 | R11: =(1-E11)*E5b!E11 -> 8.5876543 | S11: =(1-F11)*E5b!F11 -> 11.583333 | T11: =(1-G11)*E5b!G11 -> 14.444444 | U11: =(1-H11)*E5b!H11 -> 30 | V11: =(1-I11)*E5b!I11 -> 50 | ... Z11: =(1-M11)*E5b!M11 -> 500 | AA11: 2 | AB11: =(E5b!C11-P11-(E5b!B11-O11))/(E5b!C11-E5b!B11) -> 0 | AC11: =(E5b!D11-Q11-(E5b!C11-P11))/(E5b!D11-E5b!C11) -> 0.48555556 | AD11: =(E5b!E11-R11-(E5b!D11-Q11))/(E5b!E11-E5b!D11) -> 0.38888889 | AE11: =(E5b!F11-S11-(E5b!E11-R11))/(E5b!F11-E5b!E11) -> 0.34241192 | AF11: =(E5b!G11-T11-(E5b!F11-S11))/(E5b!G11-E5b!F11) -> 0.42777778 | AG11: =(E5b!H11-U11-(E5b!G11-T11))/(E5b!H11-E5b!G11) -> 0.48148148 | AH11: =(E5b!I11-V11-(E5b!H11-U11))/(E5b!I11-E5b!H11) -> 0.6 | AI11: =(E5b!J11-W11-(E5b!I11-V11))/(E5b!J11-E5b!I11) -> 0.7 | ... AL11: =(E5b!M11-Z11-(E5b!L11-Y11))/(E5b!M11-E5b!L11) -> 0.925
A12: 2034 | B12: =B11+(B$13-B$4)/9 -> 0 | C12: =C11+(C$13-C$4)/9 -> 0 | D12: =D11+(D$13-D$4)/9 -> 0.13888889 | E12: =E11+(E$13-E$4)/9 -> 0.18888889 | F12: =F11+(F$13-F$4)/9 -> 0.23888889 | G12: =G11+(G$13-G$4)/9 -> 0.28888889 | H12: =H11+(H$13-H$4)/9 -> 0.4 | I12: =I11+(I$13-I$4)/9 -> 0.5 | ... M12: =M11+(M$13-M$4)/9 -> 0.9 | O12: =(1-B12)*E5b!B12 -> 4.1111111 | P12: =(1-C12)*E5b!C12 -> 6.1111111 | Q12: =(1-D12)*E5b!D12 -> 7.0802469 | R12: =(1-E12)*E5b!E12 -> 8.291358 | S12: =(1-F12)*E5b!F12 -> 11.416667 | T12: =(1-G12)*E5b!G12 -> 14.222222 | U12: =(1-H12)*E5b!H12 -> 30 | V12: =(1-I12)*E5b!I12 -> 50 | ... Z12: =(1-M12)*E5b!M12 -> 500 | AA12: 2 | AB12: =(E5b!C12-P12-(E5b!B12-O12))/(E5b!C12-E5b!B12) -> 0 | AC12: =(E5b!D12-Q12-(E5b!C12-P12))/(E5b!D12-E5b!C12) -> 0.54093567 | AD12: =(E5b!E12-R12-(E5b!D12-Q12))/(E5b!E12-E5b!D12) -> 0.39444444 | AE12: =(E5b!F12-S12-(E5b!E12-R12))/(E5b!F12-E5b!E12) -> 0.34586563 | AF12: =(E5b!G12-T12-(E5b!F12-S12))/(E5b!G12-E5b!F12) -> 0.43888889 | AG12: =(E5b!H12-U12-(E5b!G12-T12))/(E5b!H12-E5b!G12) -> 0.47407407 | AH12: =(E5b!I12-V12-(E5b!H12-U12))/(E5b!I12-E5b!H12) -> 0.6 | AI12: =(E5b!J12-W12-(E5b!I12-V12))/(E5b!J12-E5b!I12) -> 0.7 | ... AL12: =(E5b!M12-Z12-(E5b!L12-Y12))/(E5b!M12-E5b!L12) -> 0.925
A13: 2035 | B13: 0 | C13: 0 | D13: 0.15 | E13: 0.2 | F13: 0.25 | G13: 0.3 | H13: 0.4 | I13: 0.5 | J13: 0.6 | K13: 0.7 | L13: 0.8 | M13: 0.9 | O13: =(1-B13)*E5b!B13 -> 4 | P13: =(1-C13)*E5b!C13 -> 6 | Q13: =(1-D13)*E5b!D13 -> 6.8 | R13: =(1-E13)*E5b!E13 -> 8 | S13: =(1-F13)*E5b!F13 -> 11.25 | T13: =(1-G13)*E5b!G13 -> 14 | U13: =(1-H13)*E5b!H13 -> 30 | V13: =(1-I13)*E5b!I13 -> 50 | ... Z13: =(1-M13)*E5b!M13 -> 500 | AA13: 2 | AB13: =(E5b!C13-P13-(E5b!B13-O13))/(E5b!C13-E5b!B13) -> 0 | AC13: =(E5b!D13-Q13-(E5b!C13-P13))/(E5b!D13-E5b!C13) -> 0.6 | AD13: =(E5b!E13-R13-(E5b!D13-Q13))/(E5b!E13-E5b!D13) -> 0.4 | AE13: =(E5b!F13-S13-(E5b!E13-R13))/(E5b!F13-E5b!E13) -> 0.35 | AF13: =(E5b!G13-T13-(E5b!F13-S13))/(E5b!G13-E5b!F13) -> 0.45 | AG13: =(E5b!H13-U13-(E5b!G13-T13))/(E5b!H13-E5b!G13) -> 0.46666667 | AH13: =(E5b!I13-V13-(E5b!H13-U13))/(E5b!I13-E5b!H13) -> 0.6 | AI13: =(E5b!J13-W13-(E5b!I13-V13))/(E5b!J13-E5b!I13) -> 0.7 | ... AL13: =(E5b!M13-Z13-(E5b!L13-Y13))/(E5b!M13-E5b!L13) -> 0.925
A14: 2036 | B14: =B13+(B$28-B$13)/15 -> 0 | C14: =C13+(C$28-C$13)/15 -> 0 | D14: =D13+(D$28-D$13)/15 -> 0.15 | E14: =E13+(E$28-E$13)/15 -> 0.2 | F14: =F13+(F$28-F$13)/15 -> 0.25 | G14: =G13+(G$28-G$13)/15 -> 0.3 | H14: =H13+(H$28-H$13)/15 -> 0.4 | I14: =I13+(I$28-I$13)/15 -> 0.5 | ... M14: =M13+(M$28-M$13)/15 -> 0.9 | O14: =(1-B14)*E5b!B14 -> 3.9333333 | P14: =(1-C14)*E5b!C14 -> 5.8666667 | Q14: =(1-D14)*E5b!D14 -> 6.6866667 | R14: =(1-E14)*E5b!E14 -> 7.8933333 | S14: =(1-F14)*E5b!F14 -> 11.1 | T14: =(1-G14)*E5b!G14 -> 14 | U14: =(1-H14)*E5b!H14 -> 30 | V14: =(1-I14)*E5b!I14 -> 50 | ... Z14: =(1-M14)*E5b!M14 -> 500 | AA14: 2 | AB14: =(E5b!C14-P14-(E5b!B14-O14))/(E5b!C14-E5b!B14) -> 0 | AC14: =(E5b!D14-Q14-(E5b!C14-P14))/(E5b!D14-E5b!C14) -> 0.59 | AD14: =(E5b!E14-R14-(E5b!D14-Q14))/(E5b!E14-E5b!D14) -> 0.39666667 | AE14: =(E5b!F14-S14-(E5b!E14-R14))/(E5b!F14-E5b!E14) -> 0.35 | AF14: =(E5b!G14-T14-(E5b!F14-S14))/(E5b!G14-E5b!F14) -> 0.44230769 | AG14: =(E5b!H14-U14-(E5b!G14-T14))/(E5b!H14-E5b!G14) -> 0.46666667 | AH14: =(E5b!I14-V14-(E5b!H14-U14))/(E5b!I14-E5b!H14) -> 0.6 | AI14: =(E5b!J14-W14-(E5b!I14-V14))/(E5b!J14-E5b!I14) -> 0.7 | ... AL14: =(E5b!M14-Z14-(E5b!L14-Y14))/(E5b!M14-E5b!L14) -> 0.925
A15: 2037 | B15: =B14+(B$28-B$13)/15 -> 0 | C15: =C14+(C$28-C$13)/15 -> 0 | D15: =D14+(D$28-D$13)/15 -> 0.15 | E15: =E14+(E$28-E$13)/15 -> 0.2 | F15: =F14+(F$28-F$13)/15 -> 0.25 | G15: =G14+(G$28-G$13)/15 -> 0.3 | H15: =H14+(H$28-H$13)/15 -> 0.4 | I15: =I14+(I$28-I$13)/15 -> 0.5 | ... M15: =M14+(M$28-M$13)/15 -> 0.9 | O15: =(1-B15)*E5b!B15 -> 3.8666667 | P15: =(1-C15)*E5b!C15 -> 5.7333333 | Q15: =(1-D15)*E5b!D15 -> 6.5733333 | R15: =(1-E15)*E5b!E15 -> 7.7866667 | S15: =(1-F15)*E5b!F15 -> 10.95 | T15: =(1-G15)*E5b!G15 -> 14 | U15: =(1-H15)*E5b!H15 -> 30 | V15: =(1-I15)*E5b!I15 -> 50 | ... Z15: =(1-M15)*E5b!M15 -> 500 | AA15: 2 | AB15: =(E5b!C15-P15-(E5b!B15-O15))/(E5b!C15-E5b!B15) -> 0 | AC15: =(E5b!D15-Q15-(E5b!C15-P15))/(E5b!D15-E5b!C15) -> 0.58 | AD15: =(E5b!E15-R15-(E5b!D15-Q15))/(E5b!E15-E5b!D15) -> 0.39333333 | AE15: =(E5b!F15-S15-(E5b!E15-R15))/(E5b!F15-E5b!E15) -> 0.35 | AF15: =(E5b!G15-T15-(E5b!F15-S15))/(E5b!G15-E5b!F15) -> 0.43518519 | AG15: =(E5b!H15-U15-(E5b!G15-T15))/(E5b!H15-E5b!G15) -> 0.46666667 | AH15: =(E5b!I15-V15-(E5b!H15-U15))/(E5b!I15-E5b!H15) -> 0.6 | AI15: =(E5b!J15-W15-(E5b!I15-V15))/(E5b!J15-E5b!I15) -> 0.7 | ... AL15: =(E5b!M15-Z15-(E5b!L15-Y15))/(E5b!M15-E5b!L15) -> 0.925
A16: 2038 | B16: =B15+(B$28-B$13)/15 -> 0 | C16: =C15+(C$28-C$13)/15 -> 0 | D16: =D15+(D$28-D$13)/15 -> 0.15 | E16: =E15+(E$28-E$13)/15 -> 0.2 | F16: =F15+(F$28-F$13)/15 -> 0.25 | G16: =G15+(G$28-G$13)/15 -> 0.3 | H16: =H15+(H$28-H$13)/15 -> 0.4 | I16: =I15+(I$28-I$13)/15 -> 0.5 | ... M16: =M15+(M$28-M$13)/15 -> 0.9 | O16: =(1-B16)*E5b!B16 -> 3.8 | P16: =(1-C16)*E5b!C16 -> 5.6 | Q16: =(1-D16)*E5b!D16 -> 6.46 | R16: =(1-E16)*E5b!E16 -> 7.68 | S16: =(1-F16)*E5b!F16 -> 10.8 | T16: =(1-G16)*E5b!G16 -> 14 | U16: =(1-H16)*E5b!H16 -> 30 | V16: =(1-I16)*E5b!I16 -> 50 | ... Z16: =(1-M16)*E5b!M16 -> 500 | AA16: 2 | AB16: =(E5b!C16-P16-(E5b!B16-O16))/(E5b!C16-E5b!B16) -> 0 | AC16: =(E5b!D16-Q16-(E5b!C16-P16))/(E5b!D16-E5b!C16) -> 0.57 | AD16: =(E5b!E16-R16-(E5b!D16-Q16))/(E5b!E16-E5b!D16) -> 0.39 | AE16: =(E5b!F16-S16-(E5b!E16-R16))/(E5b!F16-E5b!E16) -> 0.35 | AF16: =(E5b!G16-T16-(E5b!F16-S16))/(E5b!G16-E5b!F16) -> 0.42857143 | AG16: =(E5b!H16-U16-(E5b!G16-T16))/(E5b!H16-E5b!G16) -> 0.46666667 | AH16: =(E5b!I16-V16-(E5b!H16-U16))/(E5b!I16-E5b!H16) -> 0.6 | AI16: =(E5b!J16-W16-(E5b!I16-V16))/(E5b!J16-E5b!I16) -> 0.7 | ... AL16: =(E5b!M16-Z16-(E5b!L16-Y16))/(E5b!M16-E5b!L16) -> 0.925
A17: 2039 | B17: =B16+(B$28-B$13)/15 -> 0 | C17: =C16+(C$28-C$13)/15 -> 0 | D17: =D16+(D$28-D$13)/15 -> 0.15 | E17: =E16+(E$28-E$13)/15 -> 0.2 | F17: =F16+(F$28-F$13)/15 -> 0.25 | G17: =G16+(G$28-G$13)/15 -> 0.3 | H17: =H16+(H$28-H$13)/15 -> 0.4 | I17: =I16+(I$28-I$13)/15 -> 0.5 | ... M17: =M16+(M$28-M$13)/15 -> 0.9 | O17: =(1-B17)*E5b!B17 -> 3.7333333 | P17: =(1-C17)*E5b!C17 -> 5.4666667 | Q17: =(1-D17)*E5b!D17 -> 6.3466667 | R17: =(1-E17)*E5b!E17 -> 7.5733333 | S17: =(1-F17)*E5b!F17 -> 10.65 | T17: =(1-G17)*E5b!G17 -> 14 | U17: =(1-H17)*E5b!H17 -> 30 | V17: =(1-I17)*E5b!I17 -> 50 | ... Z17: =(1-M17)*E5b!M17 -> 500 | AA17: 2 | AB17: =(E5b!C17-P17-(E5b!B17-O17))/(E5b!C17-E5b!B17) -> 0 | AC17: =(E5b!D17-Q17-(E5b!C17-P17))/(E5b!D17-E5b!C17) -> 0.56 | AD17: =(E5b!E17-R17-(E5b!D17-Q17))/(E5b!E17-E5b!D17) -> 0.38666667 | AE17: =(E5b!F17-S17-(E5b!E17-R17))/(E5b!F17-E5b!E17) -> 0.35 | AF17: =(E5b!G17-T17-(E5b!F17-S17))/(E5b!G17-E5b!F17) -> 0.42241379 | AG17: =(E5b!H17-U17-(E5b!G17-T17))/(E5b!H17-E5b!G17) -> 0.46666667 | AH17: =(E5b!I17-V17-(E5b!H17-U17))/(E5b!I17-E5b!H17) -> 0.6 | AI17: =(E5b!J17-W17-(E5b!I17-V17))/(E5b!J17-E5b!I17) -> 0.7 | ... AL17: =(E5b!M17-Z17-(E5b!L17-Y17))/(E5b!M17-E5b!L17) -> 0.925
A18: 2040 | B18: =B17+(B$28-B$13)/15 -> 0 | C18: =C17+(C$28-C$13)/15 -> 0 | D18: =D17+(D$28-D$13)/15 -> 0.15 | E18: =E17+(E$28-E$13)/15 -> 0.2 | F18: =F17+(F$28-F$13)/15 -> 0.25 | G18: =G17+(G$28-G$13)/15 -> 0.3 | H18: =H17+(H$28-H$13)/15 -> 0.4 | I18: =I17+(I$28-I$13)/15 -> 0.5 | ... M18: =M17+(M$28-M$13)/15 -> 0.9 | O18: =(1-B18)*E5b!B18 -> 3.6666667 | P18: =(1-C18)*E5b!C18 -> 5.3333333 | Q18: =(1-D18)*E5b!D18 -> 6.2333333 | R18: =(1-E18)*E5b!E18 -> 7.4666667 | S18: =(1-F18)*E5b!F18 -> 10.5 | T18: =(1-G18)*E5b!G18 -> 14 | U18: =(1-H18)*E5b!H18 -> 30 | V18: =(1-I18)*E5b!I18 -> 50 | ... Z18: =(1-M18)*E5b!M18 -> 500 | AA18: 2 | AB18: =(E5b!C18-P18-(E5b!B18-O18))/(E5b!C18-E5b!B18) -> 0 | AC18: =(E5b!D18-Q18-(E5b!C18-P18))/(E5b!D18-E5b!C18) -> 0.55 | AD18: =(E5b!E18-R18-(E5b!D18-Q18))/(E5b!E18-E5b!D18) -> 0.38333333 | AE18: =(E5b!F18-S18-(E5b!E18-R18))/(E5b!F18-E5b!E18) -> 0.35 | AF18: =(E5b!G18-T18-(E5b!F18-S18))/(E5b!G18-E5b!F18) -> 0.41666667 | AG18: =(E5b!H18-U18-(E5b!G18-T18))/(E5b!H18-E5b!G18) -> 0.46666667 | AH18: =(E5b!I18-V18-(E5b!H18-U18))/(E5b!I18-E5b!H18) -> 0.6 | AI18: =(E5b!J18-W18-(E5b!I18-V18))/(E5b!J18-E5b!I18) -> 0.7 | ... AL18: =(E5b!M18-Z18-(E5b!L18-Y18))/(E5b!M18-E5b!L18) -> 0.925
A19: 2041 | B19: =B18+(B$28-B$13)/15 -> 0 | C19: =C18+(C$28-C$13)/15 -> 0 | D19: =D18+(D$28-D$13)/15 -> 0.15 | E19: =E18+(E$28-E$13)/15 -> 0.2 | F19: =F18+(F$28-F$13)/15 -> 0.25 | G19: =G18+(G$28-G$13)/15 -> 0.3 | H19: =H18+(H$28-H$13)/15 -> 0.4 | I19: =I18+(I$28-I$13)/15 -> 0.5 | ... M19: =M18+(M$28-M$13)/15 -> 0.9 | O19: =(1-B19)*E5b!B19 -> 3.6 | P19: =(1-C19)*E5b!C19 -> 5.2 | Q19: =(1-D19)*E5b!D19 -> 6.12 | R19: =(1-E19)*E5b!E19 -> 7.36 | S19: =(1-F19)*E5b!F19 -> 10.35 | T19: =(1-G19)*E5b!G19 -> 14 | U19: =(1-H19)*E5b!H19 -> 30 | V19: =(1-I19)*E5b!I19 -> 50 | ... Z19: =(1-M19)*E5b!M19 -> 500 | AA19: 2 | AB19: =(E5b!C19-P19-(E5b!B19-O19))/(E5b!C19-E5b!B19) -> 0 | AC19: =(E5b!D19-Q19-(E5b!C19-P19))/(E5b!D19-E5b!C19) -> 0.54 | AD19: =(E5b!E19-R19-(E5b!D19-Q19))/(E5b!E19-E5b!D19) -> 0.38 | AE19: =(E5b!F19-S19-(E5b!E19-R19))/(E5b!F19-E5b!E19) -> 0.35 | AF19: =(E5b!G19-T19-(E5b!F19-S19))/(E5b!G19-E5b!F19) -> 0.41129032 | AG19: =(E5b!H19-U19-(E5b!G19-T19))/(E5b!H19-E5b!G19) -> 0.46666667 | AH19: =(E5b!I19-V19-(E5b!H19-U19))/(E5b!I19-E5b!H19) -> 0.6 | AI19: =(E5b!J19-W19-(E5b!I19-V19))/(E5b!J19-E5b!I19) -> 0.7 | ... AL19: =(E5b!M19-Z19-(E5b!L19-Y19))/(E5b!M19-E5b!L19) -> 0.925
A20: 2042 | B20: =B19+(B$28-B$13)/15 -> 0 | C20: =C19+(C$28-C$13)/15 -> 0 | D20: =D19+(D$28-D$13)/15 -> 0.15 | E20: =E19+(E$28-E$13)/15 -> 0.2 | F20: =F19+(F$28-F$13)/15 -> 0.25 | G20: =G19+(G$28-G$13)/15 -> 0.3 | H20: =H19+(H$28-H$13)/15 -> 0.4 | I20: =I19+(I$28-I$13)/15 -> 0.5 | ... M20: =M19+(M$28-M$13)/15 -> 0.9 | O20: =(1-B20)*E5b!B20 -> 3.5333333 | P20: =(1-C20)*E5b!C20 -> 5.0666667 | Q20: =(1-D20)*E5b!D20 -> 6.0066667 | R20: =(1-E20)*E5b!E20 -> 7.2533333 | S20: =(1-F20)*E5b!F20 -> 10.2 | T20: =(1-G20)*E5b!G20 -> 14 | U20: =(1-H20)*E5b!H20 -> 30 | V20: =(1-I20)*E5b!I20 -> 50 | ... Z20: =(1-M20)*E5b!M20 -> 500 | AA20: 2 | AB20: =(E5b!C20-P20-(E5b!B20-O20))/(E5b!C20-E5b!B20) -> 0 | AC20: =(E5b!D20-Q20-(E5b!C20-P20))/(E5b!D20-E5b!C20) -> 0.53 | AD20: =(E5b!E20-R20-(E5b!D20-Q20))/(E5b!E20-E5b!D20) -> 0.37666667 | AE20: =(E5b!F20-S20-(E5b!E20-R20))/(E5b!F20-E5b!E20) -> 0.35 | AF20: =(E5b!G20-T20-(E5b!F20-S20))/(E5b!G20-E5b!F20) -> 0.40625 | AG20: =(E5b!H20-U20-(E5b!G20-T20))/(E5b!H20-E5b!G20) -> 0.46666667 | AH20: =(E5b!I20-V20-(E5b!H20-U20))/(E5b!I20-E5b!H20) -> 0.6 | AI20: =(E5b!J20-W20-(E5b!I20-V20))/(E5b!J20-E5b!I20) -> 0.7 | ... AL20: =(E5b!M20-Z20-(E5b!L20-Y20))/(E5b!M20-E5b!L20) -> 0.925
A21: 2043 | B21: =B20+(B$28-B$13)/15 -> 0 | C21: =C20+(C$28-C$13)/15 -> 0 | D21: =D20+(D$28-D$13)/15 -> 0.15 | E21: =E20+(E$28-E$13)/15 -> 0.2 | F21: =F20+(F$28-F$13)/15 -> 0.25 | G21: =G20+(G$28-G$13)/15 -> 0.3 | H21: =H20+(H$28-H$13)/15 -> 0.4 | I21: =I20+(I$28-I$13)/15 -> 0.5 | ... M21: =M20+(M$28-M$13)/15 -> 0.9 | O21: =(1-B21)*E5b!B21 -> 3.4666667 | P21: =(1-C21)*E5b!C21 -> 4.9333333 | Q21: =(1-D21)*E5b!D21 -> 5.8933333 | R21: =(1-E21)*E5b!E21 -> 7.1466667 | S21: =(1-F21)*E5b!F21 -> 10.05 | T21: =(1-G21)*E5b!G21 -> 14 | U21: =(1-H21)*E5b!H21 -> 30 | V21: =(1-I21)*E5b!I21 -> 50 | ... Z21: =(1-M21)*E5b!M21 -> 500 | AA21: 2 | AB21: =(E5b!C21-P21-(E5b!B21-O21))/(E5b!C21-E5b!B21) -> 0 | AC21: =(E5b!D21-Q21-(E5b!C21-P21))/(E5b!D21-E5b!C21) -> 0.52 | AD21: =(E5b!E21-R21-(E5b!D21-Q21))/(E5b!E21-E5b!D21) -> 0.37333333 | AE21: =(E5b!F21-S21-(E5b!E21-R21))/(E5b!F21-E5b!E21) -> 0.35 | AF21: =(E5b!G21-T21-(E5b!F21-S21))/(E5b!G21-E5b!F21) -> 0.40151515 | AG21: =(E5b!H21-U21-(E5b!G21-T21))/(E5b!H21-E5b!G21) -> 0.46666667 | AH21: =(E5b!I21-V21-(E5b!H21-U21))/(E5b!I21-E5b!H21) -> 0.6 | AI21: =(E5b!J21-W21-(E5b!I21-V21))/(E5b!J21-E5b!I21) -> 0.7 | ... AL21: =(E5b!M21-Z21-(E5b!L21-Y21))/(E5b!M21-E5b!L21) -> 0.925
A22: 2044 | B22: =B21+(B$28-B$13)/15 -> 0 | C22: =C21+(C$28-C$13)/15 -> 0 | D22: =D21+(D$28-D$13)/15 -> 0.15 | E22: =E21+(E$28-E$13)/15 -> 0.2 | F22: =F21+(F$28-F$13)/15 -> 0.25 | G22: =G21+(G$28-G$13)/15 -> 0.3 | H22: =H21+(H$28-H$13)/15 -> 0.4 | I22: =I21+(I$28-I$13)/15 -> 0.5 | ... M22: =M21+(M$28-M$13)/15 -> 0.9 | O22: =(1-B22)*E5b!B22 -> 3.4 | P22: =(1-C22)*E5b!C22 -> 4.8 | Q22: =(1-D22)*E5b!D22 -> 5.78 | R22: =(1-E22)*E5b!E22 -> 7.04 | S22: =(1-F22)*E5b!F22 -> 9.9 | T22: =(1-G22)*E5b!G22 -> 14 | U22: =(1-H22)*E5b!H22 -> 30 | V22: =(1-I22)*E5b!I22 -> 50 | ... Z22: =(1-M22)*E5b!M22 -> 500 | AA22: 2 | AB22: =(E5b!C22-P22-(E5b!B22-O22))/(E5b!C22-E5b!B22) -> 0 | AC22: =(E5b!D22-Q22-(E5b!C22-P22))/(E5b!D22-E5b!C22) -> 0.51 | AD22: =(E5b!E22-R22-(E5b!D22-Q22))/(E5b!E22-E5b!D22) -> 0.37 | AE22: =(E5b!F22-S22-(E5b!E22-R22))/(E5b!F22-E5b!E22) -> 0.35 | AF22: =(E5b!G22-T22-(E5b!F22-S22))/(E5b!G22-E5b!F22) -> 0.39705882 | AG22: =(E5b!H22-U22-(E5b!G22-T22))/(E5b!H22-E5b!G22) -> 0.46666667 | AH22: =(E5b!I22-V22-(E5b!H22-U22))/(E5b!I22-E5b!H22) -> 0.6 | AI22: =(E5b!J22-W22-(E5b!I22-V22))/(E5b!J22-E5b!I22) -> 0.7 | ... AL22: =(E5b!M22-Z22-(E5b!L22-Y22))/(E5b!M22-E5b!L22) -> 0.925
A23: 2045 | B23: =B22+(B$28-B$13)/15 -> 0 | C23: =C22+(C$28-C$13)/15 -> 0 | D23: =D22+(D$28-D$13)/15 -> 0.15 | E23: =E22+(E$28-E$13)/15 -> 0.2 | F23: =F22+(F$28-F$13)/15 -> 0.25 | G23: =G22+(G$28-G$13)/15 -> 0.3 | H23: =H22+(H$28-H$13)/15 -> 0.4 | I23: =I22+(I$28-I$13)/15 -> 0.5 | ... M23: =M22+(M$28-M$13)/15 -> 0.9 | O23: =(1-B23)*E5b!B23 -> 3.3333333 | P23: =(1-C23)*E5b!C23 -> 4.6666667 | Q23: =(1-D23)*E5b!D23 -> 5.6666667 | R23: =(1-E23)*E5b!E23 -> 6.9333333 | S23: =(1-F23)*E5b!F23 -> 9.75 | T23: =(1-G23)*E5b!G23 -> 14 | U23: =(1-H23)*E5b!H23 -> 30 | V23: =(1-I23)*E5b!I23 -> 50 | ... Z23: =(1-M23)*E5b!M23 -> 500 | AA23: 2 | AB23: =(E5b!C23-P23-(E5b!B23-O23))/(E5b!C23-E5b!B23) -> 0 | AC23: =(E5b!D23-Q23-(E5b!C23-P23))/(E5b!D23-E5b!C23) -> 0.5 | AD23: =(E5b!E23-R23-(E5b!D23-Q23))/(E5b!E23-E5b!D23) -> 0.36666667 | AE23: =(E5b!F23-S23-(E5b!E23-R23))/(E5b!F23-E5b!E23) -> 0.35 | AF23: =(E5b!G23-T23-(E5b!F23-S23))/(E5b!G23-E5b!F23) -> 0.39285714 | AG23: =(E5b!H23-U23-(E5b!G23-T23))/(E5b!H23-E5b!G23) -> 0.46666667 | AH23: =(E5b!I23-V23-(E5b!H23-U23))/(E5b!I23-E5b!H23) -> 0.6 | AI23: =(E5b!J23-W23-(E5b!I23-V23))/(E5b!J23-E5b!I23) -> 0.7 | ... AL23: =(E5b!M23-Z23-(E5b!L23-Y23))/(E5b!M23-E5b!L23) -> 0.925
A24: 2046 | B24: =B23+(B$28-B$13)/15 -> 0 | C24: =C23+(C$28-C$13)/15 -> 0 | D24: =D23+(D$28-D$13)/15 -> 0.15 | E24: =E23+(E$28-E$13)/15 -> 0.2 | F24: =F23+(F$28-F$13)/15 -> 0.25 | G24: =G23+(G$28-G$13)/15 -> 0.3 | H24: =H23+(H$28-H$13)/15 -> 0.4 | I24: =I23+(I$28-I$13)/15 -> 0.5 | ... M24: =M23+(M$28-M$13)/15 -> 0.9 | O24: =(1-B24)*E5b!B24 -> 3.2666667 | P24: =(1-C24)*E5b!C24 -> 4.5333333 | Q24: =(1-D24)*E5b!D24 -> 5.5533333 | R24: =(1-E24)*E5b!E24 -> 6.8266667 | S24: =(1-F24)*E5b!F24 -> 9.6 | T24: =(1-G24)*E5b!G24 -> 14 | U24: =(1-H24)*E5b!H24 -> 30 | V24: =(1-I24)*E5b!I24 -> 50 | ... Z24: =(1-M24)*E5b!M24 -> 500 | AA24: 2 | AB24: =(E5b!C24-P24-(E5b!B24-O24))/(E5b!C24-E5b!B24) -> 0 | AC24: =(E5b!D24-Q24-(E5b!C24-P24))/(E5b!D24-E5b!C24) -> 0.49 | AD24: =(E5b!E24-R24-(E5b!D24-Q24))/(E5b!E24-E5b!D24) -> 0.36333333 | AE24: =(E5b!F24-S24-(E5b!E24-R24))/(E5b!F24-E5b!E24) -> 0.35 | AF24: =(E5b!G24-T24-(E5b!F24-S24))/(E5b!G24-E5b!F24) -> 0.38888889 | AG24: =(E5b!H24-U24-(E5b!G24-T24))/(E5b!H24-E5b!G24) -> 0.46666667 | AH24: =(E5b!I24-V24-(E5b!H24-U24))/(E5b!I24-E5b!H24) -> 0.6 | AI24: =(E5b!J24-W24-(E5b!I24-V24))/(E5b!J24-E5b!I24) -> 0.7 | ... AL24: =(E5b!M24-Z24-(E5b!L24-Y24))/(E5b!M24-E5b!L24) -> 0.925
A25: 2047 | B25: =B24+(B$28-B$13)/15 -> 0 | C25: =C24+(C$28-C$13)/15 -> 0 | D25: =D24+(D$28-D$13)/15 -> 0.15 | E25: =E24+(E$28-E$13)/15 -> 0.2 | F25: =F24+(F$28-F$13)/15 -> 0.25 | G25: =G24+(G$28-G$13)/15 -> 0.3 | H25: =H24+(H$28-H$13)/15 -> 0.4 | I25: =I24+(I$28-I$13)/15 -> 0.5 | ... M25: =M24+(M$28-M$13)/15 -> 0.9 | O25: =(1-B25)*E5b!B25 -> 3.2 | P25: =(1-C25)*E5b!C25 -> 4.4 | Q25: =(1-D25)*E5b!D25 -> 5.44 | R25: =(1-E25)*E5b!E25 -> 6.72 | S25: =(1-F25)*E5b!F25 -> 9.45 | T25: =(1-G25)*E5b!G25 -> 14 | U25: =(1-H25)*E5b!H25 -> 30 | V25: =(1-I25)*E5b!I25 -> 50 | ... Z25: =(1-M25)*E5b!M25 -> 500 | AA25: 2 | AB25: =(E5b!C25-P25-(E5b!B25-O25))/(E5b!C25-E5b!B25) -> 0 | AC25: =(E5b!D25-Q25-(E5b!C25-P25))/(E5b!D25-E5b!C25) -> 0.48 | AD25: =(E5b!E25-R25-(E5b!D25-Q25))/(E5b!E25-E5b!D25) -> 0.36 | AE25: =(E5b!F25-S25-(E5b!E25-R25))/(E5b!F25-E5b!E25) -> 0.35 | AF25: =(E5b!G25-T25-(E5b!F25-S25))/(E5b!G25-E5b!F25) -> 0.38513514 | AG25: =(E5b!H25-U25-(E5b!G25-T25))/(E5b!H25-E5b!G25) -> 0.46666667 | AH25: =(E5b!I25-V25-(E5b!H25-U25))/(E5b!I25-E5b!H25) -> 0.6 | AI25: =(E5b!J25-W25-(E5b!I25-V25))/(E5b!J25-E5b!I25) -> 0.7 | ... AL25: =(E5b!M25-Z25-(E5b!L25-Y25))/(E5b!M25-E5b!L25) -> 0.925
... A27: 2049 | B27: =B26+(B$28-B$13)/15 -> 0 | C27: =C26+(C$28-C$13)/15 -> 0 | D27: =D26+(D$28-D$13)/15 -> 0.15 | E27: =E26+(E$28-E$13)/15 -> 0.2 | F27: =F26+(F$28-F$13)/15 -> 0.25 | G27: =G26+(G$28-G$13)/15 -> 0.3 | H27: =H26+(H$28-H$13)/15 -> 0.4 | I27: =I26+(I$28-I$13)/15 -> 0.5 | ... M27: =M26+(M$28-M$13)/15 -> 0.9 | O27: =(1-B27)*E5b!B27 -> 3.0666667 | P27: =(1-C27)*E5b!C27 -> 4.1333333 | Q27: =(1-D27)*E5b!D27 -> 5.2133333 | R27: =(1-E27)*E5b!E27 -> 6.5066667 | S27: =(1-F27)*E5b!F27 -> 9.15 | T27: =(1-G27)*E5b!G27 -> 14 | U27: =(1-H27)*E5b!H27 -> 30 | V27: =(1-I27)*E5b!I27 -> 50 | ... Z27: =(1-M27)*E5b!M27 -> 500 | AA27: 2 | AB27: =(E5b!C27-P27-(E5b!B27-O27))/(E5b!C27-E5b!B27) -> 0 | AC27: =(E5b!D27-Q27-(E5b!C27-P27))/(E5b!D27-E5b!C27) -> 0.46 | AD27: =(E5b!E27-R27-(E5b!D27-Q27))/(E5b!E27-E5b!D27) -> 0.35333333 | AE27: =(E5b!F27-S27-(E5b!E27-R27))/(E5b!F27-E5b!E27) -> 0.35 | AF27: =(E5b!G27-T27-(E5b!F27-S27))/(E5b!G27-E5b!F27) -> 0.37820513 | AG27: =(E5b!H27-U27-(E5b!G27-T27))/(E5b!H27-E5b!G27) -> 0.46666667 | AH27: =(E5b!I27-V27-(E5b!H27-U27))/(E5b!I27-E5b!H27) -> 0.6 | AI27: =(E5b!J27-W27-(E5b!I27-V27))/(E5b!J27-E5b!I27) -> 0.7 | ... AL27: =(E5b!M27-Z27-(E5b!L27-Y27))/(E5b!M27-E5b!L27) -> 0.925
A28: 2050 | B28: 0 | C28: 0 | D28: 0.15 | E28: 0.2 | F28: 0.25 | G28: 0.3 | H28: 0.4 | I28: 0.5 | J28: 0.6 | K28: 0.7 | L28: 0.8 | M28: 0.9 | O28: =(1-B28)*E5b!B28 -> 3 | P28: =(1-C28)*E5b!C28 -> 4 | Q28: =(1-D28)*E5b!D28 -> 5.1 | R28: =(1-E28)*E5b!E28 -> 6.4 | S28: =(1-F28)*E5b!F28 -> 9 | T28: =(1-G28)*E5b!G28 -> 14 | U28: =(1-H28)*E5b!H28 -> 30 | V28: =(1-I28)*E5b!I28 -> 50 | ... Z28: =(1-M28)*E5b!M28 -> 500 | AA28: 1 | AB28: =(E5b!C28-P28-(E5b!B28-O28))/(E5b!C28-E5b!B28) -> 0 | AC28: =(E5b!D28-Q28-(E5b!C28-P28))/(E5b!D28-E5b!C28) -> 0.45 | AD28: =(E5b!E28-R28-(E5b!D28-Q28))/(E5b!E28-E5b!D28) -> 0.35 | AE28: =(E5b!F28-S28-(E5b!E28-R28))/(E5b!F28-E5b!E28) -> 0.35 | AF28: =(E5b!G28-T28-(E5b!F28-S28))/(E5b!G28-E5b!F28) -> 0.375 | AG28: =(E5b!H28-U28-(E5b!G28-T28))/(E5b!H28-E5b!G28) -> 0.46666667 | AH28: =(E5b!I28-V28-(E5b!H28-U28))/(E5b!I28-E5b!H28) -> 0.6 | AI28: =(E5b!J28-W28-(E5b!I28-V28))/(E5b!J28-E5b!I28) -> 0.7 | ... AL28: =(E5b!M28-Z28-(E5b!L28-Y28))/(E5b!M28-E5b!L28) -> 0.925
A29: 2051 | B29: =B28+(B$48-B$28)/20 -> 0 | C29: =C28+(C$48-C$28)/20 -> 0 | D29: =D28+(D$48-D$28)/20 -> 0.15 | E29: =E28+(E$48-E$28)/20 -> 0.2025 | F29: =F28+(F$48-F$28)/20 -> 0.2525 | G29: =G28+(G$48-G$28)/20 -> 0.305 | H29: =H28+(H$48-H$28)/20 -> 0.405 | I29: =I28+(I$48-I$28)/20 -> 0.505 | ... M29: =M28+(M$48-M$28)/20 -> 0.9 | O29: =(1-B29)*E5b!B29 -> 3 | P29: =(1-C29)*E5b!C29 -> 4 | Q29: =(1-D29)*E5b!D29 -> 5.0575 | R29: =(1-E29)*E5b!E29 -> 6.340125 | S29: =(1-F29)*E5b!F29 -> 8.89525 | T29: =(1-G29)*E5b!G29 -> 13.9 | U29: =(1-H29)*E5b!H29 -> 29.75 | V29: =(1-I29)*E5b!I29 -> 49.5 | ... Z29: =(1-M29)*E5b!M29 -> 500 | AA29: 1 | AB29: =(E5b!C29-P29-(E5b!B29-O29))/(E5b!C29-E5b!B29) -> 0 | AC29: =(E5b!D29-Q29-(E5b!C29-P29))/(E5b!D29-E5b!C29) -> 0.45769231 | AD29: =(E5b!E29-R29-(E5b!D29-Q29))/(E5b!E29-E5b!D29) -> 0.3586875 | AE29: =(E5b!F29-S29-(E5b!E29-R29))/(E5b!F29-E5b!E29) -> 0.35313291 | AF29: =(E5b!G29-T29-(E5b!F29-S29))/(E5b!G29-E5b!F29) -> 0.38212963 | AG29: =(E5b!H29-U29-(E5b!G29-T29))/(E5b!H29-E5b!G29) -> 0.47166667 | AH29: =(E5b!I29-V29-(E5b!H29-U29))/(E5b!I29-E5b!H29) -> 0.605 | AI29: =(E5b!J29-W29-(E5b!I29-V29))/(E5b!J29-E5b!I29) -> 0.705 | ... AL29: =(E5b!M29-Z29-(E5b!L29-Y29))/(E5b!M29-E5b!L29) -> 0.925
A30: 2052 | B30: =B29+(B$48-B$28)/20 -> 0 | C30: =C29+(C$48-C$28)/20 -> 0 | D30: =D29+(D$48-D$28)/20 -> 0.15 | E30: =E29+(E$48-E$28)/20 -> 0.205 | F30: =F29+(F$48-F$28)/20 -> 0.255 | G30: =G29+(G$48-G$28)/20 -> 0.31 | H30: =H29+(H$48-H$28)/20 -> 0.41 | I30: =I29+(I$48-I$28)/20 -> 0.51 | ... M30: =M29+(M$48-M$28)/20 -> 0.9 | O30: =(1-B30)*E5b!B30 -> 3 | P30: =(1-C30)*E5b!C30 -> 4 | Q30: =(1-D30)*E5b!D30 -> 5.015 | R30: =(1-E30)*E5b!E30 -> 6.2805 | S30: =(1-F30)*E5b!F30 -> 8.791 | T30: =(1-G30)*E5b!G30 -> 13.8 | U30: =(1-H30)*E5b!H30 -> 29.5 | V30: =(1-I30)*E5b!I30 -> 49 | ... Z30: =(1-M30)*E5b!M30 -> 500 | AA30: 1 | AB30: =(E5b!C30-P30-(E5b!B30-O30))/(E5b!C30-E5b!B30) -> 0 | AC30: =(E5b!D30-Q30-(E5b!C30-P30))/(E5b!D30-E5b!C30) -> 0.46578947 | AD30: =(E5b!E30-R30-(E5b!D30-Q30))/(E5b!E30-E5b!D30) -> 0.36725 | AE30: =(E5b!F30-S30-(E5b!E30-R30))/(E5b!F30-E5b!E30) -> 0.35628205 | AF30: =(E5b!G30-T30-(E5b!F30-S30))/(E5b!G30-E5b!F30) -> 0.38914634 | AG30: =(E5b!H30-U30-(E5b!G30-T30))/(E5b!H30-E5b!G30) -> 0.47666667 | AH30: =(E5b!I30-V30-(E5b!H30-U30))/(E5b!I30-E5b!H30) -> 0.61 | AI30: =(E5b!J30-W30-(E5b!I30-V30))/(E5b!J30-E5b!I30) -> 0.71 | ... AL30: =(E5b!M30-Z30-(E5b!L30-Y30))/(E5b!M30-E5b!L30) -> 0.925
A31: 2053 | B31: =B30+(B$48-B$28)/20 -> 0 | C31: =C30+(C$48-C$28)/20 -> 0 | D31: =D30+(D$48-D$28)/20 -> 0.15 | E31: =E30+(E$48-E$28)/20 -> 0.2075 | F31: =F30+(F$48-F$28)/20 -> 0.2575 | G31: =G30+(G$48-G$28)/20 -> 0.315 | H31: =H30+(H$48-H$28)/20 -> 0.415 | I31: =I30+(I$48-I$28)/20 -> 0.515 | ... M31: =M30+(M$48-M$28)/20 -> 0.9 | O31: =(1-B31)*E5b!B31 -> 3 | P31: =(1-C31)*E5b!C31 -> 4 | Q31: =(1-D31)*E5b!D31 -> 4.9725 | R31: =(1-E31)*E5b!E31 -> 6.221125 | S31: =(1-F31)*E5b!F31 -> 8.68725 | T31: =(1-G31)*E5b!G31 -> 13.7 | U31: =(1-H31)*E5b!H31 -> 29.25 | V31: =(1-I31)*E5b!I31 -> 48.5 | ... Z31: =(1-M31)*E5b!M31 -> 500 | AA31: 1 | AB31: =(E5b!C31-P31-(E5b!B31-O31))/(E5b!C31-E5b!B31) -> 0 | AC31: =(E5b!D31-Q31-(E5b!C31-P31))/(E5b!D31-E5b!C31) -> 0.47432432 | AD31: =(E5b!E31-R31-(E5b!D31-Q31))/(E5b!E31-E5b!D31) -> 0.3756875 | AE31: =(E5b!F31-S31-(E5b!E31-R31))/(E5b!F31-E5b!E31) -> 0.35944805 | AF31: =(E5b!G31-T31-(E5b!F31-S31))/(E5b!G31-E5b!F31) -> 0.39605422 | AG31: =(E5b!H31-U31-(E5b!G31-T31))/(E5b!H31-E5b!G31) -> 0.48166667 | AH31: =(E5b!I31-V31-(E5b!H31-U31))/(E5b!I31-E5b!H31) -> 0.615 | AI31: =(E5b!J31-W31-(E5b!I31-V31))/(E5b!J31-E5b!I31) -> 0.715 | ... AL31: =(E5b!M31-Z31-(E5b!L31-Y31))/(E5b!M31-E5b!L31) -> 0.925
A32: 2054 | B32: =B31+(B$48-B$28)/20 -> 0 | C32: =C31+(C$48-C$28)/20 -> 0 | D32: =D31+(D$48-D$28)/20 -> 0.15 | E32: =E31+(E$48-E$28)/20 -> 0.21 | F32: =F31+(F$48-F$28)/20 -> 0.26 | G32: =G31+(G$48-G$28)/20 -> 0.32 | H32: =H31+(H$48-H$28)/20 -> 0.42 | I32: =I31+(I$48-I$28)/20 -> 0.52 | ... M32: =M31+(M$48-M$28)/20 -> 0.9 | O32: =(1-B32)*E5b!B32 -> 3 | P32: =(1-C32)*E5b!C32 -> 4 | Q32: =(1-D32)*E5b!D32 -> 4.93 | R32: =(1-E32)*E5b!E32 -> 6.162 | S32: =(1-F32)*E5b!F32 -> 8.584 | T32: =(1-G32)*E5b!G32 -> 13.6 | U32: =(1-H32)*E5b!H32 -> 29 | V32: =(1-I32)*E5b!I32 -> 48 | ... Z32: =(1-M32)*E5b!M32 -> 500 | AA32: 1 | AB32: =(E5b!C32-P32-(E5b!B32-O32))/(E5b!C32-E5b!B32) -> 0 | AC32: =(E5b!D32-Q32-(E5b!C32-P32))/(E5b!D32-E5b!C32) -> 0.48333333 | AD32: =(E5b!E32-R32-(E5b!D32-Q32))/(E5b!E32-E5b!D32) -> 0.384 | AE32: =(E5b!F32-S32-(E5b!E32-R32))/(E5b!F32-E5b!E32) -> 0.36263158 | AF32: =(E5b!G32-T32-(E5b!F32-S32))/(E5b!G32-E5b!F32) -> 0.40285714 | AG32: =(E5b!H32-U32-(E5b!G32-T32))/(E5b!H32-E5b!G32) -> 0.48666667 | AH32: =(E5b!I32-V32-(E5b!H32-U32))/(E5b!I32-E5b!H32) -> 0.62 | AI32: =(E5b!J32-W32-(E5b!I32-V32))/(E5b!J32-E5b!I32) -> 0.72 | ... AL32: =(E5b!M32-Z32-(E5b!L32-Y32))/(E5b!M32-E5b!L32) -> 0.925
A33: 2055 | B33: =B32+(B$48-B$28)/20 -> 0 | C33: =C32+(C$48-C$28)/20 -> 0 | D33: =D32+(D$48-D$28)/20 -> 0.15 | E33: =E32+(E$48-E$28)/20 -> 0.2125 | F33: =F32+(F$48-F$28)/20 -> 0.2625 | G33: =G32+(G$48-G$28)/20 -> 0.325 | H33: =H32+(H$48-H$28)/20 -> 0.425 | I33: =I32+(I$48-I$28)/20 -> 0.525 | ... M33: =M32+(M$48-M$28)/20 -> 0.9 | O33: =(1-B33)*E5b!B33 -> 3 | P33: =(1-C33)*E5b!C33 -> 4 | Q33: =(1-D33)*E5b!D33 -> 4.8875 | R33: =(1-E33)*E5b!E33 -> 6.103125 | S33: =(1-F33)*E5b!F33 -> 8.48125 | T33: =(1-G33)*E5b!G33 -> 13.5 | U33: =(1-H33)*E5b!H33 -> 28.75 | V33: =(1-I33)*E5b!I33 -> 47.5 | ... Z33: =(1-M33)*E5b!M33 -> 500 | AA33: 1 | AB33: =(E5b!C33-P33-(E5b!B33-O33))/(E5b!C33-E5b!B33) -> 0 | AC33: =(E5b!D33-Q33-(E5b!C33-P33))/(E5b!D33-E5b!C33) -> 0.49285714 | AD33: =(E5b!E33-R33-(E5b!D33-Q33))/(E5b!E33-E5b!D33) -> 0.3921875 | AE33: =(E5b!F33-S33-(E5b!E33-R33))/(E5b!F33-E5b!E33) -> 0.36583333 | AF33: =(E5b!G33-T33-(E5b!F33-S33))/(E5b!G33-E5b!F33) -> 0.40955882 | AG33: =(E5b!H33-U33-(E5b!G33-T33))/(E5b!H33-E5b!G33) -> 0.49166667 | AH33: =(E5b!I33-V33-(E5b!H33-U33))/(E5b!I33-E5b!H33) -> 0.625 | AI33: =(E5b!J33-W33-(E5b!I33-V33))/(E5b!J33-E5b!I33) -> 0.725 | ... AL33: =(E5b!M33-Z33-(E5b!L33-Y33))/(E5b!M33-E5b!L33) -> 0.925
A34: 2056 | B34: =B33+(B$48-B$28)/20 -> 0 | C34: =C33+(C$48-C$28)/20 -> 0 | D34: =D33+(D$48-D$28)/20 -> 0.15 | E34: =E33+(E$48-E$28)/20 -> 0.215 | F34: =F33+(F$48-F$28)/20 -> 0.265 | G34: =G33+(G$48-G$28)/20 -> 0.33 | H34: =H33+(H$48-H$28)/20 -> 0.43 | I34: =I33+(I$48-I$28)/20 -> 0.53 | ... M34: =M33+(M$48-M$28)/20 -> 0.9 | O34: =(1-B34)*E5b!B34 -> 3 | P34: =(1-C34)*E5b!C34 -> 4 | Q34: =(1-D34)*E5b!D34 -> 4.845 | R34: =(1-E34)*E5b!E34 -> 6.0445 | S34: =(1-F34)*E5b!F34 -> 8.379 | T34: =(1-G34)*E5b!G34 -> 13.4 | U34: =(1-H34)*E5b!H34 -> 28.5 | V34: =(1-I34)*E5b!I34 -> 47 | ... Z34: =(1-M34)*E5b!M34 -> 500 | AA34: 1 | AB34: =(E5b!C34-P34-(E5b!B34-O34))/(E5b!C34-E5b!B34) -> 0 | AC34: =(E5b!D34-Q34-(E5b!C34-P34))/(E5b!D34-E5b!C34) -> 0.50294118 | AD34: =(E5b!E34-R34-(E5b!D34-Q34))/(E5b!E34-E5b!D34) -> 0.40025 | AE34: =(E5b!F34-S34-(E5b!E34-R34))/(E5b!F34-E5b!E34) -> 0.36905405 | AF34: =(E5b!G34-T34-(E5b!F34-S34))/(E5b!G34-E5b!F34) -> 0.41616279 | AG34: =(E5b!H34-U34-(E5b!G34-T34))/(E5b!H34-E5b!G34) -> 0.49666667 | AH34: =(E5b!I34-V34-(E5b!H34-U34))/(E5b!I34-E5b!H34) -> 0.63 | AI34: =(E5b!J34-W34-(E5b!I34-V34))/(E5b!J34-E5b!I34) -> 0.73 | ... AL34: =(E5b!M34-Z34-(E5b!L34-Y34))/(E5b!M34-E5b!L34) -> 0.925
A35: 2057 | B35: =B34+(B$48-B$28)/20 -> 0 | C35: =C34+(C$48-C$28)/20 -> 0 | D35: =D34+(D$48-D$28)/20 -> 0.15 | E35: =E34+(E$48-E$28)/20 -> 0.2175 | F35: =F34+(F$48-F$28)/20 -> 0.2675 | G35: =G34+(G$48-G$28)/20 -> 0.335 | H35: =H34+(H$48-H$28)/20 -> 0.435 | I35: =I34+(I$48-I$28)/20 -> 0.535 | ... M35: =M34+(M$48-M$28)/20 -> 0.9 | O35: =(1-B35)*E5b!B35 -> 3 | P35: =(1-C35)*E5b!C35 -> 4 | Q35: =(1-D35)*E5b!D35 -> 4.8025 | R35: =(1-E35)*E5b!E35 -> 5.986125 | S35: =(1-F35)*E5b!F35 -> 8.27725 | T35: =(1-G35)*E5b!G35 -> 13.3 | U35: =(1-H35)*E5b!H35 -> 28.25 | V35: =(1-I35)*E5b!I35 -> 46.5 | ... Z35: =(1-M35)*E5b!M35 -> 500 | AA35: 1 | AB35: =(E5b!C35-P35-(E5b!B35-O35))/(E5b!C35-E5b!B35) -> 0 | AC35: =(E5b!D35-Q35-(E5b!C35-P35))/(E5b!D35-E5b!C35) -> 0.51363636 | AD35: =(E5b!E35-R35-(E5b!D35-Q35))/(E5b!E35-E5b!D35) -> 0.4081875 | AE35: =(E5b!F35-S35-(E5b!E35-R35))/(E5b!F35-E5b!E35) -> 0.37229452 | AF35: =(E5b!G35-T35-(E5b!F35-S35))/(E5b!G35-E5b!F35) -> 0.42267241 | AG35: =(E5b!H35-U35-(E5b!G35-T35))/(E5b!H35-E5b!G35) -> 0.50166667 | AH35: =(E5b!I35-V35-(E5b!H35-U35))/(E5b!I35-E5b!H35) -> 0.635 | AI35: =(E5b!J35-W35-(E5b!I35-V35))/(E5b!J35-E5b!I35) -> 0.735 | ... AL35: =(E5b!M35-Z35-(E5b!L35-Y35))/(E5b!M35-E5b!L35) -> 0.925
A36: 2058 | B36: =B35+(B$48-B$28)/20 -> 0 | C36: =C35+(C$48-C$28)/20 -> 0 | D36: =D35+(D$48-D$28)/20 -> 0.15 | E36: =E35+(E$48-E$28)/20 -> 0.22 | F36: =F35+(F$48-F$28)/20 -> 0.27 | G36: =G35+(G$48-G$28)/20 -> 0.34 | H36: =H35+(H$48-H$28)/20 -> 0.44 | I36: =I35+(I$48-I$28)/20 -> 0.54 | ... M36: =M35+(M$48-M$28)/20 -> 0.9 | O36: =(1-B36)*E5b!B36 -> 3 | P36: =(1-C36)*E5b!C36 -> 4 | Q36: =(1-D36)*E5b!D36 -> 4.76 | R36: =(1-E36)*E5b!E36 -> 5.928 | S36: =(1-F36)*E5b!F36 -> 8.176 | T36: =(1-G36)*E5b!G36 -> 13.2 | U36: =(1-H36)*E5b!H36 -> 28 | V36: =(1-I36)*E5b!I36 -> 46 | ... Z36: =(1-M36)*E5b!M36 -> 500 | AA36: 1 | AB36: =(E5b!C36-P36-(E5b!B36-O36))/(E5b!C36-E5b!B36) -> 0 | AC36: =(E5b!D36-Q36-(E5b!C36-P36))/(E5b!D36-E5b!C36) -> 0.525 | AD36: =(E5b!E36-R36-(E5b!D36-Q36))/(E5b!E36-E5b!D36) -> 0.416 | AE36: =(E5b!F36-S36-(E5b!E36-R36))/(E5b!F36-E5b!E36) -> 0.37555556 | AF36: =(E5b!G36-T36-(E5b!F36-S36))/(E5b!G36-E5b!F36) -> 0.42909091 | AG36: =(E5b!H36-U36-(E5b!G36-T36))/(E5b!H36-E5b!G36) -> 0.50666667 | AH36: =(E5b!I36-V36-(E5b!H36-U36))/(E5b!I36-E5b!H36) -> 0.64 | AI36: =(E5b!J36-W36-(E5b!I36-V36))/(E5b!J36-E5b!I36) -> 0.74 | ... AL36: =(E5b!M36-Z36-(E5b!L36-Y36))/(E5b!M36-E5b!L36) -> 0.925
A37: 2059 | B37: =B36+(B$48-B$28)/20 -> 0 | C37: =C36+(C$48-C$28)/20 -> 0 | D37: =D36+(D$48-D$28)/20 -> 0.15 | E37: =E36+(E$48-E$28)/20 -> 0.2225 | F37: =F36+(F$48-F$28)/20 -> 0.2725 | G37: =G36+(G$48-G$28)/20 -> 0.345 | H37: =H36+(H$48-H$28)/20 -> 0.445 | I37: =I36+(I$48-I$28)/20 -> 0.545 | ... M37: =M36+(M$48-M$28)/20 -> 0.9 | O37: =(1-B37)*E5b!B37 -> 3 | P37: =(1-C37)*E5b!C37 -> 4 | Q37: =(1-D37)*E5b!D37 -> 4.7175 | R37: =(1-E37)*E5b!E37 -> 5.870125 | S37: =(1-F37)*E5b!F37 -> 8.07525 | T37: =(1-G37)*E5b!G37 -> 13.1 | U37: =(1-H37)*E5b!H37 -> 27.75 | V37: =(1-I37)*E5b!I37 -> 45.5 | ... Z37: =(1-M37)*E5b!M37 -> 500 | AA37: 1 | AB37: =(E5b!C37-P37-(E5b!B37-O37))/(E5b!C37-E5b!B37) -> 0 | AC37: =(E5b!D37-Q37-(E5b!C37-P37))/(E5b!D37-E5b!C37) -> 0.53709677 | AD37: =(E5b!E37-R37-(E5b!D37-Q37))/(E5b!E37-E5b!D37) -> 0.4236875 | AE37: =(E5b!F37-S37-(E5b!E37-R37))/(E5b!F37-E5b!E37) -> 0.37883803 | AF37: =(E5b!G37-T37-(E5b!F37-S37))/(E5b!G37-E5b!F37) -> 0.43542135 | AG37: =(E5b!H37-U37-(E5b!G37-T37))/(E5b!H37-E5b!G37) -> 0.51166667 | AH37: =(E5b!I37-V37-(E5b!H37-U37))/(E5b!I37-E5b!H37) -> 0.645 | AI37: =(E5b!J37-W37-(E5b!I37-V37))/(E5b!J37-E5b!I37) -> 0.745 | ... AL37: =(E5b!M37-Z37-(E5b!L37-Y37))/(E5b!M37-E5b!L37) -> 0.925
A38: 2060 | B38: =B37+(B$48-B$28)/20 -> 0 | C38: =C37+(C$48-C$28)/20 -> 0 | D38: =D37+(D$48-D$28)/20 -> 0.15 | E38: =E37+(E$48-E$28)/20 -> 0.225 | F38: =F37+(F$48-F$28)/20 -> 0.275 | G38: =G37+(G$48-G$28)/20 -> 0.35 | H38: =H37+(H$48-H$28)/20 -> 0.45 | I38: =I37+(I$48-I$28)/20 -> 0.55 | ... M38: =M37+(M$48-M$28)/20 -> 0.9 | O38: =(1-B38)*E5b!B38 -> 3 | P38: =(1-C38)*E5b!C38 -> 4 | Q38: =(1-D38)*E5b!D38 -> 4.675 | R38: =(1-E38)*E5b!E38 -> 5.8125 | S38: =(1-F38)*E5b!F38 -> 7.975 | T38: =(1-G38)*E5b!G38 -> 13 | U38: =(1-H38)*E5b!H38 -> 27.5 | V38: =(1-I38)*E5b!I38 -> 45 | ... Z38: =(1-M38)*E5b!M38 -> 500 | AA38: 1 | AB38: =(E5b!C38-P38-(E5b!B38-O38))/(E5b!C38-E5b!B38) -> 0 | AC38: =(E5b!D38-Q38-(E5b!C38-P38))/(E5b!D38-E5b!C38) -> 0.55 | AD38: =(E5b!E38-R38-(E5b!D38-Q38))/(E5b!E38-E5b!D38) -> 0.43125 | AE38: =(E5b!F38-S38-(E5b!E38-R38))/(E5b!F38-E5b!E38) -> 0.38214286 | AF38: =(E5b!G38-T38-(E5b!F38-S38))/(E5b!G38-E5b!F38) -> 0.44166667 | AG38: =(E5b!H38-U38-(E5b!G38-T38))/(E5b!H38-E5b!G38) -> 0.51666667 | AH38: =(E5b!I38-V38-(E5b!H38-U38))/(E5b!I38-E5b!H38) -> 0.65 | AI38: =(E5b!J38-W38-(E5b!I38-V38))/(E5b!J38-E5b!I38) -> 0.75 | ... AL38: =(E5b!M38-Z38-(E5b!L38-Y38))/(E5b!M38-E5b!L38) -> 0.925
A39: 2061 | B39: =B38+(B$48-B$28)/20 -> 0 | C39: =C38+(C$48-C$28)/20 -> 0 | D39: =D38+(D$48-D$28)/20 -> 0.15 | E39: =E38+(E$48-E$28)/20 -> 0.2275 | F39: =F38+(F$48-F$28)/20 -> 0.2775 | G39: =G38+(G$48-G$28)/20 -> 0.355 | H39: =H38+(H$48-H$28)/20 -> 0.455 | I39: =I38+(I$48-I$28)/20 -> 0.555 | ... M39: =M38+(M$48-M$28)/20 -> 0.9 | O39: =(1-B39)*E5b!B39 -> 3 | P39: =(1-C39)*E5b!C39 -> 4 | Q39: =(1-D39)*E5b!D39 -> 4.6325 | R39: =(1-E39)*E5b!E39 -> 5.755125 | S39: =(1-F39)*E5b!F39 -> 7.87525 | T39: =(1-G39)*E5b!G39 -> 12.9 | U39: =(1-H39)*E5b!H39 -> 27.25 | V39: =(1-I39)*E5b!I39 -> 44.5 | ... Z39: =(1-M39)*E5b!M39 -> 500 | AA39: 1 | AB39: =(E5b!C39-P39-(E5b!B39-O39))/(E5b!C39-E5b!B39) -> 0 | AC39: =(E5b!D39-Q39-(E5b!C39-P39))/(E5b!D39-E5b!C39) -> 0.5637931 | AD39: =(E5b!E39-R39-(E5b!D39-Q39))/(E5b!E39-E5b!D39) -> 0.4386875 | AE39: =(E5b!F39-S39-(E5b!E39-R39))/(E5b!F39-E5b!E39) -> 0.38547101 | AF39: =(E5b!G39-T39-(E5b!F39-S39))/(E5b!G39-E5b!F39) -> 0.44782967 | AG39: =(E5b!H39-U39-(E5b!G39-T39))/(E5b!H39-E5b!G39) -> 0.52166667 | AH39: =(E5b!I39-V39-(E5b!H39-U39))/(E5b!I39-E5b!H39) -> 0.655 | AI39: =(E5b!J39-W39-(E5b!I39-V39))/(E5b!J39-E5b!I39) -> 0.755 | ... AL39: =(E5b!M39-Z39-(E5b!L39-Y39))/(E5b!M39-E5b!L39) -> 0.925
A40: 2062 | B40: =B39+(B$48-B$28)/20 -> 0 | C40: =C39+(C$48-C$28)/20 -> 0 | D40: =D39+(D$48-D$28)/20 -> 0.15 | E40: =E39+(E$48-E$28)/20 -> 0.23 | F40: =F39+(F$48-F$28)/20 -> 0.28 | G40: =G39+(G$48-G$28)/20 -> 0.36 | H40: =H39+(H$48-H$28)/20 -> 0.46 | I40: =I39+(I$48-I$28)/20 -> 0.56 | ... M40: =M39+(M$48-M$28)/20 -> 0.9 | O40: =(1-B40)*E5b!B40 -> 3 | P40: =(1-C40)*E5b!C40 -> 4 | Q40: =(1-D40)*E5b!D40 -> 4.59 | R40: =(1-E40)*E5b!E40 -> 5.698 | S40: =(1-F40)*E5b!F40 -> 7.776 | T40: =(1-G40)*E5b!G40 -> 12.8 | U40: =(1-H40)*E5b!H40 -> 27 | V40: =(1-I40)*E5b!I40 -> 44 | ... Z40: =(1-M40)*E5b!M40 -> 500 | AA40: 1 | AB40: =(E5b!C40-P40-(E5b!B40-O40))/(E5b!C40-E5b!B40) -> 0 | AC40: =(E5b!D40-Q40-(E5b!C40-P40))/(E5b!D40-E5b!C40) -> 0.57857143 | AD40: =(E5b!E40-R40-(E5b!D40-Q40))/(E5b!E40-E5b!D40) -> 0.446 | AE40: =(E5b!F40-S40-(E5b!E40-R40))/(E5b!F40-E5b!E40) -> 0.38882353 | AF40: =(E5b!G40-T40-(E5b!F40-S40))/(E5b!G40-E5b!F40) -> 0.45391304 | AG40: =(E5b!H40-U40-(E5b!G40-T40))/(E5b!H40-E5b!G40) -> 0.52666667 | AH40: =(E5b!I40-V40-(E5b!H40-U40))/(E5b!I40-E5b!H40) -> 0.66 | AI40: =(E5b!J40-W40-(E5b!I40-V40))/(E5b!J40-E5b!I40) -> 0.76 | ... AL40: =(E5b!M40-Z40-(E5b!L40-Y40))/(E5b!M40-E5b!L40) -> 0.925
... A47: 2069 | B47: =B46+(B$48-B$28)/20 -> 0 | C47: =C46+(C$48-C$28)/20 -> 0 | D47: =D46+(D$48-D$28)/20 -> 0.15 | E47: =E46+(E$48-E$28)/20 -> 0.2475 | F47: =F46+(F$48-F$28)/20 -> 0.2975 | G47: =G46+(G$48-G$28)/20 -> 0.395 | H47: =H46+(H$48-H$28)/20 -> 0.495 | I47: =I46+(I$48-I$28)/20 -> 0.595 | ... M47: =M46+(M$48-M$28)/20 -> 0.9 | O47: =(1-B47)*E5b!B47 -> 3 | P47: =(1-C47)*E5b!C47 -> 4 | Q47: =(1-D47)*E5b!D47 -> 4.2925 | R47: =(1-E47)*E5b!E47 -> 5.305125 | S47: =(1-F47)*E5b!F47 -> 7.09525 | T47: =(1-G47)*E5b!G47 -> 12.1 | U47: =(1-H47)*E5b!H47 -> 25.25 | V47: =(1-I47)*E5b!I47 -> 40.5 | ... Z47: =(1-M47)*E5b!M47 -> 500 | AA47: 1 | AB47: =(E5b!C47-P47-(E5b!B47-O47))/(E5b!C47-E5b!B47) -> 0 | AC47: =(E5b!D47-Q47-(E5b!C47-P47))/(E5b!D47-E5b!C47) -> 0.72142857 | AD47: =(E5b!E47-R47-(E5b!D47-Q47))/(E5b!E47-E5b!D47) -> 0.4936875 | AE47: =(E5b!F47-S47-(E5b!E47-R47))/(E5b!F47-E5b!E47) -> 0.41307377 | AF47: =(E5b!G47-T47-(E5b!F47-S47))/(E5b!G47-E5b!F47) -> 0.4944697 | AG47: =(E5b!H47-U47-(E5b!G47-T47))/(E5b!H47-E5b!G47) -> 0.56166667 | AH47: =(E5b!I47-V47-(E5b!H47-U47))/(E5b!I47-E5b!H47) -> 0.695 | AI47: =(E5b!J47-W47-(E5b!I47-V47))/(E5b!J47-E5b!I47) -> 0.795 | ... AL47: =(E5b!M47-Z47-(E5b!L47-Y47))/(E5b!M47-E5b!L47) -> 0.925
...

Sheet E4t
A1: Wealth Tax Schedules (Effective Tax Rates): Series for Stata Import | O1: After-tax income | AB1: Marginal tax rates
AA2: Non-monotonic marginal tax rates
A3: year | B3: tw1 | C3: tw2 | D3: tw3 | E3: tw4 | F3: tw5 | G3: tw6 | H3: tw7 | I3: tw8 | J3: tw9 | K3: tw10 | L3: tw11 | M3: tw12
A4: 2026 | B4: =TE4f!$C7 -> 0 | C4: =TE4f!$C8 -> 0 | D4: =TE4f!$C9 -> 0 | E4: =TE4f!$C10 -> 0.002 | F4: =TE4f!$C11 -> 0.005 | G4: =TE4f!$C12 -> 0.01 | H4: =TE4f!$C13 -> 0.03 | I4: =TE4f!$C14 -> 0.05 | J4: =TE4f!$C15 -> 0.08 | K4: =TE4f!$C16 -> 0.1 | L4: =TE4f!$C17 -> 0.15 | M4: =TE4f!$C18 -> 0.2 | O4: =(1-B4)*E4b!B4 -> 5 | P4: =(1-C4)*E4b!C4 -> 8 | Q4: =(1-D4)*E4b!D4 -> 10 | R4: =(1-E4)*E4b!E4 -> 11.976 | S4: =(1-F4)*E4b!F4 -> 14.925 | T4: =(1-G4)*E4b!G4 -> 19.8 | U4: =(1-H4)*E4b!H4 -> 48.5 | V4: =(1-I4)*E4b!I4 -> 95 | ... Z4: =(1-M4)*E4b!M4 -> 4000 | AA4: 0 | AB4: =(E4b!C4-P4-(E4b!B4-O4))/(E4b!C4-E4b!B4) -> 0 | AC4: =(E4b!D4-Q4-(E4b!C4-P4))/(E4b!D4-E4b!C4) -> 0 | AD4: =(E4b!E4-R4-(E4b!D4-Q4))/(E4b!E4-E4b!D4) -> 0.012 | AE4: =(E4b!F4-S4-(E4b!E4-R4))/(E4b!F4-E4b!E4) -> 0.017 | AF4: =(E4b!G4-T4-(E4b!F4-S4))/(E4b!G4-E4b!F4) -> 0.025 | AG4: =(E4b!H4-U4-(E4b!G4-T4))/(E4b!H4-E4b!G4) -> 0.043333333 | AH4: =(E4b!I4-V4-(E4b!H4-U4))/(E4b!I4-E4b!H4) -> 0.07 | AI4: =(E4b!J4-W4-(E4b!I4-V4))/(E4b!J4-E4b!I4) -> 0.11 | ... AM4: =(E4b!N4-AA4-(E4b!M4-Z4))/(E4b!N4-E4b!M4) -> 0.2
A5: 2027 | B5: =B4+(B$13-B$4)/9 -> 0 | C5: =C4+(C$13-C$4)/9 -> 0 | D5: =D4+(D$13-D$4)/9 -> 0 | E5: =E4+(E$13-E$4)/9 -> 0.0028888889 | F5: =F4+(F$13-F$4)/9 -> 0.0066666667 | G5: =G4+(G$13-G$4)/9 -> 0.012222222 | H5: =H4+(H$13-H$4)/9 -> 0.031111111 | I5: =I4+(I$13-I$4)/9 -> 0.051111111 | ... M5: =M4+(M$13-M$4)/9 -> 0.2 | O5: =(1-B5)*E4b!B5 -> 5 | P5: =(1-C5)*E4b!C5 -> 8 | Q5: =(1-D5)*E4b!D5 -> 10 | R5: =(1-E5)*E4b!E5 -> 11.965333 | S5: =(1-F5)*E4b!F5 -> 14.9 | T5: =(1-G5)*E4b!G5 -> 19.755556 | U5: =(1-H5)*E4b!H5 -> 48.444444 | V5: =(1-I5)*E4b!I5 -> 94.888889 | ... Z5: =(1-M5)*E4b!M5 -> 4000 | AA5: 0 | AB5: =(E4b!C5-P5-(E4b!B5-O5))/(E4b!C5-E4b!B5) -> 0 | AC5: =(E4b!D5-Q5-(E4b!C5-P5))/(E4b!D5-E4b!C5) -> 0 | AD5: =(E4b!E5-R5-(E4b!D5-Q5))/(E4b!E5-E4b!D5) -> 0.017333333 | AE5: =(E4b!F5-S5-(E4b!E5-R5))/(E4b!F5-E4b!E5) -> 0.021777778 | AF5: =(E4b!G5-T5-(E4b!F5-S5))/(E4b!G5-E4b!F5) -> 0.028888889 | AG5: =(E4b!H5-U5-(E4b!G5-T5))/(E4b!H5-E4b!G5) -> 0.043703704 | AH5: =(E4b!I5-V5-(E4b!H5-U5))/(E4b!I5-E4b!H5) -> 0.071111111 | AI5: =(E4b!J5-W5-(E4b!I5-V5))/(E4b!J5-E4b!I5) -> 0.11111111 | ... AM5: =(E4b!N5-AA5-(E4b!M5-Z5))/(E4b!N5-E4b!M5) -> 0.2
A6: 2028 | B6: =B5+(B$13-B$4)/9 -> 0 | C6: =C5+(C$13-C$4)/9 -> 0 | D6: =D5+(D$13-D$4)/9 -> 0 | E6: =E5+(E$13-E$4)/9 -> 0.0037777778 | F6: =F5+(F$13-F$4)/9 -> 0.0083333333 | G6: =G5+(G$13-G$4)/9 -> 0.014444444 | H6: =H5+(H$13-H$4)/9 -> 0.032222222 | I6: =I5+(I$13-I$4)/9 -> 0.052222222 | ... M6: =M5+(M$13-M$4)/9 -> 0.2 | O6: =(1-B6)*E4b!B6 -> 5 | P6: =(1-C6)*E4b!C6 -> 8 | Q6: =(1-D6)*E4b!D6 -> 10 | R6: =(1-E6)*E4b!E6 -> 11.954667 | S6: =(1-F6)*E4b!F6 -> 14.875 | T6: =(1-G6)*E4b!G6 -> 19.711111 | U6: =(1-H6)*E4b!H6 -> 48.388889 | V6: =(1-I6)*E4b!I6 -> 94.777778 | ... Z6: =(1-M6)*E4b!M6 -> 4000 | AA6: 0 | AB6: =(E4b!C6-P6-(E4b!B6-O6))/(E4b!C6-E4b!B6) -> 0 | AC6: =(E4b!D6-Q6-(E4b!C6-P6))/(E4b!D6-E4b!C6) -> 0 | AD6: =(E4b!E6-R6-(E4b!D6-Q6))/(E4b!E6-E4b!D6) -> 0.022666667 | AE6: =(E4b!F6-S6-(E4b!E6-R6))/(E4b!F6-E4b!E6) -> 0.026555556 | AF6: =(E4b!G6-T6-(E4b!F6-S6))/(E4b!G6-E4b!F6) -> 0.032777778 | AG6: =(E4b!H6-U6-(E4b!G6-T6))/(E4b!H6-E4b!G6) -> 0.044074074 | AH6: =(E4b!I6-V6-(E4b!H6-U6))/(E4b!I6-E4b!H6) -> 0.072222222 | AI6: =(E4b!J6-W6-(E4b!I6-V6))/(E4b!J6-E4b!I6) -> 0.11222222 | ... AM6: =(E4b!N6-AA6-(E4b!M6-Z6))/(E4b!N6-E4b!M6) -> 0.2
A7: 2029 | B7: =B6+(B$13-B$4)/9 -> 0 | C7: =C6+(C$13-C$4)/9 -> 0 | D7: =D6+(D$13-D$4)/9 -> 0 | E7: =E6+(E$13-E$4)/9 -> 0.0046666667 | F7: =F6+(F$13-F$4)/9 -> 0.01 | G7: =G6+(G$13-G$4)/9 -> 0.016666667 | H7: =H6+(H$13-H$4)/9 -> 0.033333333 | I7: =I6+(I$13-I$4)/9 -> 0.053333333 | ... M7: =M6+(M$13-M$4)/9 -> 0.2 | O7: =(1-B7)*E4b!B7 -> 5 | P7: =(1-C7)*E4b!C7 -> 8 | Q7: =(1-D7)*E4b!D7 -> 10 | R7: =(1-E7)*E4b!E7 -> 11.944 | S7: =(1-F7)*E4b!F7 -> 14.85 | T7: =(1-G7)*E4b!G7 -> 19.666667 | U7: =(1-H7)*E4b!H7 -> 48.333333 | V7: =(1-I7)*E4b!I7 -> 94.666667 | ... Z7: =(1-M7)*E4b!M7 -> 4000 | AA7: 0 | AB7: =(E4b!C7-P7-(E4b!B7-O7))/(E4b!C7-E4b!B7) -> 0 | AC7: =(E4b!D7-Q7-(E4b!C7-P7))/(E4b!D7-E4b!C7) -> 0 | AD7: =(E4b!E7-R7-(E4b!D7-Q7))/(E4b!E7-E4b!D7) -> 0.028 | AE7: =(E4b!F7-S7-(E4b!E7-R7))/(E4b!F7-E4b!E7) -> 0.031333333 | AF7: =(E4b!G7-T7-(E4b!F7-S7))/(E4b!G7-E4b!F7) -> 0.036666667 | AG7: =(E4b!H7-U7-(E4b!G7-T7))/(E4b!H7-E4b!G7) -> 0.044444444 | AH7: =(E4b!I7-V7-(E4b!H7-U7))/(E4b!I7-E4b!H7) -> 0.073333333 | AI7: =(E4b!J7-W7-(E4b!I7-V7))/(E4b!J7-E4b!I7) -> 0.11333333 | ... AM7: =(E4b!N7-AA7-(E4b!M7-Z7))/(E4b!N7-E4b!M7) -> 0.2
A8: 2030 | B8: =B7+(B$13-B$4)/9 -> 0 | C8: =C7+(C$13-C$4)/9 -> 0 | D8: =D7+(D$13-D$4)/9 -> 0 | E8: =E7+(E$13-E$4)/9 -> 0.0055555556 | F8: =F7+(F$13-F$4)/9 -> 0.011666667 | G8: =G7+(G$13-G$4)/9 -> 0.018888889 | H8: =H7+(H$13-H$4)/9 -> 0.034444444 | I8: =I7+(I$13-I$4)/9 -> 0.054444444 | ... M8: =M7+(M$13-M$4)/9 -> 0.2 | O8: =(1-B8)*E4b!B8 -> 5 | P8: =(1-C8)*E4b!C8 -> 8 | Q8: =(1-D8)*E4b!D8 -> 10 | R8: =(1-E8)*E4b!E8 -> 11.933333 | S8: =(1-F8)*E4b!F8 -> 14.825 | T8: =(1-G8)*E4b!G8 -> 19.622222 | U8: =(1-H8)*E4b!H8 -> 48.277778 | V8: =(1-I8)*E4b!I8 -> 94.555556 | ... Z8: =(1-M8)*E4b!M8 -> 4000 | AA8: 0 | AB8: =(E4b!C8-P8-(E4b!B8-O8))/(E4b!C8-E4b!B8) -> 0 | AC8: =(E4b!D8-Q8-(E4b!C8-P8))/(E4b!D8-E4b!C8) -> 0 | AD8: =(E4b!E8-R8-(E4b!D8-Q8))/(E4b!E8-E4b!D8) -> 0.033333333 | AE8: =(E4b!F8-S8-(E4b!E8-R8))/(E4b!F8-E4b!E8) -> 0.036111111 | AF8: =(E4b!G8-T8-(E4b!F8-S8))/(E4b!G8-E4b!F8) -> 0.040555556 | AG8: =(E4b!H8-U8-(E4b!G8-T8))/(E4b!H8-E4b!G8) -> 0.044814815 | AH8: =(E4b!I8-V8-(E4b!H8-U8))/(E4b!I8-E4b!H8) -> 0.074444444 | AI8: =(E4b!J8-W8-(E4b!I8-V8))/(E4b!J8-E4b!I8) -> 0.11444444 | ... AM8: =(E4b!N8-AA8-(E4b!M8-Z8))/(E4b!N8-E4b!M8) -> 0.2
A9: 2031 | B9: =B8+(B$13-B$4)/9 -> 0 | C9: =C8+(C$13-C$4)/9 -> 0 | D9: =D8+(D$13-D$4)/9 -> 0 | E9: =E8+(E$13-E$4)/9 -> 0.0064444444 | F9: =F8+(F$13-F$4)/9 -> 0.013333333 | G9: =G8+(G$13-G$4)/9 -> 0.021111111 | H9: =H8+(H$13-H$4)/9 -> 0.035555556 | I9: =I8+(I$13-I$4)/9 -> 0.055555556 | ... M9: =M8+(M$13-M$4)/9 -> 0.2 | O9: =(1-B9)*E4b!B9 -> 5 | P9: =(1-C9)*E4b!C9 -> 8 | Q9: =(1-D9)*E4b!D9 -> 10 | R9: =(1-E9)*E4b!E9 -> 11.922667 | S9: =(1-F9)*E4b!F9 -> 14.8 | T9: =(1-G9)*E4b!G9 -> 19.577778 | U9: =(1-H9)*E4b!H9 -> 48.222222 | V9: =(1-I9)*E4b!I9 -> 94.444444 | ... Z9: =(1-M9)*E4b!M9 -> 4000 | AA9: 0 | AB9: =(E4b!C9-P9-(E4b!B9-O9))/(E4b!C9-E4b!B9) -> 0 | AC9: =(E4b!D9-Q9-(E4b!C9-P9))/(E4b!D9-E4b!C9) -> 0 | AD9: =(E4b!E9-R9-(E4b!D9-Q9))/(E4b!E9-E4b!D9) -> 0.038666667 | AE9: =(E4b!F9-S9-(E4b!E9-R9))/(E4b!F9-E4b!E9) -> 0.040888889 | AF9: =(E4b!G9-T9-(E4b!F9-S9))/(E4b!G9-E4b!F9) -> 0.044444444 | AG9: =(E4b!H9-U9-(E4b!G9-T9))/(E4b!H9-E4b!G9) -> 0.045185185 | AH9: =(E4b!I9-V9-(E4b!H9-U9))/(E4b!I9-E4b!H9) -> 0.075555556 | AI9: =(E4b!J9-W9-(E4b!I9-V9))/(E4b!J9-E4b!I9) -> 0.11555556 | ... AM9: =(E4b!N9-AA9-(E4b!M9-Z9))/(E4b!N9-E4b!M9) -> 0.2
A10: 2032 | B10: =B9+(B$13-B$4)/9 -> 0 | C10: =C9+(C$13-C$4)/9 -> 0 | D10: =D9+(D$13-D$4)/9 -> 0 | E10: =E9+(E$13-E$4)/9 -> 0.0073333333 | F10: =F9+(F$13-F$4)/9 -> 0.015 | G10: =G9+(G$13-G$4)/9 -> 0.023333333 | H10: =H9+(H$13-H$4)/9 -> 0.036666667 | I10: =I9+(I$13-I$4)/9 -> 0.056666667 | ... M10: =M9+(M$13-M$4)/9 -> 0.2 | O10: =(1-B10)*E4b!B10 -> 5 | P10: =(1-C10)*E4b!C10 -> 8 | Q10: =(1-D10)*E4b!D10 -> 10 | R10: =(1-E10)*E4b!E10 -> 11.912 | S10: =(1-F10)*E4b!F10 -> 14.775 | T10: =(1-G10)*E4b!G10 -> 19.533333 | U10: =(1-H10)*E4b!H10 -> 48.166667 | V10: =(1-I10)*E4b!I10 -> 94.333333 | ... Z10: =(1-M10)*E4b!M10 -> 4000 | AA10: 0 | AB10: =(E4b!C10-P10-(E4b!B10-O10))/(E4b!C10-E4b!B10) -> 0 | AC10: =(E4b!D10-Q10-(E4b!C10-P10))/(E4b!D10-E4b!C10) -> 0 | AD10: =(E4b!E10-R10-(E4b!D10-Q10))/(E4b!E10-E4b!D10) -> 0.044 | AE10: =(E4b!F10-S10-(E4b!E10-R10))/(E4b!F10-E4b!E10) -> 0.045666667 | AF10: =(E4b!G10-T10-(E4b!F10-S10))/(E4b!G10-E4b!F10) -> 0.048333333 | AG10: =(E4b!H10-U10-(E4b!G10-T10))/(E4b!H10-E4b!G10) -> 0.045555556 | AH10: =(E4b!I10-V10-(E4b!H10-U10))/(E4b!I10-E4b!H10) -> 0.076666667 | AI10: =(E4b!J10-W10-(E4b!I10-V10))/(E4b!J10-E4b!I10) -> 0.11666667 | ... AM10: =(E4b!N10-AA10-(E4b!M10-Z10))/(E4b!N10-E4b!M10) -> 0.2
A11: 2033 | B11: =B10+(B$13-B$4)/9 -> 0 | C11: =C10+(C$13-C$4)/9 -> 0 | D11: =D10+(D$13-D$4)/9 -> 0 | E11: =E10+(E$13-E$4)/9 -> 0.0082222222 | F11: =F10+(F$13-F$4)/9 -> 0.016666667 | G11: =G10+(G$13-G$4)/9 -> 0.025555556 | H11: =H10+(H$13-H$4)/9 -> 0.037777778 | I11: =I10+(I$13-I$4)/9 -> 0.057777778 | ... M11: =M10+(M$13-M$4)/9 -> 0.2 | O11: =(1-B11)*E4b!B11 -> 5 | P11: =(1-C11)*E4b!C11 -> 8 | Q11: =(1-D11)*E4b!D11 -> 10 | R11: =(1-E11)*E4b!E11 -> 11.901333 | S11: =(1-F11)*E4b!F11 -> 14.75 | T11: =(1-G11)*E4b!G11 -> 19.488889 | U11: =(1-H11)*E4b!H11 -> 48.111111 | V11: =(1-I11)*E4b!I11 -> 94.222222 | ... Z11: =(1-M11)*E4b!M11 -> 4000 | AA11: 1 | AB11: =(E4b!C11-P11-(E4b!B11-O11))/(E4b!C11-E4b!B11) -> 0 | AC11: =(E4b!D11-Q11-(E4b!C11-P11))/(E4b!D11-E4b!C11) -> 0 | AD11: =(E4b!E11-R11-(E4b!D11-Q11))/(E4b!E11-E4b!D11) -> 0.049333333 | AE11: =(E4b!F11-S11-(E4b!E11-R11))/(E4b!F11-E4b!E11) -> 0.050444444 | AF11: =(E4b!G11-T11-(E4b!F11-S11))/(E4b!G11-E4b!F11) -> 0.052222222 | AG11: =(E4b!H11-U11-(E4b!G11-T11))/(E4b!H11-E4b!G11) -> 0.045925926 | AH11: =(E4b!I11-V11-(E4b!H11-U11))/(E4b!I11-E4b!H11) -> 0.077777778 | AI11: =(E4b!J11-W11-(E4b!I11-V11))/(E4b!J11-E4b!I11) -> 0.11777778 | ... AM11: =(E4b!N11-AA11-(E4b!M11-Z11))/(E4b!N11-E4b!M11) -> 0.2002
A12: 2034 | B12: =B11+(B$13-B$4)/9 -> 0 | C12: =C11+(C$13-C$4)/9 -> 0 | D12: =D11+(D$13-D$4)/9 -> 0 | E12: =E11+(E$13-E$4)/9 -> 0.0091111111 | F12: =F11+(F$13-F$4)/9 -> 0.018333333 | G12: =G11+(G$13-G$4)/9 -> 0.027777778 | H12: =H11+(H$13-H$4)/9 -> 0.038888889 | I12: =I11+(I$13-I$4)/9 -> 0.058888889 | ... M12: =M11+(M$13-M$4)/9 -> 0.2 | O12: =(1-B12)*E4b!B12 -> 5 | P12: =(1-C12)*E4b!C12 -> 8 | Q12: =(1-D12)*E4b!D12 -> 10 | R12: =(1-E12)*E4b!E12 -> 11.890667 | S12: =(1-F12)*E4b!F12 -> 14.725 | T12: =(1-G12)*E4b!G12 -> 19.444444 | U12: =(1-H12)*E4b!H12 -> 48.055556 | V12: =(1-I12)*E4b!I12 -> 94.111111 | ... Z12: =(1-M12)*E4b!M12 -> 4000 | AA12: 1 | AB12: =(E4b!C12-P12-(E4b!B12-O12))/(E4b!C12-E4b!B12) -> 0 | AC12: =(E4b!D12-Q12-(E4b!C12-P12))/(E4b!D12-E4b!C12) -> 0 | AD12: =(E4b!E12-R12-(E4b!D12-Q12))/(E4b!E12-E4b!D12) -> 0.054666667 | AE12: =(E4b!F12-S12-(E4b!E12-R12))/(E4b!F12-E4b!E12) -> 0.055222222 | AF12: =(E4b!G12-T12-(E4b!F12-S12))/(E4b!G12-E4b!F12) -> 0.056111111 | AG12: =(E4b!H12-U12-(E4b!G12-T12))/(E4b!H12-E4b!G12) -> 0.046296296 | AH12: =(E4b!I12-V12-(E4b!H12-U12))/(E4b!I12-E4b!H12) -> 0.078888889 | AI12: =(E4b!J12-W12-(E4b!I12-V12))/(E4b!J12-E4b!I12) -> 0.11888889 | ... AM12: =(E4b!N12-AA12-(E4b!M12-Z12))/(E4b!N12-E4b!M12) -> 0.2002
A13: 2035 | B13: 0 | C13: 0 | D13: 0 | E13: 0.01 | F13: 0.02 | G13: 0.03 | H13: 0.04 | I13: 0.06 | J13: 0.09 | K13: 0.1 | L13: 0.15 | M13: 0.2 | O13: =(1-B13)*E4b!B13 -> 5 | P13: =(1-C13)*E4b!C13 -> 8 | Q13: =(1-D13)*E4b!D13 -> 10 | R13: =(1-E13)*E4b!E13 -> 11.88 | S13: =(1-F13)*E4b!F13 -> 14.7 | T13: =(1-G13)*E4b!G13 -> 19.4 | U13: =(1-H13)*E4b!H13 -> 48 | V13: =(1-I13)*E4b!I13 -> 94 | ... Z13: =(1-M13)*E4b!M13 -> 4000 | AA13: 1 | AB13: =(E4b!C13-P13-(E4b!B13-O13))/(E4b!C13-E4b!B13) -> 0 | AC13: =(E4b!D13-Q13-(E4b!C13-P13))/(E4b!D13-E4b!C13) -> 0 | AD13: =(E4b!E13-R13-(E4b!D13-Q13))/(E4b!E13-E4b!D13) -> 0.06 | AE13: =(E4b!F13-S13-(E4b!E13-R13))/(E4b!F13-E4b!E13) -> 0.06 | AF13: =(E4b!G13-T13-(E4b!F13-S13))/(E4b!G13-E4b!F13) -> 0.06 | AG13: =(E4b!H13-U13-(E4b!G13-T13))/(E4b!H13-E4b!G13) -> 0.046666667 | AH13: =(E4b!I13-V13-(E4b!H13-U13))/(E4b!I13-E4b!H13) -> 0.08 | AI13: =(E4b!J13-W13-(E4b!I13-V13))/(E4b!J13-E4b!I13) -> 0.12 | ... AM13: =(E4b!N13-AA13-(E4b!M13-Z13))/(E4b!N13-E4b!M13) -> 0.2002
A14: 2036 | B14: =B13+(B$28-B$13)/15 -> 0 | C14: =C13+(C$28-C$13)/15 -> 0 | D14: =D13+(D$28-D$13)/15 -> 0 | E14: =E13+(E$28-E$13)/15 -> 0.010666667 | F14: =F13+(F$28-F$13)/15 -> 0.020666667 | G14: =G13+(G$28-G$13)/15 -> 0.031333333 | H14: =H13+(H$28-H$13)/15 -> 0.041333333 | I14: =I13+(I$28-I$13)/15 -> 0.061333333 | ... M14: =M13+(M$28-M$13)/15 -> 0.2 | O14: =(1-B14)*E4b!B14 -> 4.9333333 | P14: =(1-C14)*E4b!C14 -> 7.8 | Q14: =(1-D14)*E4b!D14 -> 9.8666667 | R14: =(1-E14)*E4b!E14 -> 11.740089 | S14: =(1-F14)*E4b!F14 -> 14.69 | T14: =(1-G14)*E4b!G14 -> 19.373333 | U14: =(1-H14)*E4b!H14 -> 47.933333 | V14: =(1-I14)*E4b!I14 -> 93.866667 | ... Z14: =(1-M14)*E4b!M14 -> 4000 | AA14: 2 | AB14: =(E4b!C14-P14-(E4b!B14-O14))/(E4b!C14-E4b!B14) -> 0 | AC14: =(E4b!D14-Q14-(E4b!C14-P14))/(E4b!D14-E4b!C14) -> 0 | AD14: =(E4b!E14-R14-(E4b!D14-Q14))/(E4b!E14-E4b!D14) -> 0.063288889 | AE14: =(E4b!F14-S14-(E4b!E14-R14))/(E4b!F14-E4b!E14) -> 0.058539007 | AF14: =(E4b!G14-T14-(E4b!F14-S14))/(E4b!G14-E4b!F14) -> 0.063333333 | AG14: =(E4b!H14-U14-(E4b!G14-T14))/(E4b!H14-E4b!G14) -> 0.048 | AH14: =(E4b!I14-V14-(E4b!H14-U14))/(E4b!I14-E4b!H14) -> 0.081333333 | AI14: =(E4b!J14-W14-(E4b!I14-V14))/(E4b!J14-E4b!I14) -> 0.12 | ... AM14: =(E4b!N14-AA14-(E4b!M14-Z14))/(E4b!N14-E4b!M14) -> 0.2004
