Workbook
Name __ISC01: #REF!
Name __ISC01: #REF!
Name __ISC01: #REF!
Name __ISC01: #REF!
Name __ISC2: #REF!
Name __ISC2: #REF!
Name __ISC2: #REF!
Name __ISC2: #REF!
Name __ISC3: #REF!+#REF!
Name __ISC3: #REF!+#REF!
Name __ISC3: #REF!+#REF!
Name __ISC3: #REF!+#REF!
Name __ISC567: #REF!
Name __ISC567: #REF!
Name __ISC567: #REF!
Name __ISC567: #REF!
Name _10000: #REF!
Name _10000: #REF!
Name _10000: #REF!
Name _10000: #REF!
Name _1080: #REF!
Name _1080: #REF!
Name _1080: #REF!
Name _1080: #REF!
Name _1090: #REF!
Name _1090: #REF!
Name _1090: #REF!
Name _1090: #REF!
Name _1100: #REF!
Name _1100: #REF!
Name _1100: #REF!
Name _1100: #REF!
Name _1110: #REF!
Name _1110: #REF!
Name _1110: #REF!
Name _1110: #REF!
Name _2: #REF!
Name _2: #REF!
Name _2: #REF!
Name _2: #REF!
Name _2010: #REF!
Name _2010: #REF!
Name _2010: #REF!
Name _2010: #REF!
Name _2080: #REF!
Name _2080: #REF!
Name _2080: #REF!
Name _2080: #REF!
Name _2090: #REF!
Name _2090: #REF!
Name _2090: #REF!
Name _2090: #REF!
Name _2100: #REF!
Name _2100: #REF!
Name _2100: #REF!
Name _2100: #REF!
Name _2110: #REF!
Name _2110: #REF!
Name _2110: #REF!
Name _2110: #REF!

Sheet ReadMe
A1: Country-Level Input-Output Analysis - Inputs used by : | D1: "Total Economy" | G1: A-Matrix Coefficients & Domestic Share
B5: O0p | C5: Share by Sector in Total Economy Output (Current Price, MER)
B6: Oxs | C6: Share by Countries in Total Economy and Sectoral Output (Current Price, MER)
B7: Ox | C7: ="A-Matrix by Sector and Country: Inputs used by Total Economy as a Share of Total Economy Output (Current Price, MER)" -> A-Matrix by Sector and Country: Inputs used by Total Economy as a Share of Total Economy Output (Current Price, MER)
B8: Px | C8: Inputs used by Total Economy: Domestic Sectoral Inputs Used as Share of Total Sectoral Inputs (Current Price MER)
B9: Qx | C9: ="Import, Export, Consumption, Investment, Intermediate Consumption as Share of Total Economy Supply (Output & Import) (Current Price MER)" -> Import, Export, Consumption, Investment, Intermediate Consumption as Share of Total Economy Supply (Output & Import) (Current Price MER)
B10: Qxo | C10: ="Import, Export, Consumption, Investment as Share of Sector Output (Current Price MER)" -> Import, Export, Consumption, Investment as Share of Sector Output (Current Price MER)
B11: Qxg | C11: ="Import, Export as Share of Sector Gross Final Expenditure (Current Price MER)" -> Import, Export as Share of Sector Gross Final Expenditure (Current Price MER)
B14: Sheet Number | C14: Sector Name
B15: 1 | C15: Food
B16: 2a | C16: Housing Services
B17: 2b | C17: Construction
B18: 3 | C18: Manufacturing
B19: 4 | C19: Energy
B20: 5 | C20: Education/Health
B21: 6 | C21: Leisure/Culture
B22: 7 | C22: Transport
B23: 8 | C23: Other services

Sheet O0p
A1: Data series on Output: Share of each Sector in World Output (current price MER).
A4: Year | B4: Food | C4: Housing Services | D4: Construction | E4: Manufacturing | F4: Energy | G4: Education/Health | H4: Leisure/Culture | I4: Transport | J4: Other Services
A5: 1970 | B5: 0.13011013 | C5: 0.041268213 | D5: 0.07636786 | E5: 0.22325366 | F5: 0.091736303 | G5: 0.11176989 | H5: 0.17203991 | I5: 0.053878158 | J5: 0.099575878
A6: 1971 | B6: 0.12730089 | C6: 0.041872162 | D6: 0.078196674 | E6: 0.22122856 | F6: 0.092831563 | G6: 0.11280852 | H6: 0.17106556 | I6: 0.053668343 | J6: 0.10102774
A7: 1972 | B7: 0.12509748 | C7: 0.041786929 | D7: 0.079433067 | E7: 0.22160528 | F7: 0.095639751 | G7: 0.11222399 | H7: 0.17024148 | I7: 0.053260414 | J7: 0.1007116
A8: 1973 | B8: 0.12720901 | C8: 0.04137314 | D8: 0.079959448 | E8: 0.22663792 | F8: 0.096597543 | G8: 0.10741486 | H8: 0.16777216 | I8: 0.053494515 | J8: 0.099541396
A9: 1974 | B9: 0.12453557 | C9: 0.0410281 | D9: 0.076376825 | E9: 0.22880268 | F9: 0.099539905 | G9: 0.10823161 | H9: 0.1678907 | I9: 0.054571305 | J9: 0.099023302
A10: 1975 | B10: 0.12336313 | C10: 0.041592613 | D10: 0.075203491 | E10: 0.21964987 | F10: 0.1045351 | G10: 0.11365598 | H10: 0.16682973 | I10: 0.053823261 | J10: 0.10134681
A11: 1976 | B11: 0.11968605 | C11: 0.04154111 | D11: 0.073418887 | E11: 0.22210652 | F11: 0.10694338 | G11: 0.11283617 | H11: 0.16870562 | I11: 0.05374722 | J11: 0.10101505
A12: 1977 | B12: 0.11735945 | C12: 0.041758704 | D12: 0.073546704 | E12: 0.22363047 | F12: 0.10713334 | G12: 0.11206693 | H12: 0.16911727 | I12: 0.053725162 | J12: 0.10166196
A13: 1978 | B13: 0.11529055 | C13: 0.04226945 | D13: 0.075307961 | E13: 0.22553659 | F13: 0.10509666 | G13: 0.11150372 | H13: 0.16823571 | I13: 0.054000489 | J13: 0.10275888
A14: 1979 | B14: 0.11453069 | C14: 0.042241251 | D14: 0.07560641 | E14: 0.2262923 | F14: 0.1057682 | G14: 0.11082718 | H14: 0.16724275 | I14: 0.054001017 | J14: 0.1034902
A15: 1980 | B15: 0.11231473 | C15: 0.042268018 | D15: 0.073758775 | E15: 0.22295553 | F15: 0.110867 | G15: 0.11082175 | H15: 0.16852532 | I15: 0.054568906 | J15: 0.10391998
A16: 1981 | B16: 0.111456 | C16: 0.043606078 | D16: 0.07221973 | E16: 0.22074951 | F16: 0.10868805 | G16: 0.1144707 | H16: 0.16874476 | I16: 0.053788482 | J16: 0.10627669
... A60: 2025 | B60: 0.082464744 | C60: 0.051913312 | D60: 0.073769242 | E60: 0.19932942 | F60: 0.088593311 | G60: 0.12524772 | H60: 0.15893735 | I60: 0.052653975 | J60: 0.16709093
A61: 2026
A62: 2027
A63: 2028
A64: 2029
A65: 2030
A66: 2031
A67: 2032
A68: 2033
A69: 2034
A70: 2035
A71: 2036
A72: 2037
... A135: 2100

Sheet O0s
A1: ="Data series on Output: Country and Region Output Shares in Total Economy (current price MER)." -> Data series on Output: Country and Region Output Shares in Total Economy (current price MER).
A4: Year | B4: World | C4: Europe | D4: North America/ Oceania | E4: Latin America | F4: Middle East/North Africa | G4: Subsaharan Africa | H4: Russia/ Central Asia | I4: East Asia | J4: South & South-East Asia | K4: DE | L4: DK | M4: ES | N4: FR | O4: GB | P4: IT | Q4: NL | R4: NO | S4: SE | T4: OC | U4: QM | V4: US | W4: CA | X4: AU | Y4: NZ | Z4: OH | AA4: AR | AB4: BR | AC4: CL | AD4: CO | AE4: MX | AF4: OD | AG4: AE | AH4: DZ | AI4: EG | AJ4: IR | AK4: MA | AL4: SA | AM4: TR | AN4: OE | AO4: CD | AP4: CI | AQ4: ET | AR4: KE | AS4: ML | AT4: NE | AU4: NG | AV4: RW | AW4: SD | AX4: ZA | AY4: OJ | AZ4: RU | BA4: OA | BB4: CN | BC4: JP | BD4: KR | BE4: TW | BF4: OB | BG4: BD | BH4: IN | BI4: ID | BJ4: MM | BK4: PK | BL4: PH | BM4: TH | BN4: VN | BO4: OI
A5: 1970 | B5: =SUM(C5:J5) -> 1 | C5: =SUM(K5:U5) -> 0.27507175 | D5: =SUM(V5:Z5) -> 0.31536158 | E5: =SUM(AA5:AF5) -> 0.048569818 | F5: =SUM(AG5:AN5) -> 0.025811883 | G5: =SUM(AO5:AY5) -> 0.046783071 | H5: =SUM(AZ5:BA5) -> 0.15302459 | I5: =SUM(BB5:BF5) -> 0.1026282 | J5: =SUM(BG5:BO5) -> 0.032749117 | K5: 0.061284526 | L5: 0.0048574984 | M5: 0.012041241 | N5: 0.048589091 | O5: 0.035131571 | P5: 0.036306901 | Q5: 0.0099245391 | R5: 0.0036583097 | S5: 0.012167034 | T5: 0.032888467 | U5: 0.028177936 | V5: 0.28899227 | W5: 0.021335026 | X5: 0.013789947 | Y5: 0.0019978605 | Z5: 0.00066000323 | AA5: 0.0092829649 | AB5: 0.010367237 | AC5: 0.0024718872 | AD5: 0.0031099383 | AE5: 0.014816558 | AF5: 0.014304685 | AG5: 0.00052568142 | AH5: 0.0019941471 | AI5: 0.0020008396 | AJ5: 0.0040584669 | AK5: 0.001199641 | AL5: 0.0015865038 | AM5: 0.0069905276 | AN5: 0.0083902566 | AO5: 0.0010424719 | AP5: 0.0004197359 | AQ5: 0.00060205286 | AR5: 0.00070143204 | AS5: 8.1446947e-05 | AT5: 0.00014770632 | AU5: 0.011292118 | AV5: 5.7916561e-05 | AW5: 0.00020148876 | AX5: 0.0049791637 | AY5: 0.007991758 | AZ5: 0.10197299 | BA5: 0.03733129 | BB5: 0.029242668 | BC5: 0.069746252 | BD5: 0.0032117506 | BE5: 0.0018040895 | BF5: 0.0023377432 | BG5: 0.0014133553 | BH5: 0.016900343 | BI5: 0.0027636786 | BJ5: 0.00076428425 | BK5: 0.0037530852 | BL5: 0.0018420935 | BM5: 0.002279489 | BN5: 0.00072576613 | BO5: 0.0034922752
A6: 1971 | B6: =SUM(C6:J6) -> 1 | C6: =SUM(K6:U6) -> 0.28055955 | D6: =SUM(V6:Z6) -> 0.31028974 | E6: =SUM(AA6:AF6) -> 0.048987944 | F6: =SUM(AG6:AN6) -> 0.026529026 | G6: =SUM(AO6:AY6) -> 0.049041749 | H6: =SUM(AZ6:BA6) -> 0.14729209 | I6: =SUM(BB6:BF6) -> 0.10369281 | J6: =SUM(BG6:BO6) -> 0.033607097 | K6: 0.064224484 | L6: 0.0048443794 | M6: 0.012290292 | N6: 0.049245785 | O6: 0.035989499 | P6: 0.036022452 | Q6: 0.010738692 | R6: 0.0038128282 | S6: 0.012009324 | T6: 0.03430496 | U6: 0.028170318 | V6: 0.28357852 | W6: 0.022078462 | X6: 0.014049696 | Y6: 0.0021718845 | Z6: 0.00068019499 | AA6: 0.0099535724 | AB6: 0.010455638 | AC6: 0.0026420127 | AD6: 0.0030345304 | AE6: 0.014524259 | AF6: 0.014175092 | AG6: 0.00066674721 | AH6: 0.0019137782 | AI6: 0.0019593049 | AJ6: 0.0046832443 | AK6: 0.0011816781 | AL6: 0.001942994 | AM6: 0.0060381114 | AN6: 0.0091921386 | AO6: 0.001128303 | AP6: 0.00042894565 | AQ6: 0.00060270416 | AR6: 0.00075253928 | AS6: 8.6618143e-05 | AT6: 0.00015323822 | AU6: 0.012273633 | AV6: 6.7397456e-05 | AW6: 0.00021253434 | AX6: 0.0053489607 | AY6: 0.0084247373 | AZ6: 0.096134768 | BA6: 0.035081937 | BB6: 0.028661236 | BC6: 0.071483284 | BD6: 0.0032317447 | BE6: 0.0019911764 | BF6: 0.0024254334 | BG6: 0.0011769587 | BH6: 0.017654975 | BI6: 0.002801996 | BJ6: 0.00074939193 | BK6: 0.0038485708 | BL6: 0.001968688 | BM6: 0.0022818957 | BN6: 0.00076513277 | BO6: 0.0036883303
A7: 1972 | B7: =SUM(C7:J7) -> 1 | C7: =SUM(K7:U7) -> 0.28468991 | D7: =SUM(V7:Z7) -> 0.29590173 | E7: =SUM(AA7:AF7) -> 0.051794224 | F7: =SUM(AG7:AN7) -> 0.0290637 | G7: =SUM(AO7:AY7) -> 0.048433274 | H7: =SUM(AZ7:BA7) -> 0.14768911 | I7: =SUM(BB7:BF7) -> 0.11291609 | J7: =SUM(BG7:BO7) -> 0.029511965 | K7: 0.066369659 | L7: 0.0049861346 | M7: 0.013504158 | N7: 0.051311243 | O7: 0.034947622 | P7: 0.036143498 | Q7: 0.011283062 | R7: 0.0038816296 | S7: 0.01223992 | T7: 0.035461714 | U7: 0.027204376 | V7: 0.27013643 | W7: 0.021714351 | X7: 0.014192011 | Y7: 0.002306 | Z7: 0.00069397156 | AA7: 0.012895854 | AB7: 0.01158158 | AC7: 0.0024638678 | AD7: 0.0029229572 | AE7: 0.014417518 | AF7: 0.013641196 | AG7: 0.00091152863 | AH7: 0.0023049524 | AI7: 0.0017650568 | AJ7: 0.0052676405 | AK7: 0.0012598206 | AL7: 0.002342925 | AM7: 0.0067435203 | AN7: 0.009758978 | AO7: 0.0010586673 | AP7: 0.00042236945 | AQ7: 0.00057112519 | AR7: 0.00071557178 | AS7: 9.044322e-05 | AT7: 0.00016294895 | AU7: 0.012572183 | AV7: 6.4315803e-05 | AW7: 0.0002100452 | AX7: 0.0048093048 | AY7: 0.0078789948 | AZ7: 0.093428961 | BA7: 0.034608605 | BB7: 0.028462533 | BC7: 0.081949763 | BD7: 0.0030516061 | BE7: 0.0019331416 | BF7: 0.0025336584 | BG7: 0.001283764 | BH7: 0.015884957 | BI7: 0.0028100162 | BJ7: 0.00058641036 | BK7: 0.0020647578 | BL7: 0.0018115524 | BM7: 0.0021405557 | BN7: 0.00069886122 | BO7: 0.0035417195
A8: 1973 | B8: =SUM(C8:J8) -> 1 | C8: =SUM(K8:U8) -> 0.30019658 | D8: =SUM(V8:Z8) -> 0.27477691 | E8: =SUM(AA8:AF8) -> 0.058604555 | F8: =SUM(AG8:AN8) -> 0.030666184 | G8: =SUM(AO8:AY8) -> 0.041431712 | H8: =SUM(AZ8:BA8) -> 0.14085715 | I8: =SUM(BB8:BF8) -> 0.12468934 | J8: =SUM(BG8:BO8) -> 0.028777578 | K8: 0.071229013 | L8: 0.0054538903 | M8: 0.014603426 | N8: 0.054338079 | O8: 0.034817545 | P8: 0.035616899 | Q8: 0.012071124 | R8: 0.0041576121 | S8: 0.012227764 | T8: 0.038625427 | U8: 0.026871081 | V8: 0.24451729 | W8: 0.020361013 | X8: 0.015638917 | Y8: 0.0024871183 | Z8: 0.00075672989 | AA8: 0.018089986 | AB8: 0.013368369 | AC8: 0.0028622031 | AD8: 0.0028254098 | AE8: 0.014537326 | AF8: 0.013149863 | AG8: 0.0013658055 | AH8: 0.0023155517 | AI8: 0.0016129566 | AJ8: 0.0063403607 | AK8: 0.0012357639 | AL8: 0.0028249851 | AM8: 0.0067439123 | AN8: 0.0092295155 | AO8: 0.0010412312 | AP8: 0.00044052739 | AQ8: 0.00052174803 | AR8: 0.00065191531 | AS8: 8.0694128e-05 | AT8: 0.00013377623 | AU8: 0.010612975 | AV8: 6.1472831e-05 | AW8: 0.00020472466 | AX8: 0.0050782894 | AY8: 0.0071499188 | AZ8: 0.091549853 | BA8: 0.033713248 | BB8: 0.028992812 | BC8: 0.091625655 | BD8: 0.0032699744 | BE8: 0.0023521499 | BF8: 0.0025256083 | BG8: 0.0015364261 | BH8: 0.014637574 | BI8: 0.0031919639 | BJ8: 0.00058328671 | BK8: 0.0017651525 | BL8: 0.0017633741 | BM8: 0.0021755989 | BN8: 0.00056093561 | BO8: 0.0035041834
A9: 1974 | B9: =SUM(C9:J9) -> 1 | C9: =SUM(K9:U9) -> 0.30262619 | D9: =SUM(V9:Z9) -> 0.26701028 | E9: =SUM(AA9:AF9) -> 0.065035689 | F9: =SUM(AG9:AN9) -> 0.043483569 | G9: =SUM(AO9:AY9) -> 0.047081069 | H9: =SUM(AZ9:BA9) -> 0.11919438 | I9: =SUM(BB9:BF9) -> 0.12399398 | J9: =SUM(BG9:BO9) -> 0.031574846 | K9: 0.071207914 | L9: 0.0053403114 | M9: 0.015660971 | N9: 0.051809461 | O9: 0.03566917 | P9: 0.037037487 | Q9: 0.01283891 | R9: 0.0044431681 | S9: 0.011797934 | T9: 0.041050534 | U9: 0.026761391 | V9: 0.23581681 | W9: 0.021790905 | X9: 0.015781148 | Y9: 0.0025212018 | Z9: 0.00079773572 | AA9: 0.020596549 | AB9: 0.014917834 | AC9: 0.0022974814 | AD9: 0.0027919395 | AE9: 0.015791026 | AF9: 0.014492193 | AG9: 0.0030967215 | AH9: 0.0028040325 | AI9: 0.0016246597 | AJ9: 0.0089031861 | AK9: 0.0013335376 | AL9: 0.0072308914 | AM9: 0.0081686566 | AN9: 0.01190116 | AO9: 0.0011027354 | AP9: 0.00046290285 | AQ9: 0.00048257961 | AR9: 0.00067259576 | AS9: 6.5774239e-05 | AT9: 0.00013343957 | AU9: 0.014039393 | AV9: 7.0555093e-05 | AW9: 0.00022193148 | AX9: 0.0055103714 | AY9: 0.0072968239 | AZ9: 0.075138537 | BA9: 0.027308515 | BB9: 0.02707511 | BC9: 0.092025753 | BD9: 0.0041893373 | BE9: 0.0027042115 | BF9: 0.0025029012 | BG9: 0.0020366269 | BH9: 0.014883488 | BI9: 0.0043477761 | BJ9: 0.00061385538 | BK9: 0.0019836729 | BL9: 0.0020979201 | BM9: 0.0024065322 | BN9: 0.00052532309 | BO9: 0.0038264155
A10: 1975 | B10: =SUM(C10:J10) -> 1 | C10: =SUM(K10:U10) -> 0.31567453 | D10: =SUM(V10:Z10) -> 0.25757693 | E10: =SUM(AA10:AF10) -> 0.054635449 | F10: =SUM(AG10:AN10) -> 0.045566708 | G10: =SUM(AO10:AY10) -> 0.056172952 | H10: =SUM(AZ10:BA10) -> 0.12031337 | I10: =SUM(BB10:BF10) -> 0.11824594 | J10: =SUM(BG10:BO10) -> 0.031814134 | K10: 0.07164396 | L10: 0.0056853049 | M10: 0.016657977 | N10: 0.05933866 | O10: 0.035918923 | P10: 0.037542457 | Q10: 0.013808727 | R10: 0.0049783076 | S10: 0.013020214 | T10: 0.042816957 | U10: 0.026615614 | V10: 0.22821738 | W10: 0.021339974 | X10: 0.015161495 | Y10: 0.0021713192 | Z10: 0.00076593179 | AA10: 0.0077659213 | AB10: 0.015873179 | AC10: 0.00099834315 | AD10: 0.0027986915 | AE10: 0.017907609 | AF10: 0.01516763 | AG10: 0.0036973301 | AH10: 0.0030527072 | AI10: 0.0017093655 | AJ10: 0.0099794741 | AK10: 0.0014230432 | AL10: 0.0068385104 | AM10: 0.0092494192 | AN10: 0.011399917 | AO10: 0.0011287914 | AP10: 0.00055126081 | AQ10: 0.00048057883 | AR10: 0.00070702665 | AS10: 9.3765314e-05 | AT10: 0.00016274008 | AU10: 0.017297619 | AV10: 8.079294e-05 | AW10: 0.00026223298 | AX10: 0.0055416237 | AY10: 0.0076230244 | AZ10: 0.078621764 | BA10: 0.027972411 | BB10: 0.027411972 | BC10: 0.086307537 | BD10: 0.0042039365 | BE10: 0.0025018902 | BF10: 0.0024476503 | BG10: 0.0015225596 | BH10: 0.014806787 | BI10: 0.0049591621 | BJ10: 0.00053071159 | BK10: 0.0022592163 | BL10: 0.0021658828 | BM10: 0.0024739315 | BN10: 0.00054251629 | BO10: 0.0037982767
A11: 1976 | B11: =SUM(C11:J11) -> 1 | C11: =SUM(K11:U11) -> 0.30218978 | D11: =SUM(V11:Z11) -> 0.26771132 | E11: =SUM(AA11:AF11) -> 0.057915082 | F11: =SUM(AG11:AN11) -> 0.050635708 | G11: =SUM(AO11:AY11) -> 0.060683995 | H11: =SUM(AZ11:BA11) -> 0.11001003 | I11: =SUM(BB11:BF11) -> 0.11905482 | J11: =SUM(BG11:BO11) -> 0.031799264 | K11: 0.070368619 | L11: 0.0058830842 | M11: 0.015711277 | N11: 0.056397382 | O11: 0.031538551 | P11: 0.034155263 | Q11: 0.013753834 | R11: 0.004967518 | S11: 0.013076042 | T11: 0.041935284 | U11: 0.026356812 | V11: 0.23704406 | W11: 0.023414939 | X11: 0.015123003 | Y11: 0.0019770177 | Z11: 0.00074229833 | AA11: 0.0099644436 | AB11: 0.017065209 | AC11: 0.0012561141 | AD11: 0.0030540089 | AE11: 0.016428496 | AF11: 0.015473473 | AG11: 0.0044044062 | AH11: 0.0032001496 | AI11: 0.0019571187 | AJ11: 0.011603665 | AK11: 0.0014136847 | AL11: 0.0085395113 | AM11: 0.0098493102 | AN11: 0.011670887 | AO11: 0.0010062513 | AP11: 0.00061613646 | AQ11: 0.00050512078 | AR11: 0.00071198374 | AS11: 0.00010492335 | AT11: 0.00018196892 | AU11: 0.019712258 | AV11: 8.513301e-05 | AW11: 0.00030895767 | AX11: 0.0050698254 | AY11: 0.0074662561 | AZ11: 0.073218374 | BA11: 0.025865852 | BB11: 0.023484073 | BC11: 0.089502667 | BD11: 0.0052156914 | BE11: 0.0028647137 | BF11: 0.0026971931 | BG11: 0.0010900968 | BH11: 0.013753901 | BI11: 0.0057454086 | BJ11: 0.00056009736 | BK11: 0.0024514944 | BL11: 0.0023473324 | BM11: 0.0026515336 | BN11: 0.00059784462 | BO11: 0.0038594556
A12: 1977 | B12: =SUM(C12:J12) -> 1 | C12: =SUM(K12:U12) -> 0.30324964 | D12: =SUM(V12:Z12) -> 0.26253961 | E12: =SUM(AA12:AF12) -> 0.054833436 | F12: =SUM(AG12:AN12) -> 0.053088156 | G12: =SUM(AO12:AY12) -> 0.06104521 | H12: =SUM(AZ12:BA12) -> 0.10619499 | I12: =SUM(BB12:BF12) -> 0.12538686 | J12: =SUM(BG12:BO12) -> 0.033662086 | K12: 0.071784767 | L12: 0.0057698417 | M12: 0.015381866 | N12: 0.055192425 | O12: 0.031232555 | P12: 0.034611367 | Q12: 0.014328203 | R12: 0.0051128389 | S12: 0.012389807 | T12: 0.042120362 | U12: 0.027126558 | V12: 0.23530802 | W12: 0.021422446 | X12: 0.013369957 | Y12: 0.0019455968 | Z12: 0.00071030488 | AA12: 0.0083933018 | AB12: 0.0172894 | AC12: 0.0015113128 | AD12: 0.0034654593 | AE12: 0.013204942 | AF12: 0.015454735 | AG12: 0.0051382114 | AH12: 0.0033863174 | AI12: 0.0021750902 | AJ12: 0.01254617 | AK12: 0.0014461736 | AL12: 0.0087840956 | AM12: 0.0099447586 | AN12: 0.011733262 | AO12: 0.0011681956 | AP12: 0.00074435879 | AQ12: 0.00050302705 | AR12: 0.00083392247 | AS12: 0.00011063861 | AT12: 0.00019470082 | AU12: 0.020357582 | AV12: 9.0312602e-05 | AW12: 0.00033792408 | AX12: 0.0051301913 | AY12: 0.0071832493 | AZ12: 0.071072323 | BA12: 0.024755094 | BB12: 0.023281167 | BC12: 0.09523851 | BD12: 0.0057624443 | BE12: 0.0032115786 | BF12: 0.0027725894 | BG12: 0.0011369224 | BH12: 0.014456734 | BI12: 0.0064092948 | BJ12: 0.00052807238 | BK12: 0.0025648765 | BL12: 0.002448247 | BM12: 0.0027910316 | BN12: 0.00064677816 | BO12: 0.0039900869
A13: 1978 | B13: =SUM(C13:J13) -> 1 | C13: =SUM(K13:U13) -> 0.31255964 | D13: =SUM(V13:Z13) -> 0.25109193 | E13: =SUM(AA13:AF13) -> 0.054759087 | F13: =SUM(AG13:AN13) -> 0.047719283 | G13: =SUM(AO13:AY13) -> 0.057264397 | H13: =SUM(AZ13:BA13) -> 0.10026254 | I13: =SUM(BB13:BF13) -> 0.14260303 | J13: =SUM(BG13:BO13) -> 0.033740088 | K13: 0.073485737 | L13: 0.005909208 | M13: 0.015756412 | N13: 0.057075852 | O13: 0.033147216 | P13: 0.035857327 | Q13: 0.014819072 | R13: 0.0048882332 | S13: 0.011447066 | T13: 0.043840064 | U13: 0.026575611 | V13: 0.22471094 | W13: 0.019115986 | X13: 0.012779039 | Y13: 0.0020089524 | Z13: 0.00070495206 | AA13: 0.0091122609 | AB13: 0.016558303 | AC13: 0.0014672256 | AD13: 0.0035142911 | AE13: 0.014024218 | AF13: 0.014234453 | AG13: 0.0040915082 | AH13: 0.0035342579 | AI13: 0.0021814367 | AJ13: 0.010529519 | AK13: 0.0014444159 | AL13: 0.0078532436 | AM13: 0.0090840824 | AN13: 0.010564515 | AO13: 0.0014218365 | AP13: 0.00079645084 | AQ13: 0.00046596513 | AR13: 0.00084536506 | AS13: 0.00010978707 | AT13: 0.00022568603 | AU13: 0.019083603 | AV13: 9.379702e-05 | AW13: 0.00031237046 | AX13: 0.0050795046 | AY13: 0.0069159541 | AZ13: 0.06864123 | BA13: 0.023571408 | BB13: 0.024502644 | BC13: 0.11006823 | BD13: 0.0067393801 | BE13: 0.0033788093 | BF13: 0.0025868804 | BG13: 0.0012137586 | BH13: 0.014692177 | BI13: 0.006164841 | BJ13: 0.00050547937 | BK13: 0.0024821284 | BL13: 0.0024263375 | BM13: 0.0028871607 | BN13: 0.00066896129 | BO13: 0.0038048614
A14: 1979 | B14: =SUM(C14:J14) -> 1 | C14: =SUM(K14:U14) -> 0.32782171 | D14: =SUM(V14:Z14) -> 0.242364 | E14: =SUM(AA14:AF14) -> 0.060251808 | F14: =SUM(AG14:AN14) -> 0.052048192 | G14: =SUM(AO14:AY14) -> 0.054748447 | H14: =SUM(AZ14:BA14) -> 0.09267988 | I14: =SUM(BB14:BF14) -> 0.1370753 | J14: =SUM(BG14:BO14) -> 0.033010666 | K14: 0.076994443 | L14: 0.0060058023 | M14: 0.018248204 | N14: 0.059181889 | O14: 0.036285142 | P14: 0.039165643 | Q14: 0.015341976 | R14: 0.0047569606 | S14: 0.01172969 | T14: 0.044054111 | U14: 0.02520596 | V14: 0.2158686 | W14: 0.018187352 | X14: 0.012369434 | Y14: 0.001978997 | Z14: 0.00072297338 | AA14: 0.012915306 | AB14: 0.015740106 | AC14: 0.0016953157 | AD14: 0.0036472921 | AE14: 0.015938151 | AF14: 0.014518659 | AG14: 0.0046349292 | AH14: 0.0038248301 | AI14: 0.0013042518 | AJ14: 0.010096552 | AK14: 0.0014844736 | AL14: 0.0093293699 | AM14: 0.01062581 | AN14: 0.012200419 | AO14: 0.001206424 | AP14: 0.0007961751 | AQ14: 0.0004360759 | AR14: 0.00083923784 | AS14: 0.00012014922 | AT14: 0.00025572966 | AU14: 0.019279335 | AV14: 9.9438799e-05 | AW14: 0.00028881821 | AX14: 0.0053944965 | AY14: 0.0069217385 | AZ14: 0.063705681 | BA14: 0.021771725 | BB14: 0.025722514 | BC14: 0.10160816 | BD14: 0.0074864582 | BE14: 0.0034832774 | BF14: 0.0026000765 | BG14: 0.0011759489 | BH14: 0.014420061 | BI14: 0.0052638064 | BJ14: 0.0005034896 | BK14: 0.0024795925 | BL14: 0.0025481494 | BM14: 0.0028436966 | BN14: 0.00063191031 | BO14: 0.0040651992
A15: 1980 | B15: =SUM(C15:J15) -> 1 | C15: =SUM(K15:U15) -> 0.32591414 | D15: =SUM(V15:Z15) -> 0.23550148 | E15: =SUM(AA15:AF15) -> 0.065209635 | F15: =SUM(AG15:AN15) -> 0.055617818 | G15: =SUM(AO15:AY15) -> 0.060031425 | H15: =SUM(AZ15:BA15) -> 0.088143677 | I15: =SUM(BB15:BF15) -> 0.13394738 | J15: =SUM(BG15:BO15) -> 0.03563445 | K15: 0.075237339 | L15: 0.0053836654 | M15: 0.016996435 | N15: 0.05977208 | O15: 0.040080152 | P15: 0.041769251 | Q15: 0.014966394 | R15: 0.0050909283 | S15: 0.011611935 | T15: 0.043509995 | U15: 0.021809331 | V15: 0.20926186 | W15: 0.018043629 | X15: 0.012912416 | Y15: 0.0019967355 | Z15: 0.00073914933 | AA15: 0.016329608 | AB15: 0.012817775 | AC15: 0.0019944447 | AD15: 0.0038928153 | AE15: 0.01932336 | AF15: 0.015440452 | AG15: 0.0060606206 | AH15: 0.0045065327 | AI15: 0.0015870965 | AJ15: 0.010071416 | AK15: 0.0015859034 | AL15: 0.012522071 | AM15: 0.0072421405 | AN15: 0.013802031 | AO15: 0.0010174021 | AP15: 0.00077703057 | AQ15: 0.00040560941 | AR15: 0.00086110938 | AS15: 0.00012340091 | AT15: 0.00027440318 | AU15: 0.021718085 | AV15: 9.9085478e-05 | AW15: 0.00028127932 | AX15: 0.0068836313 | AY15: 0.0071489052 | AZ15: 0.059352104 | BA15: 0.01975225 | BB15: 0.028491061 | BC15: 0.096097944 | BD15: 0.0068291369 | BE15: 0.0038938688 | BF15: 0.0028740535 | BG15: 0.0012034143 | BH15: 0.015750176 | BI15: 0.0065810788 | BJ15: 0.00049197176 | BK15: 0.0025996575 | BL15: 0.0026604922 | BM15: 0.0029487744 | BN15: 0.00018794417 | BO15: 0.0043385724
A16: 1981 | B16: =SUM(C16:J16) -> 1 | C16: =SUM(K16:U16) -> 0.29181578 | D16: =SUM(V16:Z16) -> 0.25744268 | E16: =SUM(AA16:AF16) -> 0.073300148 | F16: =SUM(AG16:AN16) -> 0.058762324 | G16: =SUM(AO16:AY16) -> 0.056269081 | H16: =SUM(AZ16:BA16) -> 0.084053346 | I16: =SUM(BB16:BF16) -> 0.13902486 | J16: =SUM(BG16:BO16) -> 0.039331776 | K16: 0.063351917 | L16: 0.0047537406 | M16: 0.015211233 | N16: 0.052145029 | O16: 0.037238741 | P16: 0.037702537 | Q16: 0.012820592 | R16: 0.0051137812 | S16: 0.010632508 | T16: 0.039243011 | U16: 0.022564694 | V16: 0.22735696 | W16: 0.020352853 | X16: 0.014856122 | Y16: 0.0020754442 | Z16: 0.00070766365 | AA16: 0.013160705 | AB16: 0.016015011 | AC16: 0.0023662959 | AD16: 0.004214419 | AE16: 0.02409495 | AF16: 0.016827883 | AG16: 0.0068446398 | AH16: 0.0047166373 | AI16: 0.0020007323 | AJ16: 0.010552806 | AK16: 0.0012913566 | AL16: 0.013870647 | AM16: 0.007499531 | AN16: 0.013790633 | AO16: 0.00089783262 | AP16: 0.00063389228 | AQ16: 0.00042008592 | AR16: 0.00080980343 | AS16: 0.00011350273 | AT16: 0.00023865328 | AU16: 0.019869855 | AV16: 0.00011080231 | AW16: 0.00033442689 | AX16: 0.007122587 | AY16: 0.0072430243 | AZ16: 0.056387954 | BA16: 0.018610325 | BB16: 0.025875133 | BC16: 0.102293 | BD16: 0.007500662 | BE16: 0.0045294254 | BF16: 0.0030962538 | BG16: 0.0011777485 | BH16: 0.016745246 | BI16: 0.0083733612 | BJ16: 0.00049170875 | BK16: 0.0030257252 | BL16: 0.0029170794 | BM16: 0.0031491779 | BN16: 0.00014802631 | BO16: 0.0045116268
... A60: 2025 | B60: =SUM(C60:J60) -> 1 | C60: =SUM(K60:U60) -> 0.23627517 | D60: =SUM(V60:Z60) -> 0.26612703 | E60: =SUM(AA60:AF60) -> 0.058960491 | F60: =SUM(AG60:AN60) -> 0.050047769 | G60: =SUM(AO60:AY60) -> 0.017072713 | H60: =SUM(AZ60:BA60) -> 0.026148013 | I60: =SUM(BB60:BF60) -> 0.26725481 | J60: =SUM(BG60:BO60) -> 0.078113995 | K60: 0.044171432 | L60: 0.0039812604 | M60: 0.015723358 | N60: 0.031485238 | O60: 0.03219259 | P60: 0.0236476 | Q60: 0.011357343 | R60: 0.0055381937 | S60: 0.0058194499 | T60: 0.034529391 | U60: 0.027970731 | V60: 0.22923474 | W60: 0.018188646 | X60: 0.015808792 | Y60: 0.0024634132 | Z60: 0.00059072778 | AA60: 0.0056689506 | AB60: 0.018622443 | AC60: 0.0026512435 | AD60: 0.003550742 | AE60: 0.014690444 | AF60: 0.013811956 | AG60: 0.0049491442 | AH60: 0.0019204421 | AI60: 0.0022235934 | AJ60: 0.0045012893 | AK60: 0.0012035713 | AL60: 0.0075822826 | AM60: 0.013208343 | AN60: 0.014489057 | AO60: 0.00044281436 | AP60: 0.00063665786 | AQ60: 0.0020025105 | AR60: 0.0010085452 | AS60: 0.00017493824 | AT60: 0.00015183153 | AU60: 0.0018188732 | AV60: 0.00010901448 | AW60: 0.00012765279 | AX60: 0.0039767813 | AY60: 0.0060347954 | AZ60: 0.018099383 | BA60: 0.0080642806 | BB60: 0.20214221 | BC60: 0.034406987 | BD60: 0.01904185 | BE60: 0.0065599162 | BF60: 0.0052638054 | BG60: 0.003775115 | BH60: 0.033512555 | BI60: 0.01107802 | BJ60: 0.00064994839 | BK60: 0.0034876139 | BL60: 0.0037813993 | BM60: 0.004589847 | BN60: 0.0076081303 | BO60: 0.0096781183
A61: 2026
A62: 2027
A63: 2028
A64: 2029
A65: 2030
A66: 2031
A67: 2032
A68: 2033
A69: 2034
A70: 2035
A71: 2036
A72: 2037
... A135: 2100

Sheet O1s
A1: Data series on Output: Country and Region Output Shares in "Food" Sector (current price MER).
A4: Year | B4: World | C4: Europe | D4: North America/ Oceania | E4: Latin America | F4: Middle East/North Africa | G4: Subsaharan Africa | H4: Russia/ Central Asia | I4: East Asia | J4: South & South-East Asia | K4: DE | L4: DK | M4: ES | N4: FR | O4: GB | P4: IT | Q4: NL | R4: NO | S4: SE | T4: OC | U4: QM | V4: US | W4: CA | X4: AU | Y4: NZ | Z4: OH | AA4: AR | AB4: BR | AC4: CL | AD4: CO | AE4: MX | AF4: OD | AG4: AE | AH4: DZ | AI4: EG | AJ4: IR | AK4: MA | AL4: SA | AM4: TR | AN4: OE | AO4: CD | AP4: CI | AQ4: ET | AR4: KE | AS4: ML | AT4: NE | AU4: NG | AV4: RW | AW4: SD | AX4: ZA | AY4: OJ | AZ4: RU | BA4: OA | BB4: CN | BC4: JP | BD4: KR | BE4: TW | BF4: OB | BG4: BD | BH4: IN | BI4: ID | BJ4: MM | BK4: PK | BL4: PH | BM4: TH | BN4: VN | BO4: OI
A5: 1970 | B5: =SUM(C5:J5) -> 1 | C5: =SUM(K5:U5) -> 0.25096415 | D5: =SUM(V5:Z5) -> 0.18050585 | E5: =SUM(AA5:AF5) -> 0.057054512 | F5: =SUM(AG5:AN5) -> 0.02912303 | G5: =SUM(AO5:AY5) -> 0.084236589 | H5: =SUM(AZ5:BA5) -> 0.14361713 | I5: =SUM(BB5:BF5) -> 0.12961882 | J5: =SUM(BG5:BO5) -> 0.12487992 | K5: 0.044175104 | L5: 0.0046276915 | M5: 0.015619729 | N5: 0.045330373 | O5: 0.024136674 | P5: 0.034134733 | Q5: 0.0067860838 | R5: 0.0033477538 | S5: 0.010317445 | T5: 0.031014451 | U5: 0.024620738 | V5: 0.142046 | W5: 0.012760641 | X5: 0.018395015 | Y5: 0.0020286203 | Z5: 0.00034628034 | AA5: 0.010950239 | AB5: 0.0079313065 | AC5: 0.0030567667 | AD5: 0.0034512695 | AE5: 0.017317953 | AF5: 0.01635908 | AG5: 0.00025875777 | AH5: 0.0017004241 | AI5: 0.0022923853 | AJ5: 0.0034606851 | AK5: 0.0022614502 | AL5: 0.0012913794 | AM5: 0.0085741846 | AN5: 0.0084884658 | AO5: 0.0034167462 | AP5: 0.0018287132 | AQ5: 0.0020655042 | AR5: 0.0024064512 | AS5: 0.00027942565 | AT5: 0.00050674623 | AU5: 0.025632471 | AV5: 0.00019869834 | AW5: 0.00069126137 | AX5: 0.015679258 | AY5: 0.027345215 | AZ5: 0.11190896 | BA5: 0.053410039 | BB5: 0.068529033 | BC5: 0.044282086 | BD5: 0.0072433177 | BE5: 0.0027802664 | BF5: 0.0032444569 | BG5: 0.0052095229 | BH5: 0.057559852 | BI5: 0.0081947407 | BJ5: 0.0039272211 | BK5: 0.016430707 | BL5: 0.0059495096 | BM5: 0.0094081568 | BN5: 0.0027542206 | BO5: 0.012035741
A6: 1971 | B6: =SUM(C6:J6) -> 1 | C6: =SUM(K6:U6) -> 0.25404035 | D6: =SUM(V6:Z6) -> 0.17741367 | E6: =SUM(AA6:AF6) -> 0.058863664 | F6: =SUM(AG6:AN6) -> 0.029451752 | G6: =SUM(AO6:AY6) -> 0.089257029 | H6: =SUM(AZ6:BA6) -> 0.13891476 | I6: =SUM(BB6:BF6) -> 0.12765199 | J6: =SUM(BG6:BO6) -> 0.12440679 | K6: 0.045082342 | L6: 0.0045759957 | M6: 0.016462093 | N6: 0.045429048 | O6: 0.025431409 | P6: 0.033845281 | Q6: 0.0070884545 | R6: 0.0035179637 | S6: 0.010444749 | T6: 0.032312075 | U6: 0.025495443 | V6: 0.1396546 | W6: 0.013318416 | X6: 0.018786801 | Y6: 0.0022551723 | Z6: 0.00035693794 | AA6: 0.011624805 | AB6: 0.0082410951 | AC6: 0.0032613296 | AD6: 0.0033626599 | AE6: 0.017320196 | AF6: 0.016110633 | AG6: 0.00032787729 | AH6: 0.0016361986 | AI6: 0.0022770016 | AJ6: 0.0040039737 | AK6: 0.0022809866 | AL6: 0.0015830368 | AM6: 0.0075138604 | AN6: 0.0093238702 | AO6: 0.0036644098 | AP6: 0.0018659385 | AQ6: 0.0020490058 | AR6: 0.0025583984 | AS6: 0.00029447462 | AT6: 0.00052096206 | AU6: 0.028705082 | AV6: 0.00022913029 | AW6: 0.00072255036 | AX6: 0.016453029 | AY6: 0.02859209 | AZ6: 0.10338502 | BA6: 0.050298333 | BB6: 0.06694578 | BC6: 0.044917752 | BD6: 0.0074507137 | BE6: 0.0028007826 | BF6: 0.0033483813 | BG6: 0.0043646438 | BH6: 0.057450543 | BI6: 0.0082743899 | BJ6: 0.0039412588 | BK6: 0.01700546 | BL6: 0.0063747559 | BM6: 0.0093286091 | BN6: 0.0029185936 | BO6: 0.0126156
A7: 1972 | B7: =SUM(C7:J7) -> 1 | C7: =SUM(K7:U7) -> 0.26312673 | D7: =SUM(V7:Z7) -> 0.17647711 | E7: =SUM(AA7:AF7) -> 0.063149653 | F7: =SUM(AG7:AN7) -> 0.031508298 | G7: =SUM(AO7:AY7) -> 0.086237537 | H7: =SUM(AZ7:BA7) -> 0.13777227 | I7: =SUM(BB7:BF7) -> 0.13120584 | J7: =SUM(BG7:BO7) -> 0.11052256 | K7: 0.047023546 | L7: 0.004783342 | M7: 0.017269246 | N7: 0.049636367 | O7: 0.024462944 | P7: 0.033229075 | Q7: 0.0074518893 | R7: 0.0036200755 | S7: 0.010268832 | T7: 0.033695109 | U7: 0.02554317 | V7: 0.13696549 | W7: 0.013477438 | X7: 0.018969532 | Y7: 0.0025617512 | Z7: 0.00038274218 | AA7: 0.015726184 | AB7: 0.0092946104 | AC7: 0.0032007439 | AD7: 0.0034180941 | AE7: 0.017350945 | AF7: 0.016242324 | AG7: 0.0004287551 | AH7: 0.0019014023 | AI7: 0.0020118683 | AJ7: 0.0043453843 | AK7: 0.0024247969 | AL7: 0.0018342611 | AM7: 0.0082558178 | AN7: 0.0095703981 | AO7: 0.0034125989 | AP7: 0.0018454569 | AQ7: 0.0019326733 | AR7: 0.002421477 | AS7: 0.00030605759 | AT7: 0.00055141517 | AU7: 0.029657067 | AV7: 0.00021764307 | AW7: 0.00071078771 | AX7: 0.01444481 | AY7: 0.026636729 | AZ7: 0.10411258 | BA7: 0.052319725 | BB7: 0.064786004 | BC7: 0.050272106 | BD7: 0.0068331534 | BE7: 0.0028594208 | BF7: 0.0033919372 | BG7: 0.0047941407 | BH7: 0.053360847 | BI7: 0.0082181051 | BJ7: 0.0031453337 | BK7: 0.0091966897 | BL7: 0.0058749361 | BM7: 0.0086645913 | BN7: 0.0026743308 | BO7: 0.012013248
A8: 1973 | B8: =SUM(C8:J8) -> 1 | C8: =SUM(K8:U8) -> 0.2697015 | D8: =SUM(V8:Z8) -> 0.17723615 | E8: =SUM(AA8:AF8) -> 0.069258719 | F8: =SUM(AG8:AN8) -> 0.032322307 | G8: =SUM(AO8:AY8) -> 0.078299844 | H8: =SUM(AZ8:BA8) -> 0.13163317 | I8: =SUM(BB8:BF8) -> 0.13399449 | J8: =SUM(BG8:BO8) -> 0.10755382 | K8: 0.048971328 | L8: 0.0056373069 | M8: 0.01742661 | N8: 0.051603919 | O8: 0.024443809 | P8: 0.033067426 | Q8: 0.0078293962 | R8: 0.0037089083 | S8: 0.0094230347 | T8: 0.03602217 | U8: 0.02484847 | V8: 0.13730702 | W8: 0.013221859 | X8: 0.018956865 | Y8: 0.0029034974 | Z8: 0.00043140004 | AA8: 0.021609472 | AB8: 0.010376112 | AC8: 0.0036715656 | AD8: 0.0032863279 | AE8: 0.017528359 | AF8: 0.015406367 | AG8: 0.00065327971 | AH8: 0.0019221565 | AI8: 0.0018375918 | AJ8: 0.0052631801 | AK8: 0.0023842773 | AL8: 0.0022112104 | AM8: 0.0082096635 | AN8: 0.0090356964 | AO8: 0.0032602195 | AP8: 0.0018757965 | AQ8: 0.0017180382 | AR8: 0.0021466595 | AS8: 0.00026571368 | AT8: 0.0004405051 | AU8: 0.02571024 | AV8: 0.00020242083 | AW8: 0.00067412765 | AX8: 0.014691405 | AY8: 0.023545236 | AZ8: 0.09999639 | BA8: 0.050744396 | BB8: 0.063766076 | BC8: 0.053701358 | BD8: 0.0064422683 | BE8: 0.0034491579 | BF8: 0.0032974036 | BG8: 0.0056020469 | BH8: 0.051680387 | BI8: 0.0091373991 | BJ8: 0.0030844972 | BK8: 0.0076916573 | BL8: 0.0055898475 | BM8: 0.0084879469 | BN8: 0.0021047808 | BO8: 0.01149575
A9: 1974 | B9: =SUM(C9:J9) -> 1 | C9: =SUM(K9:U9) -> 0.25670695 | D9: =SUM(V9:Z9) -> 0.17374614 | E9: =SUM(AA9:AF9) -> 0.076585788 | F9: =SUM(AG9:AN9) -> 0.044036968 | G9: =SUM(AO9:AY9) -> 0.091340193 | H9: =SUM(AZ9:BA9) -> 0.1134406 | I9: =SUM(BB9:BF9) -> 0.12963923 | J9: =SUM(BG9:BO9) -> 0.11450413 | K9: 0.048317571 | L9: 0.0054056009 | M9: 0.018324355 | N9: 0.043048454 | O9: 0.023334438 | P9: 0.032918579 | Q9: 0.0080359963 | R9: 0.0038148098 | S9: 0.0095508963 | T9: 0.036406572 | U9: 0.024441102 | V9: 0.13760342 | W9: 0.014221206 | X9: 0.016293875 | Y9: 0.0030612969 | Z9: 0.0004623817 | AA9: 0.024412547 | AB9: 0.011525056 | AC9: 0.0029451581 | AD9: 0.0032825134 | AE9: 0.019293348 | AF9: 0.016937723 | AG9: 0.0015633809 | AH9: 0.0023964031 | AI9: 0.001863617 | AJ9: 0.0076089073 | AK9: 0.0025936502 | AL9: 0.0057793277 | AM9: 0.0098787528 | AN9: 0.011819667 | AO9: 0.0034789551 | AP9: 0.0019828307 | AQ9: 0.0016009544 | AR9: 0.0022313316 | AS9: 0.00021820557 | AT9: 0.0004426848 | AU9: 0.03668364 | AV9: 0.00023406602 | AW9: 0.00073625611 | AX9: 0.015976876 | AY9: 0.024237506 | AZ9: 0.082119633 | BA9: 0.041729529 | BB9: 0.059415413 | BC9: 0.052517662 | BD9: 0.0083583468 | BE9: 0.0045837159 | BF9: 0.003194238 | BG9: 0.0075233621 | BH9: 0.050051322 | BI9: 0.012713064 | BJ9: 0.0033280509 | BK9: 0.0087807 | BL9: 0.0067498552 | BM9: 0.0093704262 | BN9: 0.0020114108 | BO9: 0.012589362
A10: 1975 | B10: =SUM(C10:J10) -> 1 | C10: =SUM(K10:U10) -> 0.27190349 | D10: =SUM(V10:Z10) -> 0.16306368 | E10: =SUM(AA10:AF10) -> 0.062820091 | F10: =SUM(AG10:AN10) -> 0.047070677 | G10: =SUM(AO10:AY10) -> 0.096734181 | H10: =SUM(AZ10:BA10) -> 0.11712813 | I10: =SUM(BB10:BF10) -> 0.13253006 | J10: =SUM(BG10:BO10) -> 0.10874969 | K10: 0.049458046 | L10: 0.005581474 | M10: 0.019902848 | N10: 0.049051315 | O10: 0.02391233 | P10: 0.034149081 | Q10: 0.0086593146 | R10: 0.0042916364 | S10: 0.01048156 | T10: 0.038748598 | U10: 0.025149537 | V10: 0.1298132 | W10: 0.013756186 | X10: 0.015147761 | Y10: 0.0024384743 | Z10: 0.00039814175 | AA10: 0.0090790795 | AB10: 0.012137095 | AC10: 0.0012733368 | AD10: 0.0032555827 | AE10: 0.021287174 | AF10: 0.01757907 | AG10: 0.0018536723 | AH10: 0.0026305551 | AI10: 0.0020267199 | AJ10: 0.0085994349 | AK10: 0.0028954627 | AL10: 0.005519955 | AM10: 0.011628569 | AN10: 0.011480448 | AO10: 0.0033804628 | AP10: 0.0022895058 | AQ10: 0.001516569 | AR10: 0.0022311734 | AS10: 0.00029589645 | AT10: 0.00051356103 | AU10: 0.042801351 | AV10: 0.00025495935 | AW10: 0.00082753211 | AX10: 0.014881088 | AY10: 0.024110936 | AZ10: 0.083103076 | BA10: 0.042562665 | BB10: 0.060709642 | BC10: 0.054813626 | BD10: 0.0083501542 | BE10: 0.0042436359 | BF10: 0.0031858083 | BG10: 0.0054781234 | BH10: 0.046102445 | BI10: 0.013711826 | BJ10: 0.0028739091 | BK10: 0.0097848145 | BL10: 0.0067098909 | BM10: 0.0091894912 | BN10: 0.0020111876 | BO10: 0.011881013
A11: 1976 | B11: =SUM(C11:J11) -> 1 | C11: =SUM(K11:U11) -> 0.26546039 | D11: =SUM(V11:Z11) -> 0.16331752 | E11: =SUM(AA11:AF11) -> 0.067569717 | F11: =SUM(AG11:AN11) -> 0.052604288 | G11: =SUM(AO11:AY11) -> 0.10149217 | H11: =SUM(AZ11:BA11) -> 0.1100543 | I11: =SUM(BB11:BF11) -> 0.13162654 | J11: =SUM(BG11:BO11) -> 0.10787508 | K11: 0.05052651 | L11: 0.0058718472 | M11: 0.018911106 | N11: 0.04609893 | O11: 0.02272948 | P11: 0.031330738 | Q11: 0.008939201 | R11: 0.0043354478 | S11: 0.010679237 | T11: 0.038596524 | U11: 0.025990619 | V11: 0.1284143 | W11: 0.015594544 | X11: 0.015642359 | Y11: 0.0023701472 | Z11: 0.00040362943 | AA11: 0.011846318 | AB11: 0.013657612 | AC11: 0.0016437772 | AD11: 0.0036284055 | AE11: 0.018684116 | AF11: 0.018257228 | AG11: 0.0022763473 | AH11: 0.0028242112 | AI11: 0.0023742391 | AJ11: 0.010240521 | AK11: 0.0029624118 | AL11: 0.0070417104 | AM11: 0.012609462 | AN11: 0.011987901 | AO11: 0.0029971572 | AP11: 0.0025773348 | AQ11: 0.001587258 | AR11: 0.0022372905 | AS11: 0.00032970419 | AT11: 0.00057180708 | AU11: 0.04949444 | AV11: 0.00026751633 | AW11: 0.0009708481 | AX11: 0.013283245 | AY11: 0.023535178 | AZ11: 0.077245908 | BA11: 0.040240701 | BB11: 0.054706249 | BC11: 0.057617982 | BD11: 0.010272556 | BE11: 0.0048237046 | BF11: 0.0034867045 | BG11: 0.003973372 | BH11: 0.042281434 | BI11: 0.015829499 | BJ11: 0.0031252595 | BK11: 0.010779402 | BL11: 0.0073210563 | BM11: 0.0097756372 | BN11: 0.0022404993 | BO11: 0.011959376
A12: 1977 | B12: =SUM(C12:J12) -> 1 | C12: =SUM(K12:U12) -> 0.26685737 | D12: =SUM(V12:Z12) -> 0.15349793 | E12: =SUM(AA12:AF12) -> 0.065747475 | F12: =SUM(AG12:AN12) -> 0.055117517 | G12: =SUM(AO12:AY12) -> 0.10338366 | H12: =SUM(AZ12:BA12) -> 0.10754999 | I12: =SUM(BB12:BF12) -> 0.13410547 | J12: =SUM(BG12:BO12) -> 0.1137406 | K12: 0.050762535 | L12: 0.0060009675 | M12: 0.018193436 | N12: 0.04486428 | O12: 0.023933645 | P12: 0.032054961 | Q12: 0.0091609358 | R12: 0.0044350511 | S12: 0.010057195 | T12: 0.038756913 | U12: 0.027354997 | V12: 0.12172624 | W12: 0.014627626 | X12: 0.013732427 | Y12: 0.0023023181 | Z12: 0.00037164769 | AA12: 0.010188247 | AB12: 0.014962569 | AC12: 0.0020342227 | AD12: 0.0042341216 | AE12: 0.014980565 | AF12: 0.018653045 | AG12: 0.0026416724 | AH12: 0.0029940494 | AI12: 0.0026812608 | AJ12: 0.011092833 | AK12: 0.0031205021 | AL12: 0.0072475543 | AM12: 0.012974412 | AN12: 0.012100351 | AO12: 0.0034101679 | AP12: 0.0030783175 | AQ12: 0.0015512336 | AR12: 0.0025716481 | AS12: 0.00034118708 | AT12: 0.00060041792 | AU12: 0.051619063 | AV12: 0.00027850578 | AW12: 0.0010420895 | AX12: 0.012953208 | AY12: 0.022256349 | AZ12: 0.075704985 | BA12: 0.039697275 | BB12: 0.051301071 | BC12: 0.062718324 | BD12: 0.01110543 | BE12: 0.0047681331 | BF12: 0.0035680303 | BG12: 0.0041274016 | BH12: 0.045422033 | BI12: 0.017355834 | BJ12: 0.0029928168 | BK12: 0.011271323 | BL12: 0.0075609402 | BM12: 0.010023657 | BN12: 0.0024145812 | BO12: 0.0120254
A13: 1978 | B13: =SUM(C13:J13) -> 1 | C13: =SUM(K13:U13) -> 0.27575602 | D13: =SUM(V13:Z13) -> 0.15039886 | E13: =SUM(AA13:AF13) -> 0.063353015 | F13: =SUM(AG13:AN13) -> 0.051543901 | G13: =SUM(AO13:AY13) -> 0.098665782 | H13: =SUM(AZ13:BA13) -> 0.1053384 | I13: =SUM(BB13:BF13) -> 0.14484815 | J13: =SUM(BG13:BO13) -> 0.11009586 | K13: 0.05232773 | L13: 0.0063504289 | M13: 0.019452222 | N13: 0.048828642 | O13: 0.025259207 | P13: 0.032732255 | Q13: 0.009641317 | R13: 0.0042740505 | S13: 0.0091195142 | T13: 0.040900113 | U13: 0.02788741 | V13: 0.11978901 | W13: 0.012971236 | X13: 0.015268916 | Y13: 0.0025374726 | Z13: 0.00038683257 | AA13: 0.01068842 | AB13: 0.01368435 | AC13: 0.0019250448 | AD13: 0.0041792765 | AE13: 0.014702659 | AF13: 0.016649556 | AG13: 0.0021824247 | AH13: 0.0032511431 | AI13: 0.0028230124 | AJ13: 0.0096860432 | AK13: 0.0032930332 | AL13: 0.0067104959 | AM13: 0.012460304 | AN13: 0.011327516 | AO13: 0.0040771804 | AP13: 0.0032680092 | AQ13: 0.0014136849 | AR13: 0.002564741 | AS13: 0.00033308142 | AT13: 0.00068470562 | AU13: 0.048920002 | AV13: 0.00028456944 | AW13: 0.00094769628 | AX13: 0.012383593 | AY13: 0.021130836 | AZ13: 0.069784463 | BA13: 0.037033674 | BB13: 0.053520214 | BC13: 0.071130047 | BD13: 0.012573297 | BE13: 0.0047344413 | BF13: 0.0034242844 | BG13: 0.0043988396 | BH13: 0.044508843 | BI13: 0.016475398 | BJ13: 0.0029100754 | BK13: 0.010923022 | BL13: 0.0074410137 | BM13: 0.010140459 | BN13: 0.0024963148 | BO13: 0.01120788
A14: 1979 | B14: =SUM(C14:J14) -> 1 | C14: =SUM(K14:U14) -> 0.28240823 | D14: =SUM(V14:Z14) -> 0.14884396 | E14: =SUM(AA14:AF14) -> 0.068875499 | F14: =SUM(AG14:AN14) -> 0.054062593 | G14: =SUM(AO14:AY14) -> 0.10096507 | H14: =SUM(AZ14:BA14) -> 0.094556203 | I14: =SUM(BB14:BF14) -> 0.14487784 | J14: =SUM(BG14:BO14) -> 0.10541061 | K14: 0.053096613 | L14: 0.0063396181 | M14: 0.021618712 | N14: 0.049803769 | O14: 0.027660015 | P14: 0.034315041 | Q14: 0.0099975729 | R14: 0.004121215 | S14: 0.0084317191 | T14: 0.040656049 | U14: 0.026957194 | V14: 0.11780569 | W14: 0.013520731 | X14: 0.014892887 | Y14: 0.0025412226 | Z14: 0.00039400849 | AA14: 0.015071406 | AB14: 0.013176401 | AC14: 0.0022316528 | AD14: 0.0043535706 | AE14: 0.014914035 | AF14: 0.01695085 | AG14: 0.0023745365 | AH14: 0.003390662 | AI14: 0.0016427497 | AJ14: 0.0089504619 | AK14: 0.0033430979 | AL14: 0.0076691524 | AM14: 0.014190515 | AN14: 0.012614227 | AO14: 0.0034305472 | AP14: 0.0032440367 | AQ14: 0.0013123161 | AR14: 0.0025255818 | AS14: 0.00036157412 | AT14: 0.00076958658 | AU14: 0.051264721 | AV14: 0.00029924869 | AW14: 0.00086916244 | AX14: 0.012931522 | AY14: 0.021024933 | AZ14: 0.063781633 | BA14: 0.034349048 | BB14: 0.061120185 | BC14: 0.0625506 | BD14: 0.013699488 | BE14: 0.0045479863 | BF14: 0.0032618847 | BG14: 0.0042760444 | BH14: 0.041501048 | BI14: 0.014178314 | BJ14: 0.0029377681 | BK14: 0.0109581 | BL14: 0.0078267921 | BM14: 0.0098148114 | BN14: 0.0023845267 | BO14: 0.011753158
A15: 1980 | B15: =SUM(C15:J15) -> 1 | C15: =SUM(K15:U15) -> 0.27706615 | D15: =SUM(V15:Z15) -> 0.1435362 | E15: =SUM(AA15:AF15) -> 0.074271412 | F15: =SUM(AG15:AN15) -> 0.053814097 | G15: =SUM(AO15:AY15) -> 0.11176095 | H15: =SUM(AZ15:BA15) -> 0.087420354 | I15: =SUM(BB15:BF15) -> 0.13698299 | J15: =SUM(BG15:BO15) -> 0.11514784 | K15: 0.050958427 | L15: 0.0062052538 | M15: 0.020023046 | N15: 0.049252746 | O15: 0.028805945 | P15: 0.035420469 | Q15: 0.010185954 | R15: 0.0043495367 | S15: 0.0082817443 | T15: 0.039324967 | U15: 0.023725208 | V15: 0.1112559 | W15: 0.014075317 | X15: 0.014761583 | Y15: 0.0027443647 | Z15: 0.00042298569 | AA15: 0.019565869 | AB15: 0.010852298 | AC15: 0.0027157667 | AD15: 0.0047908057 | AE15: 0.017920175 | AF15: 0.018588917 | AG15: 0.0029249362 | AH15: 0.0038066829 | AI15: 0.0019444441 | AJ15: 0.0085073584 | AK15: 0.0035564147 | AL15: 0.0098484914 | AM15: 0.0094523333 | AN15: 0.013669941 | AO15: 0.002854546 | AP15: 0.0031430844 | AQ15: 0.001206917 | AR15: 0.0025622866 | AS15: 0.00036718737 | AT15: 0.00081650439 | AU15: 0.058452757 | AV15: 0.00029483524 | AW15: 0.00083696481 | AX15: 0.015969756 | AY15: 0.021511338 | AZ15: 0.060148203 | BA15: 0.032251801 | BB15: 0.062104723 | BC15: 0.055628053 | BD15: 0.010953321 | BE15: 0.0046076108 | BF15: 0.0034258408 | BG15: 0.0043814626 | BH15: 0.047588629 | BI15: 0.017479199 | BJ15: 0.0029240865 | BK15: 0.011528394 | BL15: 0.0081396834 | BM15: 0.0099262525 | BN15: 0.00070971915 | BO15: 0.012248966
A16: 1981 | B16: =SUM(C16:J16) -> 1 | C16: =SUM(K16:U16) -> 0.25079708 | D16: =SUM(V16:Z16) -> 0.15546604 | E16: =SUM(AA16:AF16) -> 0.079985818 | F16: =SUM(AG16:AN16) -> 0.056274456 | G16: =SUM(AO16:AY16) -> 0.10429397 | H16: =SUM(AZ16:BA16) -> 0.084439829 | I16: =SUM(BB16:BF16) -> 0.14507867 | J16: =SUM(BG16:BO16) -> 0.12366412 | K16: 0.043034879 | L16: 0.0057953885 | M16: 0.017216912 | N16: 0.043838021 | O16: 0.026739671 | P16: 0.030692524 | Q16: 0.0095188774 | R16: 0.0043289688 | S16: 0.0077255935 | T16: 0.036416195 | U16: 0.024977855 | V16: 0.11938847 | W16: 0.016595749 | X16: 0.016049212 | Y16: 0.0027375094 | Z16: 0.00037759869 | AA16: 0.015919737 | AB16: 0.012664572 | AC16: 0.0032756616 | AD16: 0.0052849068 | AE16: 0.02336373 | AF16: 0.020626772 | AG16: 0.0033200528 | AH16: 0.00400054 | AI16: 0.0024737521 | AJ16: 0.0089506401 | AK16: 0.0029528294 | AL16: 0.010946365 | AM16: 0.0098612266 | AN16: 0.013654122 | AO16: 0.0024515457 | AP16: 0.0025286577 | AQ16: 0.0012177931 | AR16: 0.0023475508 | AS16: 0.00032903469 | AT16: 0.00069183543 | AU16: 0.05301946 | AV16: 0.00032120641 | AW16: 0.00096947493 | AX16: 0.015684122 | AY16: 0.021284908 | AZ16: 0.057151896 | BA16: 0.031080237 | BB16: 0.062340267 | BC16: 0.06154268 | BD16: 0.012166246 | BE16: 0.0051154159 | BF16: 0.0036177714 | BG16: 0.0042486186 | BH16: 0.049320439 | BI16: 0.021638638 | BJ16: 0.0029454568 | BK16: 0.013324599 | BL16: 0.0087959662 | BM16: 0.010254665 | BN16: 0.00055283538 | BO16: 0.01233035
... A60: 2025 | B60: =SUM(C60:J60) -> 1 | C60: =SUM(K60:U60) -> 0.13549553 | D60: =SUM(V60:Z60) -> 0.11504482 | E60: =SUM(AA60:AF60) -> 0.087547633 | F60: =SUM(AG60:AN60) -> 0.059363303 | G60: =SUM(AO60:AY60) -> 0.025671958 | H60: =SUM(AZ60:BA60) -> 0.033241892 | I60: =SUM(BB60:BF60) -> 0.37528558 | J60: =SUM(BG60:BO60) -> 0.16834929 | K60: 0.016628614 | L60: 0.002044942 | M60: 0.011547747 | N60: 0.019382226 | O60: 0.013996456 | P60: 0.014819431 | Q60: 0.009515267 | R60: 0.002887088 | S60: 0.0022681257 | T60: 0.018952691 | U60: 0.02340216 | V60: 0.089741981 | W60: 0.01150994 | X60: 0.010163264 | Y60: 0.0033574017 | Z60: 0.00022911086 | AA60: 0.012901703 | AB60: 0.022926298 | AC60: 0.0036564312 | AD60: 0.0064348619 | AE60: 0.021174446 | AF60: 0.02042108 | AG60: 0.0034329963 | AH60: 0.0022504915 | AI60: 0.00419755 | AJ60: 0.0052748861 | AK60: 0.0039189472 | AL60: 0.0041616267 | AM60: 0.020358672 | AN60: 0.015745884 | AO60: 0.00060643963 | AP60: 0.0021846795 | AQ60: 0.0032070515 | AR60: 0.0016152008 | AS60: 0.0002801663 | AT60: 0.00024316054 | AU60: 0.0032549067 | AV60: 0.00017458837 | AW60: 0.00020443792 | AX60: 0.0037023149 | AY60: 0.010564193 | AZ60: 0.020850213 | BA60: 0.01237922 | BB60: 0.34360055 | BC60: 0.016433297 | BD60: 0.0097466326 | BE60: 0.0031605366 | BF60: 0.0022038992 | BG60: 0.01181509 | BH60: 0.058260961 | BI60: 0.024735882 | BJ60: 0.0044692557 | BK60: 0.015415927 | BL60: 0.01097962 | BM60: 0.007282986 | BN60: 0.021904048 | BO60: 0.013422422
A61: 2026
A62: 2027
A63: 2028
A64: 2029
A65: 2030
A66: 2031
A67: 2032
A68: 2033
A69: 2034
A70: 2035
A71: 2036
A72: 2037
... A135: 2100

Sheet O2as
A1: Data series on Output: Country and Region Output Shares in "Housing Services" Sector (current price MER).
A4: Year | B4: World | C4: Europe | D4: North America/ Oceania | E4: Latin America | F4: Middle East/North Africa | G4: Subsaharan Africa | H4: Russia/ Central Asia | I4: East Asia | J4: South & South-East Asia | K4: DE | L4: DK | M4: ES | N4: FR | O4: GB | P4: IT | Q4: NL | R4: NO | S4: SE | T4: OC | U4: QM | V4: US | W4: CA | X4: AU | Y4: NZ | Z4: OH | AA4: AR | AB4: BR | AC4: CL | AD4: CO | AE4: MX | AF4: OD | AG4: AE | AH4: DZ | AI4: EG | AJ4: IR | AK4: MA | AL4: SA | AM4: TR | AN4: OE | AO4: CD | AP4: CI | AQ4: ET | AR4: KE | AS4: ML | AT4: NE | AU4: NG | AV4: RW | AW4: SD | AX4: ZA | AY4: OJ | AZ4: RU | BA4: OA | BB4: CN | BC4: JP | BD4: KR | BE4: TW | BF4: OB | BG4: BD | BH4: IN | BI4: ID | BJ4: MM | BK4: PK | BL4: PH | BM4: TH | BN4: VN | BO4: OI
A5: 1970 | B5: =SUM(C5:J5) -> 1 | C5: =SUM(K5:U5) -> 0.28974966 | D5: =SUM(V5:Z5) -> 0.46259844 | E5: =SUM(AA5:AF5) -> 0.051621399 | F5: =SUM(AG5:AN5) -> 0.019093897 | G5: =SUM(AO5:AY5) -> 0.0071232805 | H5: =SUM(AZ5:BA5) -> 0.09245224 | I5: =SUM(BB5:BF5) -> 0.069012396 | J5: =SUM(BG5:BO5) -> 0.0083486893 | K5: 0.051197687 | L5: 0.0044257894 | M5: 0.0057653266 | N5: 0.055741656 | O5: 0.045014924 | P5: 0.024130327 | Q5: 0.0094137661 | R5: 0.0050912961 | S5: 0.016536119 | T5: 0.037077614 | U5: 0.029449208 | V5: 0.40101321 | W5: 0.033719925 | X5: 0.015189647 | Y5: 0.0023432833 | Z5: 0.000903276 | AA5: 0.0098871336 | AB5: 0.0076732443 | AC5: 0.003790716 | AD5: 0.0032432665 | AE5: 0.022209642 | AF5: 0.015850797 | AG5: 0.00023679772 | AH5: 0.0011241672 | AI5: 0.001629676 | AJ5: 0.002287893 | AK5: 0.00085642519 | AL5: 0.00099465941 | AM5: 0.0059632804 | AN5: 0.0056118085 | AO5: 0.00028278287 | AP5: 0.00012656166 | AQ5: 0.00020276667 | AR5: 0.00023623679 | AS5: 2.7430691e-05 | AT5: 4.9746325e-05 | AU5: 0.0025162915 | AV5: 1.9505842e-05 | AW5: 6.7859828e-05 | AX5: 0.0016449046 | AY5: 0.0026844283 | AZ5: 0.070217093 | BA5: 0.027767592 | BB5: 0.010751325 | BC5: 0.053310029 | BD5: 0.0011756868 | BE5: 0.00095134952 | BF5: 0.0014173315 | BG5: 0.00041429165 | BH5: 0.0038848031 | BI5: 0.00069625223 | BJ5: 0.00017332608 | BK5: 0.00091255454 | BL5: 0.00049547272 | BM5: 0.00051624841 | BN5: 0.00021231104 | BO5: 0.00087325897
A6: 1971 | B6: =SUM(C6:J6) -> 1 | C6: =SUM(K6:U6) -> 0.29755342 | D6: =SUM(V6:Z6) -> 0.4536677 | E6: =SUM(AA6:AF6) -> 0.052730376 | F6: =SUM(AG6:AN6) -> 0.018613509 | G6: =SUM(AO6:AY6) -> 0.0082026371 | H6: =SUM(AZ6:BA6) -> 0.086991935 | I6: =SUM(BB6:BF6) -> 0.073504773 | J6: =SUM(BG6:BO6) -> 0.0087356576 | K6: 0.055600618 | L6: 0.0045427976 | M6: 0.0058588337 | N6: 0.057250957 | O6: 0.04591445 | P6: 0.024494638 | Q6: 0.0099580989 | R6: 0.0052562976 | S6: 0.016068935 | T6: 0.037928748 | U6: 0.029167495 | V6: 0.3918803 | W6: 0.034781739 | X6: 0.0150928 | Y6: 0.0025803236 | Z6: 0.00092930187 | AA6: 0.010436268 | AB6: 0.0078165943 | AC6: 0.0040039755 | AD6: 0.003183396 | AE6: 0.021727872 | AF6: 0.015556396 | AG6: 0.00028872549 | AH6: 0.0010408768 | AI6: 0.0015469228 | AJ6: 0.0025471501 | AK6: 0.00079448807 | AL6: 0.0011470442 | AM6: 0.0049164976 | AN6: 0.0059870278 | AO6: 0.0003263035 | AP6: 0.00013470638 | AQ6: 0.0002164168 | AR6: 0.00027021905 | AS6: 3.1102526e-05 | AT6: 5.5024218e-05 | AU6: 0.0030672679 | AV6: 2.4200832e-05 | AW6: 7.6316054e-05 | AX6: 0.0018805964 | AY6: 0.0030199728 | AZ6: 0.066019332 | BA6: 0.025861876 | BB6: 0.010388018 | BC6: 0.058085304 | BD6: 0.0011912301 | BE6: 0.00098028259 | BF6: 0.001498418 | BG6: 0.00036468375 | BH6: 0.0040249081 | BI6: 0.00072444362 | BJ6: 0.00017420249 | BK6: 0.0009929299 | BL6: 0.00057847919 | BM6: 0.00052763011 | BN6: 0.00022422256 | BO6: 0.00096234834
A7: 1972 | B7: =SUM(C7:J7) -> 1 | C7: =SUM(K7:U7) -> 0.30678218 | D7: =SUM(V7:Z7) -> 0.43032995 | E7: =SUM(AA7:AF7) -> 0.055508034 | F7: =SUM(AG7:AN7) -> 0.020384878 | G7: =SUM(AO7:AY7) -> 0.0081654543 | H7: =SUM(AZ7:BA7) -> 0.088993087 | I7: =SUM(BB7:BF7) -> 0.082101925 | J7: =SUM(BG7:BO7) -> 0.0077344953 | K7: 0.058680478 | L7: 0.0047338793 | M7: 0.006311534 | N7: 0.060641691 | O7: 0.046689673 | P7: 0.025557604 | Q7: 0.010413934 | R7: 0.0054070096 | S7: 0.017072107 | T7: 0.038893095 | U7: 0.028428478 | V7: 0.37162198 | W7: 0.033875458 | X7: 0.015522272 | Y7: 0.0028043117 | Z7: 0.000961398 | AA7: 0.013370503 | AB7: 0.0086256077 | AC7: 0.0037054526 | AD7: 0.0031032526 | AE7: 0.0209361 | AF7: 0.01488912 | AG7: 0.00039361689 | AH7: 0.0012610374 | AI7: 0.0014149674 | AJ7: 0.0028819214 | AK7: 0.00084117101 | AL7: 0.0013539814 | AM7: 0.0055050056 | AN7: 0.0064705305 | AO7: 0.00031827465 | AP7: 0.00013568142 | AQ7: 0.00021379884 | AR7: 0.00026787195 | AS7: 3.3857122e-05 | AT7: 6.0999405e-05 | AU7: 0.003349075 | AV7: 2.4076409e-05 | AW7: 7.8629732e-05 | AX7: 0.0017512298 | AY7: 0.0029466238 | AZ7: 0.064439104 | BA7: 0.025334675 | BB7: 0.0093787765 | BC7: 0.067955335 | BD7: 0.0010606826 | BE7: 0.00096800456 | BF7: 0.0016812947 | BG7: 0.00041023712 | BH7: 0.0036138976 | BI7: 0.00072417541 | BJ7: 0.00013595382 | BK7: 0.00055027965 | BL7: 0.00056374395 | BM7: 0.00049379775 | BN7: 0.00020004954 | BO7: 0.00094270638
A8: 1973 | B8: =SUM(C8:J8) -> 1 | C8: =SUM(K8:U8) -> 0.32966231 | D8: =SUM(V8:Z8) -> 0.39386567 | E8: =SUM(AA8:AF8) -> 0.061779174 | F8: =SUM(AG8:AN8) -> 0.021555448 | G8: =SUM(AO8:AY8) -> 0.0085443421 | H8: =SUM(AZ8:BA8) -> 0.08809696 | I8: =SUM(BB8:BF8) -> 0.08858008 | J8: =SUM(BG8:BO8) -> 0.0079160089 | K8: 0.065679435 | L8: 0.0051911962 | M8: 0.0070325576 | N8: 0.067274043 | O8: 0.048533985 | P8: 0.024365172 | Q8: 0.01151063 | R8: 0.0060197898 | S8: 0.016862025 | T8: 0.042997403 | U8: 0.029235117 | V8: 0.33532417 | W8: 0.031312251 | X8: 0.017098626 | Y8: 0.0031274737 | Z8: 0.0010760223 | AA8: 0.019011367 | AB8: 0.0096095282 | AC8: 0.0043794435 | AD8: 0.0031248643 | AE8: 0.019953755 | AF8: 0.014645819 | AG8: 0.00061954201 | AH8: 0.0013168911 | AI8: 0.0013255688 | AJ8: 0.0036058641 | AK8: 0.0008158231 | AL8: 0.0016467973 | AM8: 0.0055264422 | AN8: 0.0063741397 | AO8: 0.00034620285 | AP8: 0.00015307154 | AQ8: 0.00021639473 | AR8: 0.00027038155 | AS8: 3.3467849e-05 | AT8: 5.5483624e-05 | AU8: 0.0033283061 | AV8: 2.5495825e-05 | AW8: 8.4909448e-05 | AX8: 0.0020540948 | AY8: 0.002964125 | AZ8: 0.065537882 | BA8: 0.025290484 | BB8: 0.0086811236 | BC8: 0.074509449 | BD8: 0.0010717648 | BE8: 0.0011931141 | BF8: 0.0017916218 | BG8: 0.00053426357 | BH8: 0.003398743 | BI8: 0.0008835218 | BJ8: 0.00014210895 | BK8: 0.00051323917 | BL8: 0.00061500137 | BM8: 0.00053184108 | BN8: 0.0001671727 | BO8: 0.0010109924
A9: 1974 | B9: =SUM(C9:J9) -> 1 | C9: =SUM(K9:U9) -> 0.33693173 | D9: =SUM(V9:Z9) -> 0.37484579 | E9: =SUM(AA9:AF9) -> 0.068328647 | F9: =SUM(AG9:AN9) -> 0.031731095 | G9: =SUM(AO9:AY9) -> 0.010670653 | H9: =SUM(AZ9:BA9) -> 0.081319558 | I9: =SUM(BB9:BF9) -> 0.087071938 | J9: =SUM(BG9:BO9) -> 0.0091005897 | K9: 0.066267319 | L9: 0.0051545038 | M9: 0.0076897208 | N9: 0.067208548 | O9: 0.054637432 | P9: 0.02388929 | Q9: 0.012274206 | R9: 0.0065537894 | S9: 0.015030259 | T9: 0.046199355 | U9: 0.029599787 | V9: 0.3178864 | W9: 0.032343282 | X9: 0.017596571 | Y9: 0.0031915506 | Z9: 0.0011272978 | AA9: 0.02206645 | AB9: 0.010896369 | AC9: 0.0035938726 | AD9: 0.0032442388 | AE9: 0.019982035 | AF9: 0.016556576 | AG9: 0.0015758833 | AH9: 0.0017450531 | AI9: 0.0014185483 | AJ9: 0.005540782 | AK9: 0.00090015751 | AL9: 0.0044657213 | AM9: 0.0069059584 | AN9: 0.0089503749 | AO9: 0.00039916409 | AP9: 0.00017080353 | AQ9: 0.00021787715 | AR9: 0.00030366647 | AS9: 2.9696041e-05 | AT9: 6.0245878e-05 | AU9: 0.0051564764 | AV9: 3.1854522e-05 | AW9: 0.0001001986 | AX9: 0.0024453962 | AY9: 0.0032957894 | AZ9: 0.056581586 | BA9: 0.021236291 | BB9: 0.0081386467 | BC9: 0.073504235 | BD9: 0.0013446561 | BE9: 0.0015143552 | BF9: 0.001942709 | BG9: 0.00075949079 | BH9: 0.0034549197 | BI9: 0.0012832448 | BJ9: 0.00015543867 | BK9: 0.00062057367 | BL9: 0.00080624142 | BM9: 0.00061466593 | BN9: 0.00016140593 | BO9: 0.001179041
A10: 1975 | B10: =SUM(C10:J10) -> 1 | C10: =SUM(K10:U10) -> 0.35243996 | D10: =SUM(V10:Z10) -> 0.36920934 | E10: =SUM(AA10:AF10) -> 0.058064049 | F10: =SUM(AG10:AN10) -> 0.03172245 | G10: =SUM(AO10:AY10) -> 0.012740826 | H10: =SUM(AZ10:BA10) -> 0.07948098 | I10: =SUM(BB10:BF10) -> 0.086609533 | J10: =SUM(BG10:BO10) -> 0.0097328637 | K10: 0.067904321 | L10: 0.0055835547 | M10: 0.0086370025 | N10: 0.07486693 | O10: 0.048733316 | P10: 0.026720115 | Q10: 0.013151749 | R10: 0.0072153627 | S10: 0.017409648 | T10: 0.049122973 | U10: 0.028969219 | V10: 0.31431548 | W10: 0.032304927 | X10: 0.014391246 | Y10: 0.0027965284 | Z10: 0.0010790819 | AA10: 0.0082535653 | AB10: 0.011943436 | AC10: 0.001556029 | AD10: 0.0032723182 | AE10: 0.022671869 | AF10: 0.017323038 | AG10: 0.0017527617 | AH10: 0.0017969121 | AI10: 0.001436498 | AJ10: 0.0058742083 | AK10: 0.0008990418 | AL10: 0.0039034297 | AM10: 0.0074488351 | AN10: 0.0082394108 | AO10: 0.00043900377 | AP10: 0.00021850832 | AQ10: 0.00023360619 | AR10: 0.00034368098 | AS10: 4.55787e-05 | AT10: 7.9106877e-05 | AU10: 0.0068323758 | AV10: 3.9272914e-05 | AW10: 0.00012746972 | AX10: 0.0026129361 | AY10: 0.0037096336 | AZ10: 0.058918542 | BA10: 0.021612897 | BB10: 0.0081389081 | BC10: 0.072741839 | BD10: 0.0013546334 | BE10: 0.0014571153 | BF10: 0.0019031602 | BG10: 0.00061362119 | BH10: 0.003588627 | BI10: 0.0015168552 | BJ10: 0.00014281254 | BK10: 0.0007677816 | BL10: 0.00090975775 | BM10: 0.00066311597 | BN10: 0.00017120674 | BO10: 0.0012451499
A11: 1976 | B11: =SUM(C11:J11) -> 1 | C11: =SUM(K11:U11) -> 0.33663823 | D11: =SUM(V11:Z11) -> 0.37912301 | E11: =SUM(AA11:AF11) -> 0.061642542 | F11: =SUM(AG11:AN11) -> 0.034621886 | G11: =SUM(AO11:AY11) -> 0.014359988 | H11: =SUM(AZ11:BA11) -> 0.073303117 | I11: =SUM(BB11:BF11) -> 0.089944079 | J11: =SUM(BG11:BO11) -> 0.010367142 | K11: 0.065740803 | L11: 0.0058016432 | M11: 0.0084197055 | N11: 0.072105803 | O11: 0.042202442 | P11: 0.023350724 | Q11: 0.013638597 | R11: 0.0073288081 | S11: 0.016848458 | T11: 0.04869647 | U11: 0.029220533 | V11: 0.32270187 | W11: 0.036148826 | X11: 0.012909886 | Y11: 0.0026039179 | Z11: 0.0010597808 | AA11: 0.010342726 | AB11: 0.01333159 | AC11: 0.0019209358 | AD11: 0.003540371 | AE11: 0.021072893 | AF11: 0.01734554 | AG11: 0.0021075389 | AH11: 0.0018889644 | AI11: 0.001635392 | AJ11: 0.0068493389 | AK11: 0.00085843723 | AL11: 0.0047537243 | AM11: 0.007723396 | AN11: 0.0084673225 | AO11: 0.00042301287 | AP11: 0.00026213143 | AQ11: 0.00026571844 | AR11: 0.00037453856 | AS11: 5.5194858e-05 | AT11: 9.5724627e-05 | AU11: 0.008602996 | AV11: 4.4784161e-05 | AW11: 0.00016252697 | AX11: 0.00257043 | AY11: 0.0039363676 | AZ11: 0.053808234 | BA11: 0.019449319 | BB11: 0.0072418158 | BC11: 0.07629433 | BD11: 0.0017867773 | BE11: 0.0015733533 | BF11: 0.0021703074 | BG11: 0.00047442344 | BH11: 0.0035147787 | BI11: 0.0018463196 | BJ11: 0.00015891366 | BK11: 0.00090215732 | BL11: 0.0010800893 | BM11: 0.00074725781 | BN11: 0.00019467527 | BO11: 0.0013473851
A12: 1977 | B12: =SUM(C12:J12) -> 1 | C12: =SUM(K12:U12) -> 0.3357998 | D12: =SUM(V12:Z12) -> 0.37476618 | E12: =SUM(AA12:AF12) -> 0.057573909 | F12: =SUM(AG12:AN12) -> 0.035216191 | G12: =SUM(AO12:AY12) -> 0.015263863 | H12: =SUM(AZ12:BA12) -> 0.070144858 | I12: =SUM(BB12:BF12) -> 0.10028883 | J12: =SUM(BG12:BO12) -> 0.010946358 | K12: 0.068205424 | L12: 0.005831668 | M12: 0.008521783 | N12: 0.069355277 | O12: 0.040105775 | P12: 0.023498787 | Q12: 0.014422276 | R12: 0.0075433842 | S12: 0.015655479 | T12: 0.049747403 | U12: 0.030046542 | V12: 0.32291769 | W12: 0.034090898 | X12: 0.010906516 | Y12: 0.0026269649 | Z12: 0.001025536 | AA12: 0.0085723841 | AB12: 0.013816327 | AC12: 0.0022812146 | AD12: 0.0040227644 | AE12: 0.016187937 | AF12: 0.017159137 | AG12: 0.0023924106 | AH12: 0.0019588683 | AI12: 0.0017928335 | AJ12: 0.0072575286 | AK12: 0.00084251212 | AL12: 0.00466313 | AM12: 0.0075894704 | AN12: 0.0084188718 | AO12: 0.00050459273 | AP12: 0.00032234071 | AQ12: 0.0002722529 | AR12: 0.00045134314 | AS12: 5.988084e-05 | AT12: 0.00010537776 | AU12: 0.009412365 | AV12: 4.8879812e-05 | AW12: 0.00018289436 | AX12: 0.0026662849 | AY12: 0.0038965885 | AZ12: 0.051987431 | BA12: 0.01834716 | BB12: 0.007484826 | BC12: 0.085796311 | BD12: 0.0022018122 | BE12: 0.0016454717 | BF12: 0.002304461 | BG12: 0.00050693272 | BH12: 0.0035899031 | BI12: 0.0020624552 | BJ12: 0.00015041489 | BK12: 0.00097094651 | BL12: 0.0011691117 | BM12: 0.00078507964 | BN12: 0.00020693952 | BO12: 0.0014111492
A13: 1978 | B13: =SUM(C13:J13) -> 1 | C13: =SUM(K13:U13) -> 0.34104712 | D13: =SUM(V13:Z13) -> 0.35575188 | E13: =SUM(AA13:AF13) -> 0.057311639 | F13: =SUM(AG13:AN13) -> 0.0316661 | G13: =SUM(AO13:AY13) -> 0.016001835 | H13: =SUM(AZ13:BA13) -> 0.067199306 | I13: =SUM(BB13:BF13) -> 0.11970736 | J13: =SUM(BG13:BO13) -> 0.011314769 | K13: 0.071205797 | L13: 0.0060673792 | M13: 0.0084091388 | N13: 0.069173819 | O13: 0.040326272 | P13: 0.024866146 | Q13: 0.015315147 | R13: 0.0070377928 | S13: 0.015346134 | T13: 0.051152628 | U13: 0.028788283 | V13: 0.30822519 | W13: 0.029991844 | X13: 0.010287715 | Y13: 0.0027260489 | Z13: 0.0010176813 | AA13: 0.0092623541 | AB13: 0.013547734 | AC13: 0.0022139359 | AD13: 0.0041302661 | AE13: 0.017243101 | AF13: 0.015874597 | AG13: 0.001911974 | AH13: 0.002057635 | AI13: 0.0018118716 | AJ13: 0.0061302566 | AK13: 0.00081865595 | AL13: 0.0040665739 | AM13: 0.0068820465 | AN13: 0.0076752432 | AO13: 0.0006555331 | AP13: 0.00036566158 | AQ13: 0.00026959847 | AR13: 0.00048911197 | AS13: 6.3520687e-05 | AT13: 0.0001305776 | AU13: 0.0096875821 | AV13: 5.4269152e-05 | AW13: 0.00018073155 | AX13: 0.0028122059 | AY13: 0.0040084681 | AZ13: 0.050484203 | BA13: 0.017503435 | BB13: 0.0076818285 | BC13: 0.10418967 | BD13: 0.0026572117 | BE13: 0.0017382708 | BF13: 0.0022615085 | BG13: 0.00057614798 | BH13: 0.0036673031 | BI13: 0.0020705017 | BJ13: 0.00014999799 | BK13: 0.0010040478 | BL13: 0.001248139 | BM13: 0.00084558393 | BN13: 0.00021905337 | BO13: 0.0014225678
