Workbook
Name __ISC01: #REF!
Name __ISC01: #REF!
Name __ISC01: #REF!
Name __ISC01: #REF!
Name __ISC2: #REF!
Name __ISC2: #REF!
Name __ISC2: #REF!
Name __ISC2: #REF!
Name __ISC3: #REF!+#REF!
Name __ISC3: #REF!+#REF!
Name __ISC3: #REF!+#REF!
Name __ISC3: #REF!+#REF!
Name __ISC567: #REF!
Name __ISC567: #REF!
Name __ISC567: #REF!
Name __ISC567: #REF!
Name _10000: #REF!
Name _10000: #REF!
Name _10000: #REF!
Name _10000: #REF!
Name _1080: #REF!
Name _1080: #REF!
Name _1080: #REF!
Name _1080: #REF!
Name _1090: #REF!
Name _1090: #REF!
Name _1090: #REF!
Name _1090: #REF!
Name _1100: #REF!
Name _1100: #REF!
Name _1100: #REF!
Name _1100: #REF!
Name _1110: #REF!
Name _1110: #REF!
Name _1110: #REF!
Name _1110: #REF!
Name _2: #REF!
Name _2: #REF!
Name _2: #REF!
Name _2: #REF!
Name _2010: #REF!
Name _2010: #REF!
Name _2010: #REF!
Name _2010: #REF!
Name _2080: #REF!
Name _2080: #REF!
Name _2080: #REF!
Name _2080: #REF!
Name _2090: #REF!
Name _2090: #REF!
Name _2090: #REF!
Name _2090: #REF!
Name _2100: #REF!
Name _2100: #REF!
Name _2100: #REF!
Name _2100: #REF!
Name _2110: #REF!
Name _2110: #REF!
Name _2110: #REF!
Name _2110: #REF!

Sheet ReadMe
A1: Country-Level Input-Output Analysis - Inputs used by : | D1: "Manufacturing" | G1: A-Matrix Coefficients & Domestic Share
B5: Ox | C5: ="A-Matrix by Sector and Country: Inputs used by " & D1 & " Sector as a Share of " & D1 & " Output (Current Price, MER)" -> A-Matrix by Sector and Country: Inputs used by "Manufacturing" Sector as a Share of "Manufacturing" Output (Current Price, MER)
B6: Px | C6: ="Inputs used by " & D1 & " Sector : Domestic Sectoral Inputs Used as Share of Total Sectoral Inputs (Current Price MER)" -> Inputs used by "Manufacturing" Sector : Domestic Sectoral Inputs Used as Share of Total Sectoral Inputs (Current Price MER)
B7: Qx | C7: ="Import, Export, Consumption, Investment as Share of Sector Supply (Output & Import) (Current Price MER)" -> Import, Export, Consumption, Investment as Share of Sector Supply (Output & Import) (Current Price MER)
B8: Qxo | C8: ="Import, Export, Consumption, Investment as Share of Sector Output (Current Price MER)" -> Import, Export, Consumption, Investment as Share of Sector Output (Current Price MER)
B9: Qxg | C9: ="Import, Export as Share of Sector Gross Final Expenditure (Current Price MER)" -> Import, Export as Share of Sector Gross Final Expenditure (Current Price MER)
B12: Sheet Number | C12: Sector Name
B13: 1 | C13: Food
B14: 2a | C14: Housing Services
B15: 2b | C15: Construction
B16: 3 | C16: Manufacturing
B17: 4 | C17: Energy
B18: 5 | C18: Education/Health
B19: 6 | C19: Leisure/Culture
B20: 7 | C20: Transport
B21: 8 | C21: Other services

Sheet O0
A1: ="Data series on A-Matrix Coefficients: Total Inputs used by " & ReadMe!D1 & " Sector as Share of " & ReadMe!D1 & " Output (current price MER)." -> Data series on A-Matrix Coefficients: Total Inputs used by "Manufacturing" Sector as Share of "Manufacturing" Output (current price MER).
A4: Year | B4: World | C4: Europe | D4: North America/ Oceania | E4: Latin America | F4: Middle East/North Africa | G4: Subsaharan Africa | H4: Russia/ Central Asia | I4: East Asia | J4: South & South-East Asia | K4: DE | L4: DK | M4: ES | N4: FR | O4: GB | P4: IT | Q4: NL | R4: NO | S4: SE | T4: OC | U4: QM | V4: US | W4: CA | X4: AU | Y4: NZ | Z4: OH | AA4: AR | AB4: BR | AC4: CL | AD4: CO | AE4: MX | AF4: OD | AG4: AE | AH4: DZ | AI4: EG | AJ4: IR | AK4: MA | AL4: SA | AM4: TR | AN4: OE | AO4: CD | AP4: CI | AQ4: ET | AR4: KE | AS4: ML | AT4: NE | AU4: NG | AV4: RW | AW4: SD | AX4: ZA | AY4: OJ | AZ4: RU | BA4: OA | BB4: CN | BC4: JP | BD4: KR | BE4: TW | BF4: OB | BG4: BD | BH4: IN | BI4: ID | BJ4: MM | BK4: PK | BL4: PH | BM4: TH | BN4: VN | BO4: OI
A5: 1970 | B5: 0.64732629 | C5: 0.64026497 | D5: 0.63421407 | E5: 0.63786683 | F5: 0.59730905 | G5: 0.52291764 | H5: 0.72266774 | I5: 0.64757181 | J5: 0.5303405 | K5: 0.60912611 | L5: 0.55510825 | M5: 0.73545686 | N5: 0.65471285 | O5: 0.6832624 | P5: 0.58233788 | Q5: 0.63451764 | R5: 0.66666253 | S5: 0.71019809 | T5: 0.6478015 | U5: 0.6478015 | V5: 0.62861003 | W5: 0.72267557 | X5: 0.58365983 | Y5: 0.64180393 | Z5: 0.63181509 | AA5: 0.53795563 | AB5: 0.62162635 | AC5: 0.56143205 | AD5: 0.55641855 | AE5: 0.70170099 | AF5: 0.61767804 | AG5: 0.63523792 | AH5: 0.59929575 | AI5: 0.57720204 | AJ5: 0.59929575 | AK5: 0.60899535 | AL5: 0.56211349 | AM5: 0.60478755 | AN5: 0.59929575 | AO5: 0.4078714 | AP5: 0.53504234 | AQ5: 0.56053681 | AR5: 0.56053681 | AS5: 0.56053681 | AT5: 0.56053681 | AU5: 0.50327514 | AV5: 0.56053681 | AW5: 0.56053681 | AX5: 0.56053681 | AY5: 0.56053681 | AZ5: 0.72266774 | BA5: 0.72752618 | BB5: 0.66322851 | BC5: 0.63424452 | BD5: 0.70592849 | BE5: 0.82745056 | BF5: 0.6619369 | BG5: 0.41558114 | BH5: 0.53968997 | BI5: 0.57516097 | BJ5: 0.53792045 | BK5: 0.48343309 | BL5: 0.46358315 | BM5: 0.63294613 | BN5: 0.55691611 | BO5: 0.58654418
A6: 1971 | B6: 0.65098881 | C6: 0.64134817 | D6: 0.6342142 | E6: 0.64318444 | F6: 0.59818252 | G6: 0.60148304 | H6: 0.7247967 | I6: 0.65104183 | J6: 0.61239967 | K6: 0.60994297 | L6: 0.56219593 | M6: 0.74026903 | N6: 0.65753042 | O6: 0.67626517 | P6: 0.57767633 | Q6: 0.65767934 | R6: 0.66725105 | S6: 0.71984946 | T6: 0.64837337 | U6: 0.64837337 | V6: 0.62743801 | W6: 0.71776087 | X6: 0.60400499 | Y6: 0.64081081 | Z6: 0.63083742 | AA6: 0.54033653 | AB6: 0.61853935 | AC6: 0.56391685 | AD6: 0.55888117 | AE6: 0.71733163 | AF6: 0.62041177 | AG6: 0.63710932 | AH6: 0.60106127 | AI6: 0.57890247 | AJ6: 0.60106127 | AK6: 0.61078944 | AL6: 0.56376947 | AM6: 0.60656925 | AN6: 0.60106127 | AO6: 0.46957869 | AP6: 0.61598947 | AQ6: 0.64534102 | AR6: 0.64534102 | AS6: 0.64534102 | AT6: 0.64534102 | AU6: 0.57941618 | AV6: 0.64534102 | AW6: 0.64534102 | AX6: 0.64534102 | AY6: 0.64534102 | AZ6: 0.7247967 | BA6: 0.72966946 | BB6: 0.66519549 | BC6: 0.63639726 | BD6: 0.70915054 | BE6: 0.83129071 | BF6: 0.66388695 | BG6: 0.47845486 | BH6: 0.62134024 | BI6: 0.66217769 | BJ6: 0.61930301 | BK6: 0.5565722 | BL6: 0.53371914 | BM6: 0.72870523 | BN6: 0.64117254 | BO6: 0.67528307
A7: 1972 | B7: 0.6476889 | C7: 0.63836338 | D7: 0.63562741 | E7: 0.63751572 | F7: 0.59757994 | G7: 0.56507181 | H7: 0.72368668 | I7: 0.64800596 | J7: 0.57822813 | K7: 0.61191588 | L7: 0.56253243 | M7: 0.74025661 | N7: 0.65181742 | O7: 0.66450833 | P7: 0.57589413 | Q7: 0.64354833 | R7: 0.66424576 | S7: 0.71952939 | T7: 0.6454531 | U7: 0.6454531 | V7: 0.62908945 | W7: 0.70342426 | X7: 0.62435802 | Y7: 0.64245027 | Z7: 0.63245137 | AA7: 0.5411279 | AB7: 0.6154192 | AC7: 0.56474275 | AD7: 0.55969969 | AE7: 0.71999609 | AF7: 0.62132042 | AG7: 0.6361336 | AH7: 0.60014074 | AI7: 0.57801589 | AJ7: 0.60014074 | AK7: 0.60985402 | AL7: 0.56290606 | AM7: 0.60564029 | AN7: 0.60014074 | AO7: 0.44212267 | AP7: 0.57997289 | AQ7: 0.60760827 | AR7: 0.60760827 | AS7: 0.60760827 | AT7: 0.60760827 | AU7: 0.54553802 | AV7: 0.60760827 | AW7: 0.60760827 | AX7: 0.60760827 | AY7: 0.60760827 | AZ7: 0.72368668 | BA7: 0.72855197 | BB7: 0.66384204 | BC7: 0.63428989 | BD7: 0.72449242 | BE7: 0.81997339 | BF7: 0.66287021 | BG7: 0.45047985 | BH7: 0.5850108 | BI7: 0.62346051 | BJ7: 0.58309268 | BK7: 0.52402971 | BL7: 0.50251286 | BM7: 0.68609821 | BN7: 0.60368352 | BO7: 0.63579963
A8: 1973 | B8: 0.64526609 | C8: 0.63795328 | D8: 0.64192603 | E8: 0.62631135 | F8: 0.59442719 | G8: 0.5212046 | H8: 0.72004613 | I8: 0.64365339 | J8: 0.53173444 | K8: 0.61706944 | L8: 0.56482265 | M8: 0.7350568 | N8: 0.6460092 | O8: 0.67806981 | P8: 0.56473108 | Q8: 0.62463703 | R8: 0.66302619 | S8: 0.71481635 | T8: 0.64426804 | U8: 0.64426804 | V8: 0.63795644 | W8: 0.6951464 | X8: 0.61752414 | Y8: 0.65002196 | Z8: 0.63990521 | AA8: 0.54190304 | AB8: 0.61573019 | AC8: 0.56555171 | AD8: 0.56050143 | AE8: 0.71036714 | AF8: 0.62221043 | AG8: 0.63293349 | AH8: 0.5971217 | AI8: 0.57510814 | AJ8: 0.5971217 | AK8: 0.60678611 | AL8: 0.56007433 | AM8: 0.60259358 | AN8: 0.5971217 | AO8: 0.40644821 | AP8: 0.53317543 | AQ8: 0.55858094 | AR8: 0.55858094 | AS8: 0.55858094 | AT8: 0.55858094 | AU8: 0.50151907 | AV8: 0.55858094 | AW8: 0.55858094 | AX8: 0.55858094 | AY8: 0.55858094 | AZ8: 0.72004613 | BA8: 0.72488695 | BB8: 0.65561143 | BC8: 0.63172414 | BD8: 0.69922355 | BE8: 0.80589439 | BF8: 0.65953561 | BG8: 0.41413106 | BH8: 0.53780683 | BI8: 0.57315407 | BJ8: 0.53604349 | BK8: 0.48174625 | BL8: 0.46196558 | BM8: 0.6307376 | BN8: 0.55497287 | BO8: 0.58449756
A9: 1974 | B9: 0.64204988 | C9: 0.63489371 | D9: 0.66122533 | E9: 0.60485821 | F9: 0.58764963 | G9: 0.50918927 | H9: 0.7155669 | I9: 0.63755461 | J9: 0.52134136 | K9: 0.62113317 | L9: 0.58074617 | M9: 0.72474774 | N9: 0.61384983 | O9: 0.68338361 | P9: 0.5821998 | Q9: 0.62617774 | R9: 0.65648487 | S9: 0.69063804 | T9: 0.63791178 | U9: 0.63791178 | V9: 0.66228302 | W9: 0.68857282 | X9: 0.60638382 | Y9: 0.67142279 | Z9: 0.66097297 | AA9: 0.51997841 | AB9: 0.58674424 | AC9: 0.5426703 | AD9: 0.53782435 | AE9: 0.69209146 | AF9: 0.59703668 | AG9: 0.62899616 | AH9: 0.59340715 | AI9: 0.57153054 | AJ9: 0.59340715 | AK9: 0.60301145 | AL9: 0.55659024 | AM9: 0.598845 | AN9: 0.59340715 | AO9: 0.39892139 | AP9: 0.52330179 | AQ9: 0.54823683 | AR9: 0.54823683 | AS9: 0.54823683 | AT9: 0.54823683 | AU9: 0.49223167 | AV9: 0.54823683 | AW9: 0.54823683 | AX9: 0.54823683 | AY9: 0.54823683 | AZ9: 0.7155669 | BA9: 0.7203776 | BB9: 0.64652863 | BC9: 0.6299488 | BD9: 0.70637774 | BE9: 0.7022481 | BF9: 0.6554328 | BG9: 0.40646195 | BH9: 0.52784744 | BI9: 0.56254009 | BJ9: 0.52611674 | BK9: 0.47282502 | BL9: 0.45341065 | BM9: 0.61905726 | BN9: 0.54469558 | BO9: 0.57367351
A10: 1975 | B10: 0.64566542 | C10: 0.64886125 | D10: 0.65262313 | E10: 0.63503903 | F10: 0.58260517 | G10: 0.53851895 | H10: 0.70781225 | I10: 0.63483815 | J10: 0.55556208 | K10: 0.61754735 | L10: 0.56045938 | M10: 0.72373864 | N10: 0.63784357 | O10: 0.70547492 | P10: 0.61470571 | Q10: 0.66054493 | R10: 0.67302942 | S10: 0.7039854 | T10: 0.65398826 | U10: 0.65398826 | V10: 0.65090108 | W10: 0.68946776 | X10: 0.62159815 | Y10: 0.66137496 | Z10: 0.65108152 | AA10: 0.53190759 | AB10: 0.60585703 | AC10: 0.55512007 | AD10: 0.55016294 | AE10: 0.6904362 | AF10: 0.61073371 | AG10: 0.62217968 | AH10: 0.58697635 | AI10: 0.56533682 | AJ10: 0.58697635 | AK10: 0.59647656 | AL10: 0.55055843 | AM10: 0.59235527 | AN10: 0.58697635 | AO10: 0.42317035 | AP10: 0.55511138 | AQ10: 0.58156213 | AR10: 0.58156213 | AS10: 0.58156213 | AT10: 0.58156213 | AU10: 0.52215262 | AV10: 0.58156213 | AW10: 0.58156213 | AX10: 0.58156213 | AY10: 0.58156213 | AZ10: 0.70781225 | BA10: 0.71257082 | BB10: 0.65081414 | BC10: 0.62128026 | BD10: 0.71698216 | BE10: 0.74639294 | BF10: 0.64832982 | BG10: 0.43116928 | BH10: 0.55993334 | BI10: 0.59673483 | BJ10: 0.55809744 | BK10: 0.50156631 | BL10: 0.48097181 | BM10: 0.65668747 | BN10: 0.57780562 | BO10: 0.60854502
A11: 1976 | B11: 0.64197046 | C11: 0.63850704 | D11: 0.65075266 | E11: 0.6321025 | F11: 0.58436994 | G11: 0.54672051 | H11: 0.71105168 | I11: 0.63817931 | J11: 0.5678242 | K11: 0.62053183 | L11: 0.56727025 | M11: 0.71811643 | N11: 0.62041304 | O11: 0.69855413 | P11: 0.58447531 | Q11: 0.64369336 | R11: 0.6610612 | S11: 0.70034615 | T11: 0.64235864 | U11: 0.64235864 | V11: 0.648063 | W11: 0.70026358 | X11: 0.61043918 | Y11: 0.65858173 | Z11: 0.64833176 | AA11: 0.54041831 | AB11: 0.61510262 | AC11: 0.56400219 | AD11: 0.55896575 | AE11: 0.68990023 | AF11: 0.62050567 | AG11: 0.6250272 | AH11: 0.58966275 | AI11: 0.56792418 | AJ11: 0.58966275 | AK11: 0.59920644 | AL11: 0.55307816 | AM11: 0.59506628 | AN11: 0.58966275 | AO11: 0.43071587 | AP11: 0.56500953 | AQ11: 0.59193192 | AR11: 0.59193192 | AS11: 0.59193192 | AT11: 0.59193192 | AU11: 0.53146308 | AV11: 0.59193192 | AW11: 0.59193192 | AX11: 0.59193192 | AY11: 0.59193192 | AZ11: 0.71105168 | BA11: 0.71583202 | BB11: 0.65174644 | BC11: 0.62412475 | BD11: 0.72317329 | BE11: 0.74263391 | BF11: 0.65129702 | BG11: 0.43885743 | BH11: 0.56991747 | BI11: 0.60737517 | BJ11: 0.56804884 | BK11: 0.5105097 | BL11: 0.48954798 | BM11: 0.66839681 | BN11: 0.58810842 | BO11: 0.61939593
A12: 1977 | B12: 0.64488158 | C12: 0.6401193 | D12: 0.65033082 | E12: 0.62639957 | F12: 0.58756635 | G12: 0.58627049 | H12: 0.71465611 | I12: 0.64259715 | J12: 0.61054202 | K12: 0.60917165 | L12: 0.57831571 | M12: 0.7291521 | N12: 0.62441722 | O12: 0.70924664 | P12: 0.59404119 | Q12: 0.64969633 | R12: 0.66360211 | S12: 0.69934081 | T12: 0.64482766 | U12: 0.64482766 | V12: 0.64798556 | W12: 0.69691079 | X12: 0.61215339 | Y12: 0.65955901 | Z12: 0.64929383 | AA12: 0.54548222 | AB12: 0.6216277 | AC12: 0.5692871 | AD12: 0.56420346 | AE12: 0.67356573 | AF12: 0.62632003 | AG12: 0.62819556 | AH12: 0.59265185 | AI12: 0.57080308 | AJ12: 0.59265185 | AK12: 0.60224392 | AL12: 0.5558818 | AM12: 0.59808277 | AN12: 0.59265185 | AO12: 0.46233887 | AP12: 0.60649232 | AQ12: 0.63539134 | AR12: 0.63539134 | AS12: 0.63539134 | AT12: 0.63539134 | AU12: 0.57048291 | AV12: 0.63539134 | AW12: 0.63539134 | AX12: 0.63539134 | AY12: 0.63539134 | AZ12: 0.71465611 | BA12: 0.71946069 | BB12: 0.65504898 | BC12: 0.6272953 | BD12: 0.71351849 | BE12: 0.75874075 | BF12: 0.65459855 | BG12: 0.47107818 | BH12: 0.6117606 | BI12: 0.65196843 | BJ12: 0.60975477 | BK12: 0.54799113 | BL12: 0.52549042 | BM12: 0.71747026 | BN12: 0.63128713 | BO12: 0.66487176
A13: 1978 | B13: 0.64208972 | C13: 0.64051213 | D13: 0.65052654 | E13: 0.6182512 | F13: 0.58054019 | G13: 0.58395589 | H13: 0.70649186 | I13: 0.63592446 | J13: 0.60930582 | K13: 0.60007125 | L13: 0.58360758 | M13: 0.7386926 | N13: 0.63444825 | O13: 0.70625152 | P13: 0.60573073 | Q13: 0.64763973 | R13: 0.6656617 | S13: 0.69422083 | T13: 0.64682898 | U13: 0.64682898 | V13: 0.64446061 | W13: 0.73092734 | X13: 0.60232374 | Y13: 0.6572496 | Z13: 0.64702036 | AA13: 0.54417703 | AB13: 0.62573631 | AC13: 0.56792495 | AD13: 0.56285347 | AE13: 0.64966263 | AF13: 0.62482142 | AG13: 0.62101904 | AH13: 0.58588138 | AI13: 0.56428221 | AJ13: 0.58588138 | AK13: 0.59536386 | AL13: 0.54953139 | AM13: 0.59125025 | AN13: 0.58588138 | AO13: 0.46106221 | AP13: 0.60481761 | AQ13: 0.63363684 | AR13: 0.63363684 | AS13: 0.63363684 | AT13: 0.63363684 | AU13: 0.56890763 | AV13: 0.63363684 | AW13: 0.63363684 | AX13: 0.63363684 | AY13: 0.63363684 | AZ13: 0.70649186 | BA13: 0.71124155 | BB13: 0.64704892 | BC13: 0.61920616 | BD13: 0.7017225 | BE13: 0.78685215 | BF13: 0.64712039 | BG13: 0.46977739 | BH13: 0.61007134 | BI13: 0.65016815 | BJ13: 0.60807105 | BK13: 0.54647796 | BL13: 0.52403938 | BM13: 0.71548911 | BN13: 0.62954395 | BO13: 0.66303584
A14: 1979 | B14: 0.64087393 | C14: 0.63845948 | D14: 0.65248563 | E14: 0.59825747 | F14: 0.58268216 | G14: 0.58603546 | H14: 0.70918891 | I14: 0.63968798 | J14: 0.60876739 | K14: 0.60630517 | L14: 0.59316182 | M14: 0.73487603 | N14: 0.6348721 | O14: 0.68612737 | P14: 0.61056909 | Q14: 0.63534285 | R14: 0.66345578 | S14: 0.67366388 | T14: 0.64468547 | U14: 0.64468547 | V14: 0.65061469 | W14: 0.69309206 | X14: 0.6171911 | Y14: 0.66203937 | Z14: 0.65173558 | AA14: 0.53207829 | AB14: 0.6184608 | AC14: 0.55529822 | AD14: 0.5503395 | AE14: 0.62172204 | AF14: 0.6109297 | AG14: 0.62338979 | AH14: 0.58811799 | AI14: 0.56643637 | AJ14: 0.58811799 | AK14: 0.59763668 | AL14: 0.55162924 | AM14: 0.59350737 | AN14: 0.58811799 | AO14: 0.46159328 | AP14: 0.60551427 | AQ14: 0.63436669 | AR14: 0.63436669 | AS14: 0.63436669 | AT14: 0.63436669 | AU14: 0.56956293 | AV14: 0.63436669 | AW14: 0.63436669 | AX14: 0.63436669 | AY14: 0.63436669 | AZ14: 0.70918891 | BA14: 0.71395673 | BB14: 0.64619795 | BC14: 0.62361234 | BD14: 0.71827149 | BE14: 0.75770612 | BF14: 0.64959079 | BG14: 0.4703185 | BH14: 0.61077405 | BI14: 0.65091704 | BJ14: 0.60877146 | BK14: 0.54710742 | BL14: 0.52464299 | BM14: 0.71631324 | BN14: 0.63026909 | BO14: 0.66379956
A15: 1980 | B15: 0.64646706 | C15: 0.63975129 | D15: 0.65771874 | E15: 0.59160178 | F15: 0.59611982 | G15: 0.59468588 | H15: 0.72928882 | I15: 0.65639808 | J15: 0.61660901 | K15: 0.61217137 | L15: 0.58602626 | M15: 0.72331036 | N15: 0.63434106 | O15: 0.68873256 | P15: 0.61486075 | Q15: 0.62549612 | R15: 0.66585865 | S15: 0.6786362 | T15: 0.64702036 | U15: 0.64702036 | V15: 0.65400388 | W15: 0.71639793 | X15: 0.62103386 | Y15: 0.66560754 | Z15: 0.65524822 | AA15: 0.52822809 | AB15: 0.62525942 | AC15: 0.55127999 | AD15: 0.54635716 | AE15: 0.61138401 | AF15: 0.60650892 | AG15: 0.64105798 | AH15: 0.6047865 | AI15: 0.58249037 | AJ15: 0.6047865 | AK15: 0.61457497 | AL15: 0.56726358 | AM15: 0.61032862 | AN15: 0.6047865 | AO15: 0.46659241 | AP15: 0.61207208 | AQ15: 0.64123698 | AR15: 0.64123698 | AS15: 0.64123698 | AT15: 0.64123698 | AU15: 0.57573138 | AV15: 0.64123698 | AW15: 0.64123698 | AX15: 0.64123698 | AY15: 0.64123698 | AZ15: 0.72928882 | BA15: 0.73419178 | BB15: 0.64674314 | BC15: 0.64714622 | BD15: 0.73830551 | BE15: 0.73554765 | BF15: 0.66800157 | BG15: 0.47541212 | BH15: 0.61738882 | BI15: 0.65796657 | BJ15: 0.61536454 | BK15: 0.55303268 | BL15: 0.53032495 | BM15: 0.72407102 | BN15: 0.637095 | BO15: 0.67098861
A16: 1981 | B16: 0.64542856 | C16: 0.6389787 | D16: 0.65094809 | E16: 0.59862264 | F16: 0.59343657 | G16: 0.60736818 | H16: 0.72687278 | I16: 0.6591035 | J16: 0.62911591 | K16: 0.60739478 | L16: 0.59230807 | M16: 0.72393429 | N16: 0.64082489 | O16: 0.66991686 | P16: 0.62553645 | Q16: 0.63478131 | R16: 0.6653318 | S16: 0.67788494 | T16: 0.64650842 | U16: 0.64650842 | V16: 0.64418041 | W16: 0.72851211 | X16: 0.62267352 | Y16: 0.65690356 | Z16: 0.6466797 | AA16: 0.51494763 | AB16: 0.61613176 | AC16: 0.53741997 | AD16: 0.5326209 | AE16: 0.62449235 | AF16: 0.59126036 | AG16: 0.63893423 | AH16: 0.60278292 | AI16: 0.58056065 | AJ16: 0.60278292 | AK16: 0.61253896 | AL16: 0.5653843 | AM16: 0.60830668 | AN16: 0.60278292 | AO16: 0.47502832 | AP16: 0.62313825 | AQ16: 0.65283044 | AR16: 0.65283044 | AS16: 0.65283044 | AT16: 0.65283044 | AU16: 0.58614051 | AV16: 0.65283044 | AW16: 0.65283044 | AX16: 0.65283044 | AY16: 0.65283044 | AZ16: 0.72687278 | BA16: 0.73175949 | BB16: 0.66526144 | BC16: 0.63782581 | BD16: 0.74262473 | BE16: 0.80800209 | BF16: 0.66578856 | BG16: 0.48400749 | BH16: 0.62855112 | BI16: 0.6698625 | BJ16: 0.62649024 | BK16: 0.56303142 | BL16: 0.53991314 | BM16: 0.73716211 | BN16: 0.64861358 | BO16: 0.68311997
... A60: 2025 | B60: 0.68124729 | C60: 0.66668436 | D60: 0.58052016 | E60: 0.68902618 | F60: 0.62132969 | G60: 0.61484128 | H60: 0.67869942 | I60: 0.73541672 | J60: 0.7339807 | K60: 0.65223379 | L60: 0.55668823 | M60: 0.73289878 | N60: 0.67484872 | O60: 0.60564366 | P60: 0.71578681 | Q60: 0.70487449 | R60: 0.6378889 | S60: 0.65135625 | T60: 0.67115991 | U60: 0.67115991 | V60: 0.55782233 | W60: 0.6745996 | X60: 0.67378087 | Y60: 0.61518011 | Z60: 0.57247464 | AA60: 0.60184464 | AB60: 0.73459524 | AC60: 0.6381656 | AD60: 0.66114637 | AE60: 0.68406164 | AF60: 0.68842538 | AG60: 0.62485393 | AH60: 0.60807443 | AI60: 0.53512684 | AJ60: 0.60807443 | AK60: 0.66293542 | AL60: 0.55131005 | AM60: 0.64888093 | AN60: 0.60807443 | AO60: 0.46970668 | AP60: 0.57728354 | AQ60: 0.63153129 | AR60: 0.63153129 | AS60: 0.63153129 | AT60: 0.63153129 | AU60: 0.59009611 | AV60: 0.63153129 | AW60: 0.63153129 | AX60: 0.63153129 | AY60: 0.63153129 | AZ60: 0.67869942 | BA60: 0.67324552 | BB60: 0.75481313 | BC60: 0.65811981 | BD60: 0.71064714 | BE60: 0.66261196 | BF60: 0.73827076 | BG60: 0.53151465 | BH60: 0.76215611 | BI60: 0.70676926 | BJ60: 0.67041981 | BK60: 0.585977 | BL60: 0.65483184 | BM60: 0.77483031 | BN60: 0.7699152 | BO60: 0.73298986
A61: 2026
A62: 2027
A63: 2028
A64: 2029
A65: 2030
A66: 2031
A67: 2032
A68: 2033
A69: 2034
A70: 2035
A71: 2036
A72: 2037
... A135: 2100

Sheet O1
A1: ="Data Series on A-Matrix Coefficients: Total Food Inputs used by " & ReadMe!D1 & " Sector as Share of " & ReadMe!D1 & " Output (current price MER)." -> Data Series on A-Matrix Coefficients: Total Food Inputs used by "Manufacturing" Sector as Share of "Manufacturing" Output (current price MER).
A4: Year | B4: World | C4: Europe | D4: North America/ Oceania | E4: Latin America | F4: Middle East/North Africa | G4: Subsaharan Africa | H4: Russia/ Central Asia | I4: East Asia | J4: South & South-East Asia | K4: DE | L4: DK | M4: ES | N4: FR | O4: GB | P4: IT | Q4: NL | R4: NO | S4: SE | T4: OC | U4: QM | V4: US | W4: CA | X4: AU | Y4: NZ | Z4: OH | AA4: AR | AB4: BR | AC4: CL | AD4: CO | AE4: MX | AF4: OD | AG4: AE | AH4: DZ | AI4: EG | AJ4: IR | AK4: MA | AL4: SA | AM4: TR | AN4: OE | AO4: CD | AP4: CI | AQ4: ET | AR4: KE | AS4: ML | AT4: NE | AU4: NG | AV4: RW | AW4: SD | AX4: ZA | AY4: OJ | AZ4: RU | BA4: OA | BB4: CN | BC4: JP | BD4: KR | BE4: TW | BF4: OB | BG4: BD | BH4: IN | BI4: ID | BJ4: MM | BK4: PK | BL4: PH | BM4: TH | BN4: VN | BO4: OI
A5: 1970 | B5: 0.023546635 | C5: 0.020127944 | D5: 0.011126041 | E5: 0.025593253 | F5: 0.014778202 | G5: 0.052532999 | H5: 0.026081175 | I5: 0.028251336 | J5: 0.14582621 | K5: 0.0059065341 | L5: 0.017727324 | M5: 0.01678946 | N5: 0.044310389 | O5: 0.010495953 | P5: 0.016733974 | Q5: 0.0090678225 | R5: 0.05038934 | S5: 0.089497716 | T5: 0.022019039 | U5: 0.022019039 | V5: 0.0060380549 | W5: 0.035824853 | X5: 0.050580563 | Y5: 0.061415153 | Z5: 0.0090738779 | AA5: 0.040171448 | AB5: 0.021842277 | AC5: 0.065049043 | AD5: 0.013694795 | AE5: 0.018262026 | AF5: 0.034040548 | AG5: 0.0050084786 | AH5: 0.013694163 | AI5: 0.0054326046 | AJ5: 0.013694163 | AK5: 0.024491197 | AL5: 0.0019995484 | AM5: 0.01887871 | AN5: 0.013694163 | AO5: 0.0028531248 | AP5: 0.1808595 | AQ5: 0.03767043 | AR5: 0.03767043 | AS5: 0.03767043 | AT5: 0.03767043 | AU5: 0.065812817 | AV5: 0.03767043 | AW5: 0.03767043 | AX5: 0.03767043 | AY5: 0.03767043 | AZ5: 0.026081175 | BA5: 0.032486195 | BB5: 0.056472204 | BC5: 0.017140833 | BD5: 0.076939546 | BE5: 0.040150759 | BF5: 0.019125684 | BG5: 0.046061561 | BH5: 0.16651422 | BI5: 0.066017486 | BJ5: 0.33621315 | BK5: 0.30436242 | BL5: 0.082599042 | BM5: 0.04629027 | BN5: 0.077220684 | BO5: 0.086583909
A6: 1971 | B6: 0.024458538 | C6: 0.020611094 | D6: 0.011500415 | E6: 0.025984631 | F6: 0.013816649 | G6: 0.054336684 | H6: 0.025305737 | I6: 0.027105846 | J6: 0.1529626 | K6: 0.0057816048 | L6: 0.018986436 | M6: 0.018276571 | N6: 0.043067416 | O6: 0.011011892 | P6: 0.01639938 | Q6: 0.0088214737 | R6: 0.05306522 | S6: 0.10618893 | T6: 0.02318834 | U6: 0.02318834 | V6: 0.0061898532 | W6: 0.035209402 | X6: 0.051625893 | Y6: 0.062488993 | Z6: 0.0092325341 | AA6: 0.039341238 | AB6: 0.023520613 | AC6: 0.063704696 | AD6: 0.013411769 | AE6: 0.017895105 | AF6: 0.033337043 | AG6: 0.0048595681 | AH6: 0.013287012 | AI6: 0.0052710841 | AJ6: 0.013287012 | AK6: 0.023763032 | AL6: 0.0019400984 | AM6: 0.018317414 | AN6: 0.013287012 | AO6: 0.0029459707 | AP6: 0.186745 | AQ6: 0.038896295 | AR6: 0.038896295 | AS6: 0.038896295 | AT6: 0.038896295 | AU6: 0.067954485 | AV6: 0.038896295 | AW6: 0.038896295 | AX6: 0.038896295 | AY6: 0.038896295 | AZ6: 0.025305737 | BA6: 0.031520325 | BB6: 0.054341001 | BC6: 0.016296041 | BD6: 0.069596952 | BE6: 0.033791164 | BF6: 0.018557045 | BG6: 0.047560488 | BH6: 0.1719329 | BI6: 0.068165815 | BJ6: 0.34715413 | BK6: 0.31426693 | BL6: 0.085286965 | BM6: 0.04779664 | BN6: 0.079733586 | BO6: 0.089401507
A7: 1972 | B7: 0.023241692 | C7: 0.020880097 | D7: 0.01213309 | E7: 0.024703076 | F7: 0.012718964 | G7: 0.052398549 | H7: 0.023228036 | I7: 0.026435244 | J7: 0.13701582 | K7: 0.0059783378 | L7: 0.019322773 | M7: 0.016794858 | N7: 0.044403509 | O7: 0.010699977 | P7: 0.015730591 | Q7: 0.0093076952 | R7: 0.052560382 | S7: 0.10465008 | T7: 0.022967737 | U7: 0.022967737 | V7: 0.0066422089 | W7: 0.034433808 | X7: 0.054929928 | Y7: 0.064904067 | Z7: 0.009589353 | AA7: 0.035915029 | AB7: 0.022776178 | AC7: 0.058156686 | AD7: 0.012243745 | AE7: 0.016680702 | AF7: 0.030433737 | AG7: 0.0044605784 | AH7: 0.012196096 | AI7: 0.0048383073 | AJ7: 0.012196096 | AK7: 0.021811993 | AL7: 0.0017808087 | AM7: 0.016813482 | AN7: 0.012196096 | AO7: 0.0027960607 | AP7: 0.17724221 | AQ7: 0.036917001 | AR7: 0.036917001 | AS7: 0.036917001 | AT7: 0.036917001 | AU7: 0.064496523 | AV7: 0.036917001 | AW7: 0.036917001 | AX7: 0.036917001 | AY7: 0.036917001 | AZ7: 0.023228036 | BA7: 0.028932382 | BB7: 0.050650365 | BC7: 0.017520532 | BD7: 0.074894975 | BE7: 0.02827276 | BF7: 0.017033439 | BG7: 0.045140304 | BH7: 0.16318385 | BI7: 0.0646971 | BJ7: 0.32948869 | BK7: 0.298275 | BL7: 0.080947015 | BM7: 0.045364439 | BN7: 0.075676227 | BO7: 0.084852182
A8: 1973 | B8: 0.022929759 | C8: 0.020848238 | D8: 0.013841219 | E8: 0.025315443 | F8: 0.012021206 | G8: 0.048751386 | H8: 0.022555019 | I8: 0.025495281 | J8: 0.12451604 | K8: 0.0058749317 | L8: 0.018633201 | M8: 0.015262837 | N8: 0.042357327 | O8: 0.012303669 | P8: 0.015692342 | Q8: 0.0087826654 | R8: 0.051576392 | S8: 0.10731215 | T8: 0.022537755 | U8: 0.022537755 | V8: 0.0074124089 | W8: 0.040984798 | X8: 0.050748845 | Y8: 0.07278845 | Z8: 0.010754243 | AA8: 0.035717658 | AB8: 0.020601515 | AC8: 0.057837087 | AD8: 0.012176459 | AE8: 0.017238437 | AF8: 0.030266489 | AG8: 0.0043313359 | AH8: 0.011842722 | AI8: 0.0046981204 | AJ8: 0.011842722 | AK8: 0.021180005 | AL8: 0.0017292109 | AM8: 0.016326322 | AN8: 0.011842722 | AO8: 0.0026425934 | AP8: 0.16751392 | AQ8: 0.034890738 | AR8: 0.034890738 | AS8: 0.034890738 | AT8: 0.034890738 | AU8: 0.060956504 | AV8: 0.034890738 | AW8: 0.034890738 | AX8: 0.034890738 | AY8: 0.034890738 | AZ8: 0.022555019 | BA8: 0.028094084 | BB8: 0.05114464 | BC8: 0.017372202 | BD8: 0.062578621 | BE8: 0.02840723 | BF8: 0.016539906 | BG8: 0.042662689 | BH8: 0.15422718 | BI8: 0.061146071 | BJ8: 0.31140405 | BK8: 0.28190359 | BL8: 0.076504077 | BM8: 0.042874522 | BN8: 0.071522588 | BO8: 0.080194902
A9: 1974 | B9: 0.021037832 | C9: 0.018576102 | D9: 0.012377191 | E9: 0.023447888 | F9: 0.010690936 | G9: 0.046829276 | H9: 0.022933785 | I9: 0.022462752 | J9: 0.11191886 | K9: 0.0051878153 | L9: 0.018094279 | M9: 0.01329012 | N9: 0.033917984 | O9: 0.011883604 | P9: 0.014209622 | Q9: 0.007282355 | R9: 0.047156549 | S9: 0.10493966 | T9: 0.02060638 | U9: 0.02060638 | V9: 0.0072129302 | W9: 0.038722021 | X9: 0.029265448 | Y9: 0.067326877 | Z9: 0.0099473148 | AA9: 0.033582929 | AB9: 0.019700301 | AC9: 0.054380351 | AD9: 0.011448712 | AE9: 0.016278499 | AF9: 0.028457559 | AG9: 0.004404072 | AH9: 0.012041597 | AI9: 0.0047770159 | AJ9: 0.012041597 | AK9: 0.02153568 | AL9: 0.0017582495 | AM9: 0.01660049 | AN9: 0.012041597 | AO9: 0.0024628931 | AP9: 0.15612272 | AQ9: 0.032518116 | AR9: 0.032518116 | AS9: 0.032518116 | AT9: 0.032518116 | AU9: 0.056811371 | AV9: 0.032518116 | AW9: 0.032518116 | AX9: 0.032518116 | AY9: 0.032518116 | AZ9: 0.022933785 | BA9: 0.028565868 | BB9: 0.051203962 | BC9: 0.014079371 | BD9: 0.049239522 | BE9: 0.02993006 | BF9: 0.01681766 | BG9: 0.039761562 | BH9: 0.1437395 | BI9: 0.056988047 | BJ9: 0.29022811 | BK9: 0.26273372 | BL9: 0.071301686 | BM9: 0.03995899 | BN9: 0.066658945 | BO9: 0.074741529
A10: 1975 | B10: 0.02141986 | C10: 0.018787572 | D10: 0.011562749 | E10: 0.020777073 | F10: 0.011235038 | G10: 0.046722575 | H10: 0.023313862 | I10: 0.024471567 | J10: 0.10899211 | K10: 0.0053154522 | L10: 0.016265651 | M10: 0.015396293 | N10: 0.035003797 | O10: 0.011045479 | P10: 0.015082053 | Q10: 0.0075217093 | R10: 0.047840345 | S10: 0.093079754 | T10: 0.020905184 | U10: 0.020905184 | V10: 0.0065899173 | W10: 0.037199087 | X10: 0.027657411 | Y10: 0.063136123 | Z10: 0.0093281452 | AA10: 0.034863709 | AB10: 0.020232615 | AC10: 0.056454299 | AD10: 0.011885341 | AE10: 0.01693808 | AF10: 0.029542867 | AG10: 0.0044770599 | AH10: 0.01224116 | AI10: 0.0048561845 | AJ10: 0.01224116 | AK10: 0.021892587 | AL10: 0.0017873887 | AM10: 0.016875607 | AN10: 0.01224116 | AO10: 0.0023925917 | AP10: 0.15166632 | AQ10: 0.031589911 | AR10: 0.031589911 | AS10: 0.031589911 | AT10: 0.031589911 | AU10: 0.055189734 | AV10: 0.031589911 | AW10: 0.031589911 | AX10: 0.031589911 | AY10: 0.031589911 | AZ10: 0.023313862 | BA10: 0.029039285 | BB10: 0.049094434 | BC10: 0.014738585 | BD10: 0.056725787 | BE10: 0.034499181 | BF10: 0.017096376 | BG10: 0.038626599 | BH10: 0.13963656 | BI10: 0.055361367 | BJ10: 0.28194377 | BK10: 0.25523419 | BL10: 0.069266434 | BM10: 0.038818391 | BN10: 0.064756216 | BO10: 0.072608089
A11: 1976 | B11: 0.020909079 | C11: 0.018119682 | D11: 0.011696894 | E11: 0.021466741 | F11: 0.010627064 | G11: 0.047616777 | H11: 0.022936576 | I11: 0.023951629 | J11: 0.10587302 | K11: 0.0055606459 | L11: 0.016335867 | M11: 0.014700315 | N11: 0.029854689 | O11: 0.011752328 | P11: 0.013154472 | Q11: 0.0073216768 | R11: 0.046847277 | S11: 0.097561912 | T11: 0.020471235 | U11: 0.020471235 | V11: 0.0066757927 | W11: 0.038558342 | X11: 0.027966563 | Y11: 0.064955126 | Z11: 0.0095968968 | AA11: 0.033441927 | AB11: 0.020846539 | AC11: 0.054152028 | AD11: 0.011400643 | AE11: 0.016768054 | AF11: 0.028338076 | AG11: 0.004404608 | AH11: 0.012043062 | AI11: 0.0047775972 | AJ11: 0.012043062 | AK11: 0.021538301 | AL11: 0.0017584635 | AM11: 0.01660251 | AN11: 0.012043062 | AO11: 0.0023691675 | AP11: 0.15018146 | AQ11: 0.031280636 | AR11: 0.031280636 | AS11: 0.031280636 | AT11: 0.031280636 | AU11: 0.05464941 | AV11: 0.031280636 | AW11: 0.031280636 | AX11: 0.031280636 | AY11: 0.031280636 | AZ11: 0.022936576 | BA11: 0.028569345 | BB11: 0.049902325 | BC11: 0.014888906 | BD11: 0.056445019 | BE11: 0.032480033 | BF11: 0.016819707 | BG11: 0.038248433 | BH11: 0.13826948 | BI11: 0.054819363 | BJ11: 0.27918346 | BK11: 0.25273537 | BL11: 0.068588295 | BM11: 0.038438348 | BN11: 0.064122234 | BO11: 0.071897234
A12: 1977 | B12: 0.021168183 | C12: 0.018400814 | D12: 0.010762374 | E12: 0.022097748 | F12: 0.0095836333 | G12: 0.053366337 | H12: 0.020832273 | I12: 0.022753675 | J12: 0.11788185 | K12: 0.0055576673 | L12: 0.017184073 | M12: 0.014388689 | N12: 0.029365698 | O12: 0.011407829 | P12: 0.013509287 | Q12: 0.007260165 | R12: 0.048457618 | S12: 0.11350133 | T12: 0.021174919 | U12: 0.021174919 | V12: 0.0064392391 | W12: 0.035686163 | X12: 0.027252362 | Y12: 0.060091069 | Z12: 0.0088782491 | AA12: 0.031164755 | AB12: 0.02457495 | AC12: 0.050464637 | AD12: 0.010624335 | AE12: 0.015811982 | AF12: 0.026408442 | AG12: 0.0040005098 | AH12: 0.010938178 | AI12: 0.0043392794 | AJ12: 0.010938178 | AK12: 0.019562282 | AL12: 0.0015971343 | AM12: 0.015079323 | AN12: 0.010938178 | AO12: 0.0026443912 | AP12: 0.16762789 | AQ12: 0.034914476 | AR12: 0.034914476 | AS12: 0.034914476 | AT12: 0.034914476 | AU12: 0.060997976 | AV12: 0.034914476 | AW12: 0.034914476 | AX12: 0.034914476 | AY12: 0.034914476 | AZ12: 0.020832273 | BA12: 0.025948267 | BB12: 0.043802803 | BC12: 0.015040655 | BD12: 0.055176462 | BE12: 0.027972167 | BF12: 0.015276593 | BG12: 0.042691714 | BH12: 0.15433211 | BI12: 0.061187672 | BJ12: 0.31161592 | BK12: 0.28209538 | BL12: 0.076556127 | BM12: 0.042903692 | BN12: 0.071571248 | BO12: 0.080249463
A13: 1978 | B13: 0.020786335 | C13: 0.017945963 | D13: 0.012182173 | E13: 0.021601147 | F13: 0.0090899219 | G13: 0.047434065 | H13: 0.019582217 | I13: 0.021343981 | J13: 0.10712181 | K13: 0.0054539223 | L13: 0.017759737 | M13: 0.015649271 | N13: 0.029683248 | O13: 0.010695775 | P13: 0.013994137 | Q13: 0.0077969094 | R13: 0.046473401 | S13: 0.11310162 | T13: 0.020307859 | U13: 0.020307859 | V13: 0.006485079 | W13: 0.037080912 | X13: 0.046140991 | Y13: 0.064091031 | Z13: 0.0094692297 | AA13: 0.032149194 | AB13: 0.022044914 | AC13: 0.052058724 | AD13: 0.010959939 | AE13: 0.016531398 | AF13: 0.027242638 | AG13: 0.0037604562 | AH13: 0.010281825 | AI13: 0.0040788976 | AJ13: 0.010281825 | AK13: 0.018388433 | AL13: 0.001501297 | AM13: 0.014174476 | AN13: 0.010281825 | AO13: 0.0023728241 | AP13: 0.15041325 | AQ13: 0.031328915 | AR13: 0.031328915 | AS13: 0.031328915 | AT13: 0.031328915 | AU13: 0.054733756 | AV13: 0.031328915 | AW13: 0.031328915 | AX13: 0.031328915 | AY13: 0.031328915 | AZ13: 0.019582217 | BA13: 0.024391221 | BB13: 0.042736574 | BC13: 0.013704925 | BD13: 0.048893441 | BE13: 0.030391108 | BF13: 0.014359909 | BG13: 0.038307465 | BH13: 0.13848289 | BI13: 0.054903971 | BJ13: 0.27961435 | BK13: 0.25312544 | BL13: 0.068694154 | BM13: 0.038497674 | BN13: 0.0642212 | BO13: 0.0720082
A14: 1979 | B14: 0.019649345 | C14: 0.016221545 | D14: 0.011072831 | E14: 0.020771743 | F14: 0.0096766122 | G14: 0.042178457 | H14: 0.020780742 | I14: 0.022396812 | J14: 0.095731663 | K14: 0.0054131016 | L14: 0.017399873 | M14: 0.014236811 | N14: 0.028271819 | O14: 0.010629798 | P14: 0.013312022 | Q14: 0.0075054658 | R14: 0.041179169 | S14: 0.088198603 | T14: 0.017994396 | U14: 0.017994396 | V14: 0.0062347496 | W14: 0.033423468 | X14: 0.038720006 | Y14: 0.059211472 | Z14: 0.0087482915 | AA14: 0.030396407 | AB14: 0.021616219 | AC14: 0.049220461 | AD14: 0.010362399 | AE14: 0.015157474 | AF14: 0.025757358 | AG14: 0.0039906141 | AH14: 0.010911121 | AI14: 0.0043285457 | AJ14: 0.010911121 | AK14: 0.019513892 | AL14: 0.0015931836 | AM14: 0.015042022 | AN14: 0.010911121 | AO14: 0.0020995925 | AP14: 0.13309311 | AQ14: 0.027721379 | AR14: 0.027721379 | AS14: 0.027721379 | AT14: 0.027721379 | AU14: 0.048431145 | AV14: 0.027721379 | AW14: 0.027721379 | AX14: 0.027721379 | AY14: 0.027721379 | AZ14: 0.020780742 | BA14: 0.025884081 | BB14: 0.046475223 | BC14: 0.014462288 | BD14: 0.037492358 | BE14: 0.024894071 | BF14: 0.015238804 | BG14: 0.033896347 | BH14: 0.12253653 | BI14: 0.048581759 | BJ14: 0.24741666 | BK14: 0.22397796 | BL14: 0.060783998 | BM14: 0.034064653 | BN14: 0.056826106 | BO14: 0.063716431
A15: 1980 | B15: 0.019451725 | C15: 0.015278125 | D15: 0.010702197 | E15: 0.01899095 | F15: 0.0082095708 | G15: 0.045682856 | H15: 0.020334373 | I15: 0.020655663 | J15: 0.1034894 | K15: 0.0053555913 | L15: 0.018036365 | M15: 0.013288414 | N15: 0.025558226 | O15: 0.010329948 | P15: 0.012628658 | Q15: 0.0075825768 | R15: 0.041091318 | S15: 0.085562901 | T15: 0.017956007 | U15: 0.017956007 | V15: 0.0058066084 | W15: 0.031050677 | X15: 0.036295231 | Y15: 0.055816486 | Z15: 0.008246694 | AA15: 0.027891873 | AB15: 0.021507361 | AC15: 0.045164906 | AD15: 0.0095085814 | AE15: 0.013082606 | AF15: 0.023635062 | AG15: 0.003904896 | AH15: 0.010676751 | AI15: 0.0042355689 | AJ15: 0.010676751 | AK15: 0.019094736 | AL15: 0.0015589621 | AM15: 0.014718921 | AN15: 0.010676751 | AO15: 0.0022841482 | AP15: 0.14479209 | AQ15: 0.030158109 | AR15: 0.030158109 | AS15: 0.030158109 | AT15: 0.030158109 | AU15: 0.052688277 | AV15: 0.030158109 | AW15: 0.030158109 | AX15: 0.030158109 | AY15: 0.030158109 | AZ15: 0.020334373 | BA15: 0.025328093 | BB15: 0.043371313 | BC15: 0.01324005 | BD15: 0.030703761 | BE15: 0.021832888 | BF15: 0.014911476 | BG15: 0.036875861 | BH15: 0.13330758 | BI15: 0.052852131 | BJ15: 0.26916477 | BK15: 0.24366578 | BL15: 0.066126956 | BM15: 0.037058961 | BN15: 0.061821163 | BO15: 0.069317152
A16: 1981 | B16: 0.019726492 | C16: 0.015655702 | D16: 0.010884168 | E16: 0.021488073 | F16: 0.0084368903 | G16: 0.042203511 | H16: 0.021787386 | I16: 0.020274144 | J16: 0.096239741 | K16: 0.0053253472 | L16: 0.019530524 | M16: 0.011885808 | N16: 0.025067117 | O16: 0.010941134 | P16: 0.012587859 | Q16: 0.0074495801 | R16: 0.041732583 | S16: 0.091810131 | T16: 0.018236225 | U16: 0.018236225 | V16: 0.0054102091 | W16: 0.033655186 | X16: 0.037447901 | Y16: 0.056824334 | Z16: 0.0083956001 | AA16: 0.035240126 | AB16: 0.021721207 | AC16: 0.057063826 | AD16: 0.012013665 | AE16: 0.015919541 | AF16: 0.029861837 | AG16: 0.0041839241 | AH16: 0.011439669 | AI16: 0.0045382256 | AJ16: 0.011439669 | AK16: 0.020459169 | AL16: 0.0016703593 | AM16: 0.015770676 | AN16: 0.011439669 | AO16: 0.0021469338 | AP16: 0.13609407 | AQ16: 0.028346437 | AR16: 0.028346437 | AS16: 0.028346437 | AT16: 0.028346437 | AU16: 0.049523163 | AV16: 0.028346437 | AW16: 0.028346437 | AX16: 0.028346437 | AY16: 0.028346437 | AZ16: 0.021787386 | BA16: 0.027137936 | BB16: 0.048605977 | BC16: 0.011870283 | BD16: 0.030538673 | BE16: 0.022883434 | BF16: 0.01597699 | BG16: 0.034660637 | BH16: 0.12529947 | BI16: 0.049677174 | BJ16: 0.25299538 | BK16: 0.22902818 | BL16: 0.062154547 | BM16: 0.034832738 | BN16: 0.058107413 | BO16: 0.065153099
... A60: 2025 | B60: 0.018651476 | C60: 0.007008775 | D60: 0.0081716007 | E60: 0.014482799 | F60: 0.017137525 | G60: 0.013646859 | H60: 0.0094876431 | I60: 0.02847393 | J60: 0.036577606 | K60: 0.0043768186 | L60: 0.004917669 | M60: 0.0085029722 | N60: 0.0076710753 | O60: 0.0084496404 | P60: 0.0056473102 | Q60: 0.0061908697 | R60: 0.010819084 | S60: 0.023740975 | T60: 0.0084442274 | U60: 0.0084442274 | V60: 0.0041432267 | W60: 0.025891429 | X60: 0.01877137 | Y60: 0.039633323 | Z60: 0.0067648312 | AA60: 0.017890777 | AB60: 0.029903326 | AC60: 0.027919538 | AD60: 0.013067568 | AE60: 0.0060183207 | AF60: 0.017474685 | AG60: 0.0015020199 | AH60: 0.013630451 | AI60: 0.0022474396 | AJ60: 0.013630451 | AK60: 0.02527143 | AL60: 0.0064296319 | AM60: 0.025280871 | AN60: 0.013630451 | AO60: 0.00023565584 | AP60: 0.027722499 | AQ60: 0.014453797 | AR60: 0.014453797 | AS60: 0.014453797 | AT60: 0.014453797 | AU60: 0.010884573 | AV60: 0.014453797 | AW60: 0.014453797 | AX60: 0.014453797 | AY60: 0.014453797 | AZ60: 0.0094876431 | BA60: 0.010214292 | BB60: 0.036767406 | BC60: 0.0028970962 | BD60: 0.0026503593 | BE60: 0.0015878631 | BF60: 0.029430582 | BG60: 0.027871396 | BH60: 0.033523218 | BI60: 0.044833936 | BJ60: 0.16988267 | BK60: 0.12173602 | BL60: 0.035761226 | BM60: 0.013757994 | BN60: 0.036606674 | BO60: 0.033427735
A61: 2026
A62: 2027
A63: 2028
A64: 2029
A65: 2030
A66: 2031
A67: 2032
A68: 2033
A69: 2034
A70: 2035
A71: 2036
A72: 2037
... A135: 2100

Sheet O2a
A1: ="Data Series on A-Matrix Coefficients: Total Housing Services Inputs used by " & ReadMe!D1 & " Sector as Share of " & ReadMe!D1 & " Output (current price MER)." -> Data Series on A-Matrix Coefficients: Total Housing Services Inputs used by "Manufacturing" Sector as Share of "Manufacturing" Output (current price MER).
A4: Year | B4: World | C4: Europe | D4: North America/ Oceania | E4: Latin America | F4: Middle East/North Africa | G4: Subsaharan Africa | H4: Russia/ Central Asia | I4: East Asia | J4: South & South-East Asia | K4: DE | L4: DK | M4: ES | N4: FR | O4: GB | P4: IT | Q4: NL | R4: NO | S4: SE | T4: OC | U4: QM | V4: US | W4: CA | X4: AU | Y4: NZ | Z4: OH | AA4: AR | AB4: BR | AC4: CL | AD4: CO | AE4: MX | AF4: OD | AG4: AE | AH4: DZ | AI4: EG | AJ4: IR | AK4: MA | AL4: SA | AM4: TR | AN4: OE | AO4: CD | AP4: CI | AQ4: ET | AR4: KE | AS4: ML | AT4: NE | AU4: NG | AV4: RW | AW4: SD | AX4: ZA | AY4: OJ | AZ4: RU | BA4: OA | BB4: CN | BC4: JP | BD4: KR | BE4: TW | BF4: OB | BG4: BD | BH4: IN | BI4: ID | BJ4: MM | BK4: PK | BL4: PH | BM4: TH | BN4: VN | BO4: OI
A5: 1970 | B5: 0.0028109762 | C5: 0.0027090058 | D5: 0.0035428016 | E5: 0.0017539451 | F5: 0.0018868171 | G5: 0.0026438976 | H5: 0.0032332265 | I5: 0.0019851809 | J5: 0.00053988283 | K5: 0.0039534902 | L5: 0.0048676378 | M5: 0.00047707565 | N5: 0.0023182348 | O5: 0.00081623274 | P5: 0.0030705772 | Q5: 0.0029144342 | R5: 0.004151405 | S5: 0.0033305319 | T5: 0.0029610369 | U5: 0.0029610369 | V5: 0.0038507113 | W5: 0.001530649 | X5: 0.00065788042 | Y5: 0.0086922863 | Z5: 0.0036763518 | AA5: 4.327788e-05 | AB5: 9.4519342e-06 | AC5: 0.0049161205 | AD5: 0.00012161758 | AE5: 0.0029416294 | AF5: 0.0011250038 | AG5: 0.001728722 | AH5: 0.0023016742 | AI5: 0.00046446702 | AJ5: 0.0023016742 | AK5: 0.00043114455 | AL5: 0.00036520912 | AM5: 0.0026260926 | AN5: 0.0023016742 | AO5: 3.1488223e-05 | AP5: 0.0035286321 | AQ5: 0.0056956889 | AR5: 0.0056956889 | AS5: 0.0056956889 | AT5: 0.0056956889 | AU5: 0.00022209125 | AV5: 0.0056956889 | AW5: 0.0056956889 | AX5: 0.0056956889 | AY5: 0.0056956889 | AZ5: 0.0032332265 | BA5: 0.0024225573 | BB5: 0.00080197776 | BC5: 0.0024626679 | BD5: 0.00043082225 | BE5: 0.00079905678 | BF5: 0.0018988777 | BG5: 0.00082230408 | BH5: 2.7695662e-05 | BI5: 0.0013269231 | BJ5: 0.00055784872 | BK5: 0.0013566738 | BL5: 0.0014896462 | BM5: 0.00046080017 | BN5: 0.00077997139 | BO5: 0.0015324617
A6: 1971 | B6: 0.0029522211 | C6: 0.0029033683 | D6: 0.0035315251 | E6: 0.0019220032 | F6: 0.0020688442 | G6: 0.0026795417 | H6: 0.0036523098 | I6: 0.0022114015 | J6: 0.00050663553 | K6: 0.0043288281 | L6: 0.0052891627 | M6: 0.00048677896 | N6: 0.002401538 | O6: 0.00084812808 | P6: 0.0032526008 | Q6: 0.0030019366 | R6: 0.0043554354 | S6: 0.0034058765 | T6: 0.0031065639 | U6: 0.0031065639 | V6: 0.0038482724 | W6: 0.0015709637 | X6: 0.00059625325 | Y6: 0.0087321123 | Z6: 0.003693196 | AA6: 4.6368839e-05 | AB6: 9.6591116e-06 | AC6: 0.0052672357 | AD6: 0.00013030366 | AE6: 0.003279537 | AF6: 0.0012053529 | AG6: 0.0019527949 | AH6: 0.0026000119 | AI6: 0.00052467015 | AJ6: 0.0026000119 | AK6: 0.0004870285 | AL6: 0.00041254668 | AM6: 0.0029664806 | AN6: 0.0026000119 | AO6: 3.2535522e-05 | AP6: 0.0036459944 | AQ6: 0.0058851276 | AR6: 0.0058851276 | AS6: 0.0058851276 | AT6: 0.0058851276 | AU6: 0.00022947801 | AV6: 0.0058851276 | AW6: 0.0058851276 | AX6: 0.0058851276 | AY6: 0.0058851276 | AZ6: 0.0036523098 | BA6: 0.0027365635 | BB6: 0.00083828407 | BC6: 0.0027945422 | BD6: 0.00043104233 | BE6: 0.00079305342 | BF6: 0.0021450058 | BG6: 0.00084965393 | BH6: 2.861682e-05 | BI6: 0.0013710566 | BJ6: 0.00057640278 | BK6: 0.0014017968 | BL6: 0.0015391919 | BM6: 0.00047612639 | BN6: 0.00080591325 | BO6: 0.0015834314
A7: 1972 | B7: 0.0030269487 | C7: 0.0030370892 | D7: 0.0034300981 | E7: 0.0019130896 | F7: 0.0022890839 | G7: 0.0024915116 | H7: 0.0039744288 | I7: 0.0023520465 | J7: 0.00049076003 | K7: 0.0045412021 | L7: 0.0054884577 | M7: 0.00046917728 | N7: 0.0024634611 | O7: 0.00086662795 | P7: 0.0034515845 | Q7: 0.0031258764 | R7: 0.0045457145 | S7: 0.0036443148 | T7: 0.0032422827 | U7: 0.0032422827 | V7: 0.0037401849 | W7: 0.0015382746 | X7: 0.00058078374 | Y7: 0.0085013343 | Z7: 0.0035955898 | AA7: 4.8763289e-05 | AB7: 9.5725856e-06 | AC7: 0.0055392317 | AD7: 0.00013703244 | AE7: 0.0036317299 | AF7: 0.0012675964 | AG7: 0.0021250236 | AH7: 0.0028293224 | AI7: 0.00057094394 | AJ7: 0.0028293224 | AK7: 0.00052998245 | AL7: 0.00044893163 | AM7: 0.0032281122 | AN7: 0.0028293224 | AO7: 3.1849379e-05 | AP7: 0.0035691039 | AQ7: 0.0057610159 | AR7: 0.0057610159 | AS7: 0.0057610159 | AT7: 0.0057610159 | AU7: 0.00022463854 | AV7: 0.0057610159 | AW7: 0.0057610159 | AX7: 0.0057610159 | AY7: 0.0057610159 | AZ7: 0.0039744288 | BA7: 0.0029779173 | BB7: 0.00063377237 | BC7: 0.0030012371 | BD7: 0.00040461605 | BE7: 0.0007534833 | BF7: 0.0023341867 | BG7: 0.00083173554 | BH7: 2.8013319e-05 | BI7: 0.0013421423 | BJ7: 0.000564247 | BK7: 0.0013722342 | BL7: 0.0015067318 | BM7: 0.00046608534 | BN7: 0.00078891731 | BO7: 0.0015500383
A8: 1973 | B8: 0.0030683876 | C8: 0.0031470545 | D8: 0.0035535909 | E8: 0.0017638767 | F8: 0.002297573 | G8: 0.0025013092 | H8: 0.0039943317 | I8: 0.0023742681 | J8: 0.00049813062 | K8: 0.0047377463 | L8: 0.0057745546 | M8: 0.00047733811 | N8: 0.0025740705 | O8: 0.00096216457 | P8: 0.0032136068 | Q8: 0.0032818235 | R8: 0.0046921307 | S8: 0.0035277526 | T8: 0.0033467157 | U8: 0.0033467157 | V8: 0.00393585 | W8: 0.0014735066 | X8: 0.00053698226 | Y8: 0.0087971245 | Z8: 0.0037206925 | AA8: 4.7642083e-05 | AB8: 9.1200882e-06 | AC8: 0.0054118691 | AD8: 0.00013388167 | AE8: 0.0036931155 | AF8: 0.0012384508 | AG8: 0.0021356651 | AH8: 0.002843491 | AI8: 0.00057380308 | AJ8: 0.002843491 | AK8: 0.00053263646 | AL8: 0.00045117977 | AM8: 0.0032442778 | AN8: 0.002843491 | AO8: 2.9731096e-05 | AP8: 0.0033317249 | AQ8: 0.0053778542 | AR8: 0.0053778542 | AS8: 0.0053778542 | AT8: 0.0053778542 | AU8: 0.00020969796 | AV8: 0.0053778542 | AW8: 0.0053778542 | AX8: 0.0053778542 | AY8: 0.0053778542 | AZ8: 0.0039943317 | BA8: 0.00299283 | BB8: 0.00057622784 | BC8: 0.0029872252 | BD8: 0.000361942 | BE8: 0.00076254742 | BF8: 0.0023458757 | BG8: 0.0007764173 | BH8: 2.615017e-05 | BI8: 0.0012528772 | BJ8: 0.00052671926 | BK8: 0.0012809677 | BL8: 0.00140652 | BM8: 0.00043508628 | BN8: 0.00073644689 | BO8: 0.0014469462
A9: 1974 | B9: 0.0029526796 | C9: 0.0031538088 | D9: 0.0033313003 | E9: 0.0015272955 | F9: 0.0021438455 | G9: 0.0018341475 | H9: 0.0040513091 | I9: 0.0024370075 | J9: 0.00045651259 | K9: 0.0047427682 | L9: 0.0060609683 | M9: 0.0004684791 | N9: 0.0026078007 | O9: 0.0010697147 | P9: 0.0030492304 | Q9: 0.0033996349 | R9: 0.0046380468 | S9: 0.0029898621 | T9: 0.0033081397 | U9: 0.0033081397 | V9: 0.0037174946 | W9: 0.0013648712 | X9: 0.00051319846 | Y9: 0.0083052709 | Z9: 0.0035126659 | AA9: 4.3923033e-05 | AB9: 8.7524769e-06 | AC9: 0.0049894061 | AD9: 0.00012343056 | AE9: 0.003324489 | AF9: 0.0011417745 | AG9: 0.0021661295 | AH9: 0.0028840521 | AI9: 0.00058198814 | AJ9: 0.0028840521 | AK9: 0.00054023429 | AL9: 0.00045761565 | AM9: 0.003290556 | AN9: 0.0028840521 | AO9: 2.464528e-05 | AP9: 0.0027617984 | AQ9: 0.0044579158 | AR9: 0.0044579158 | AS9: 0.0044579158 | AT9: 0.0044579158 | AU9: 0.00017382693 | AV9: 0.0044579158 | AW9: 0.0044579158 | AX9: 0.0044579158 | AY9: 0.0044579158 | AZ9: 0.0040513091 | BA9: 0.0030355214 | BB9: 0.00061054202 | BC9: 0.0030289393 | BD9: 0.00038858091 | BE9: 0.0008729179 | BF9: 0.0023793386 | BG9: 0.00064360297 | BH9: 2.1676909e-05 | BI9: 0.0010385594 | BJ9: 0.0004366184 | BK9: 0.0010618447 | BL9: 0.00116592 | BM9: 0.00036066021 | BN9: 0.00061046992 | BO9: 0.0011994309
A10: 1975 | B10: 0.0031141858 | C10: 0.0033008604 | D10: 0.0036287601 | E10: 0.0019138517 | F10: 0.0022834037 | G10: 0.0018117183 | H10: 0.004160594 | I10: 0.0024229677 | J10: 0.00050554578 | K10: 0.0049061812 | L10: 0.0060264217 | M10: 0.00056830304 | N10: 0.0026872216 | O10: 0.00092792381 | P10: 0.0035723009 | Q10: 0.0037343319 | R10: 0.0048743272 | S10: 0.003239528 | T10: 0.0034766695 | U10: 0.0034766695 | V10: 0.0040839946 | W10: 0.0014241212 | X10: 0.0004207883 | Y10: 0.0090551072 | Z10: 0.0038298048 | AA10: 4.8219469e-05 | AB10: 9.8076193e-06 | AC10: 0.0054774568 | AD10: 0.00013550422 | AE10: 0.0035958744 | AF10: 0.0012534599 | AG10: 0.0022245613 | AH10: 0.00296185 | AI10: 0.00059768738 | AJ10: 0.00296185 | AK10: 0.00055480722 | AL10: 0.00046995992 | AM10: 0.0033793194 | AN10: 0.00296185 | AO10: 2.6520405e-05 | AP10: 0.0029719286 | AQ10: 0.0047970943 | AR10: 0.0047970943 | AS10: 0.0047970943 | AT10: 0.0047970943 | AU10: 0.00018705247 | AV10: 0.0047970943 | AW10: 0.0047970943 | AX10: 0.0047970943 | AY10: 0.0047970943 | AZ10: 0.004160594 | BA10: 0.0031174052 | BB10: 0.00060963687 | BC10: 0.0031540972 | BD10: 0.00040966074 | BE10: 0.00094329337 | BF10: 0.0024435217 | BG10: 0.00069257122 | BH10: 2.3326187e-05 | BI10: 0.0011175777 | BJ10: 0.00046983832 | BK10: 0.0011426347 | BL10: 0.0012546285 | BM10: 0.00038810088 | BN10: 0.00065691725 | BO10: 0.001290689
A11: 1976 | B11: 0.0029954141 | C11: 0.0033602262 | D11: 0.0032976888 | E11: 0.0018031299 | F11: 0.0021446426 | G11: 0.0016995315 | H11: 0.0039954136 | I11: 0.0023699659 | J11: 0.00056388489 | K11: 0.0049541662 | L11: 0.0062790633 | M11: 0.00057988056 | N11: 0.0027100661 | O11: 0.00095813094 | P11: 0.003278829 | Q11: 0.0038828524 | R11: 0.0049041253 | S11: 0.0031775157 | T11: 0.0034979233 | U11: 0.0034979233 | V11: 0.0036842905 | W11: 0.0015094031 | X11: 0.00038613619 | Y11: 0.008399156 | Z11: 0.003552374 | AA11: 4.9683014e-05 | AB11: 1.0279172e-05 | AC11: 0.0056437071 | AD11: 0.000139617 | AE11: 0.0037134021 | AF11: 0.0012915045 | AG11: 0.0021362436 | AH11: 0.0028442611 | AI11: 0.0005739585 | AJ11: 0.0028442611 | AK11: 0.00053278073 | AL11: 0.00045130197 | AM11: 0.0032451565 | AN11: 0.0028442611 | AO11: 2.7358531e-05 | AP11: 0.0030658506 | AQ11: 0.0049486972 | AR11: 0.0049486972 | AS11: 0.0049486972 | AT11: 0.0049486972 | AU11: 0.0001929639 | AV11: 0.0049486972 | AW11: 0.0049486972 | AX11: 0.0049486972 | AY11: 0.0049486972 | AZ11: 0.0039954136 | BA11: 0.0029936406 | BB11: 0.0006263895 | BC11: 0.0030054745 | BD11: 0.00046040891 | BE11: 0.00097116499 | BF11: 0.0023465111 | BG11: 0.00071445859 | BH11: 2.4063365e-05 | BI11: 0.0011528966 | BJ11: 0.00048468665 | BK11: 0.0011787455 | BL11: 0.0012942786 | BM11: 0.00040036605 | BN11: 0.00067767785 | BO11: 0.0013314787
A12: 1977 | B12: 0.0029969446 | C12: 0.0034156285 | D12: 0.0032455207 | E12: 0.0015575207 | F12: 0.0022116419 | G12: 0.0016234792 | H12: 0.0041216507 | I12: 0.0024309239 | J12: 0.00053664429 | K12: 0.0050583659 | L12: 0.0065441973 | M12: 0.00061303906 | N12: 0.0027154189 | O12: 0.0009664461 | P12: 0.0033516316 | Q12: 0.0040813302 | R12: 0.0049417832 | S12: 0.0032048644 | T12: 0.0035247832 | U12: 0.0035247832 | V12: 0.0035696481 | W12: 0.0015959249 | X12: 0.00039224195 | Y12: 0.0082466625 | Z12: 0.0034878778 | AA12: 4.8310334e-05 | AB12: 1.0799865e-05 | AC12: 0.0054877785 | AD12: 0.00013575956 | AE12: 0.0032751734 | AF12: 0.0012558219 | AG12: 0.0022037393 | AH12: 0.002934127 | AI12: 0.00059209302 | AJ12: 0.002934127 | AK12: 0.00054961422 | AL12: 0.00046556109 | AM12: 0.0033476889 | AN12: 0.002934127 | AO12: 2.63129e-05 | AP12: 0.0029486752 | AQ12: 0.0047595601 | AR12: 0.0047595601 | AS12: 0.0047595601 | AT12: 0.0047595601 | AU12: 0.00018558891 | AV12: 0.0047595601 | AW12: 0.0047595601 | AX12: 0.0047595601 | AY12: 0.0047595601 | AZ12: 0.0041216507 | BA12: 0.0030882262 | BB12: 0.00062207707 | BC12: 0.0031034141 | BD12: 0.00053683217 | BE12: 0.00099290753 | BF12: 0.0024206503 | BG12: 0.00068715229 | BH12: 2.3143674e-05 | BI12: 0.0011088334 | BJ12: 0.00046616214 | BK12: 0.0011336943 | BL12: 0.0012448118 | BM12: 0.00038506424 | BN12: 0.0006517773 | BO12: 0.0012805902
A13: 1978 | B13: 0.0030740311 | C13: 0.0035530601 | D13: 0.0034167765 | E13: 0.0014907609 | F13: 0.0022407205 | G13: 0.0015478757 | H13: 0.0042015281 | I13: 0.0024765283 | J13: 0.00046984121 | K13: 0.0051062439 | L13: 0.0068347346 | M13: 0.00060850546 | N13: 0.0030676237 | O13: 0.00095258179 | P13: 0.0036396918 | Q13: 0.0044133209 | R13: 0.0053811591 | S13: 0.0034667619 | T13: 0.003838173 | U13: 0.003838173 | V13: 0.003765075 | W13: 0.0016041185 | X13: 0.00049008219 | Y13: 0.0085990648 | Z13: 0.0036369243 | AA13: 4.8844503e-05 | AB13: 1.1340603e-05 | AC13: 0.0055484571 | AD13: 0.00013726066 | AE13: 0.0030150446 | AF13: 0.0012697075 | AG13: 0.0022464477 | AH13: 0.0029909902 | AI13: 0.00060356774 | AJ13: 0.0029909902 | AK13: 0.00056026571 | AL13: 0.00047458364 | AM13: 0.003412567 | AN13: 0.0029909902 | AO13: 2.4639009e-05 | AP13: 0.0027610957 | AQ13: 0.0044567815 | AR13: 0.0044567815 | AS13: 0.0044567815 | AT13: 0.0044567815 | AU13: 0.0001737827 | AV13: 0.0044567815 | AW13: 0.0044567815 | AX13: 0.0044567815 | AY13: 0.0044567815 | AZ13: 0.0042015281 | BA13: 0.0031480759 | BB13: 0.00059692724 | BC13: 0.0031560735 | BD13: 0.00058577154 | BE13: 0.00099341199 | BF13: 0.0024675624 | BG13: 0.00064343921 | BH13: 2.1671393e-05 | BI13: 0.0010382951 | BJ13: 0.00043650731 | BK13: 0.0010615746 | BL13: 0.0011656233 | BM13: 0.00036056844 | BN13: 0.00061031459 | BO13: 0.0011991257
A14: 1979 | B14: 0.0030832908 | C14: 0.00368954 | D14: 0.003516063 | E14: 0.0013766663 | F14: 0.0021694907 | G14: 0.0014762108 | H14: 0.0040316428 | I14: 0.0023315268 | J14: 0.00043020671 | K14: 0.0054364251 | L14: 0.0071265596 | M14: 0.00062409994 | N14: 0.0034453979 | O14: 0.0010029422 | P14: 0.0034833173 | Q14: 0.0043395796 | R14: 0.005802071 | S14: 0.0033638932 | T14: 0.0041383933 | U14: 0.0041383933 | V14: 0.0038751641 | W14: 0.0015037581 | X14: 0.00063586737 | Y14: 0.008729261 | Z14: 0.00369199 | AA14: 4.7841494e-05 | AB14: 1.1547946e-05 | AC14: 0.005434521 | AD14: 0.00013444205 | AE14: 0.002609789 | AF14: 0.0012436344 | AG14: 0.0021556144 | AH14: 0.002870052 | AI14: 0.00057916298 | AJ14: 0.002870052 | AK14: 0.00053761183 | AL14: 0.00045539424 | AM14: 0.0032745826 | AN14: 0.002870052 | AO14: 2.3105861e-05 | AP14: 0.0025892882 | AQ14: 0.0041794609 | AR14: 0.0041794609 | AS14: 0.0041794609 | AT14: 0.0041794609 | AU14: 0.00016296917 | AV14: 0.0041794609 | AW14: 0.0041794609 | AX14: 0.0041794609 | AY14: 0.0041794609 | AZ14: 0.0040316428 | BA14: 0.003020786 | BB14: 0.00052271809 | BC14: 0.0030452727 | BD14: 0.0006286953 | BE14: 0.0010813136 | BF14: 0.0023677886 | BG14: 0.00060340159 | BH14: 2.0322904e-05 | BI14: 0.00097368785 | BJ14: 0.0004093459 | BK14: 0.00099551872 | BL14: 0.0010930931 | BM14: 0.00033813228 | BN14: 0.00057233813 | BO14: 0.0011245108
A15: 1980 | B15: 0.003019301 | C15: 0.0038350097 | D15: 0.0032353348 | E15: 0.0013368715 | F15: 0.0019126129 | G15: 0.001423583 | H15: 0.0040410569 | I15: 0.0023180513 | J15: 0.00040516294 | K15: 0.0058384707 | L15: 0.0071249381 | M15: 0.00064835709 | N15: 0.0036690963 | O15: 0.001100189 | P15: 0.0033505992 | Q15: 0.0044436235 | R15: 0.0061330835 | S15: 0.0033262751 | T15: 0.0043744917 | U15: 0.0043744917 | V15: 0.0035634664 | W15: 0.0015195276 | X15: 0.00077182056 | Y15: 0.0082030511 | Z15: 0.0034694326 | AA15: 4.7405433e-05 | AB15: 1.1968911e-05 | AC15: 0.0053849869 | AD15: 0.00013321665 | AE15: 0.0022319065 | AF15: 0.0012322991 | AG15: 0.0021606479 | AH15: 0.0028767538 | AI15: 0.00058051537 | AJ15: 0.0028767538 | AK15: 0.00053886719 | AL15: 0.00045645762 | AM15: 0.003282229 | AN15: 0.0028767538 | AO15: 2.1336368e-05 | AP15: 0.0023909953 | AQ15: 0.0038593894 | AR15: 0.0038593894 | AS15: 0.0038593894 | AT15: 0.0038593894 | AU15: 0.00015048867 | AV15: 0.0038593894 | AW15: 0.0038593894 | AX15: 0.0038593894 | AY15: 0.0038593894 | AZ15: 0.0040410569 | BA15: 0.0030278398 | BB15: 0.00051695799 | BC15: 0.0030450075 | BD15: 0.00081411358 | BE15: 0.0010841303 | BF15: 0.0023733175 | BG15: 0.00055719188 | BH15: 1.8766535e-05 | BI15: 0.00089912088 | BJ15: 0.00037799737 | BK15: 0.0009192799 | BL15: 0.0010093818 | BM15: 0.00031223743 | BN15: 0.00052850733 | BO15: 0.0010383935
A16: 1981 | B16: 0.0030994813 | C16: 0.0039973779 | D16: 0.0033800848 | E16: 0.0016912697 | F16: 0.0019469384 | G16: 0.0016447033 | H16: 0.0041757924 | I16: 0.002419612 | J16: 0.00045904872 | K16: 0.0061128214 | L16: 0.0074531928 | M16: 0.00066951097 | N16: 0.0037790404 | O16: 0.0013020444 | P16: 0.0034474336 | Q16: 0.00436493 | R16: 0.0063330252 | S16: 0.0036656258 | T16: 0.0045171024 | U16: 0.0045171024 | V16: 0.0037401062 | W16: 0.0016239472 | X16: 0.00087196524 | Y16: 0.0086544781 | Z16: 0.003660361 | AA16: 4.5413987e-05 | AB16: 1.1099227e-05 | AC16: 0.00515877 | AD16: 0.00012762037 | AE16: 0.0026386002 | AF16: 0.0011805316 | AG16: 0.0022326875 | AH16: 0.0029726695 | AI16: 0.0005998707 | AJ16: 0.0029726695 | AK16: 0.0005568339 | AL16: 0.00047167666 | AM16: 0.0033916639 | AN16: 0.0029726695 | AO16: 2.3138756e-05 | AP16: 0.0025929744 | AQ16: 0.0041854111 | AR16: 0.0041854111 | AS16: 0.0041854111 | AT16: 0.0041854111 | AU16: 0.00016320119 | AV16: 0.0041854111 | AW16: 0.0041854111 | AX16: 0.0041854111 | AY16: 0.0041854111 | AZ16: 0.0041757924 | BA16: 0.0031287929 | BB16: 0.00053934706 | BC16: 0.0031504318 | BD16: 0.0007436274 | BE16: 0.0011743431 | BF16: 0.0024524478 | BG16: 0.00060426063 | BH16: 2.0351837e-05 | BI16: 0.00097507406 | BJ16: 0.00040992867 | BK16: 0.000996936 | BL16: 0.0010946493 | BM16: 0.00033861367 | BN16: 0.00057315295 | BO16: 0.0011261117
... A60: 2025 | B60: 0.0040663665 | C60: 0.0081008893 | D60: 0.007753506 | E60: 0.0023360228 | F60: 0.0030441391 | G60: 0.006188351 | H60: 0.0046354799 | I60: 0.00066765973 | J60: 0.0013699863 | K60: 0.012464082 | L60: 0.0082106951 | M60: 0.0077098746 | N60: 0.0067379464 | O60: 0.0027085595 | P60: 0.0074141033 | Q60: 0.0056105475 | R60: 0.015659311 | S60: 0.0074348387 | T60: 0.0073309223 | U60: 0.0073309223 | V60: 0.0086679332 | W60: 0.0039987138 | X60: 0.0036060001 | Y60: 0.0084173857 | Z60: 0.008078896 | AA60: 4.97589e-06 | AB60: 1.6862139e-05 | AC60: 0.005371843 | AD60: 0.0018518246 | AE60: 0.0035940794 | AF60: 0.0017601597 | AG60: 0.00015204383 | AH60: 0.0046103994 | AI60: 0.0017918332 | AJ60: 0.0046103994 | AK60: 0.00070556981 | AL60: 0.0012951738 | AM60: 0.0040172961 | AN60: 0.0046103994 | AO60: 1.7204565e-05 | AP60: 0.018149255 | AQ60: 0.0057430968 | AR60: 0.0057430968 | AS60: 0.0057430968 | AT60: 0.0057430968 | AU60: 0.007217547 | AV60: 0.0057430968 | AW60: 0.0057430968 | AX60: 0.0057430968 | AY60: 0.0057430968 | AZ60: 0.0046354799 | BA60: 0.0041730026 | BB60: 0.00017394872 | BC60: 0.0021385498 | BD60: 0.001903173 | BE60: 0.0030073225 | BF60: 0.00060976711 | BG60: 0.0010061108 | BH60: 0.00069138353 | BI60: 0.00063988824 | BJ60: 0.001079639 | BK60: 0.0013616518 | BL60: 0.011122746 | BM60: 0.00064489162 | BN60: 0.00066519027 | BO60: 0.0011108726
A61: 2026
A62: 2027
A63: 2028
A64: 2029
A65: 2030
A66: 2031
A67: 2032
A68: 2033
A69: 2034
A70: 2035
A71: 2036
A72: 2037
... A135: 2100

Sheet O2b
A1: ="Data series on A-Matrix Coefficients: Total Construction Inputs used by " & ReadMe!D1 & " Sector as Share of " & ReadMe!D1 & " Output (current price MER)." -> Data series on A-Matrix Coefficients: Total Construction Inputs used by "Manufacturing" Sector as Share of "Manufacturing" Output (current price MER).
A4: Year | B4: World | C4: Europe | D4: North America/ Oceania | E4: Latin America | F4: Middle East/North Africa | G4: Subsaharan Africa | H4: Russia/ Central Asia | I4: East Asia | J4: South & South-East Asia | K4: DE | L4: DK | M4: ES | N4: FR | O4: GB | P4: IT | Q4: NL | R4: NO | S4: SE | T4: OC | U4: QM | V4: US | W4: CA | X4: AU | Y4: NZ | Z4: OH | AA4: AR | AB4: BR | AC4: CL | AD4: CO | AE4: MX | AF4: OD | AG4: AE | AH4: DZ | AI4: EG | AJ4: IR | AK4: MA | AL4: SA | AM4: TR | AN4: OE | AO4: CD | AP4: CI | AQ4: ET | AR4: KE | AS4: ML | AT4: NE | AU4: NG | AV4: RW | AW4: SD | AX4: ZA | AY4: OJ | AZ4: RU | BA4: OA | BB4: CN | BC4: JP | BD4: KR | BE4: TW | BF4: OB | BG4: BD | BH4: IN | BI4: ID | BJ4: MM | BK4: PK | BL4: PH | BM4: TH | BN4: VN | BO4: OI
A5: 1970 | B5: 0.0034939128 | C5: 0.0038383135 | D5: 0.0045267718 | E5: 0.00069205768 | F5: 0.00045716562 | G5: 0.0012427419 | H5: 0.0033136115 | I5: 0.0010282659 | J5: 0.011767811 | K5: 0.0023346232 | L5: 0.0034316745 | M5: 0.0057184182 | N5: 0.0033313466 | O5: 0.0032225317 | P5: 0.0053282418 | Q5: 0.0084105856 | R5: 0.0023850343 | S5: 0.0072286592 | T5: 0.0046605576 | U5: 0.0046605576 | V5: 0.0027737309 | W5: 0.0057469729 | X5: 0.033319066 | Y5: 0.0033479309 | Z5: 0.0056464552 | AA5: 7.9697836e-05 | AB5: 0.00028901264 | AC5: 0.001516473 | AD5: 9.0559947e-05 | AE5: 0.0010580179 | AF5: 0.00039786895 | AG5: 0.0036536883 | AH5: 0.0008582486 | AI5: 0.00011489608 | AJ5: 0.0008582486 | AK5: 0.00020776404 | AL5: 0.00077071219 | AM5: 0.00017764298 | AN5: 0.0008582486 | AO5: 0.0034370575 | AP5: 0.00049055005 | AQ5: 0.0019755404 | AR5: 0.0019755404 | AS5: 0.0019755404 | AT5: 0.0019755404 | AU5: 0.00035693186 | AV5: 0.0019755404 | AW5: 0.0019755404 | AX5: 0.0019755404 | AY5: 0.0019755404 | AZ5: 0.0033136115 | BA5: 0.0025569174 | BB5: 0 | BC5: 0.001351777 | BD5: 0.0025727383 | BE5: 0.0003307628 | BF5: 0.0010922453 | BG5: 0.0023997855 | BH5: 0.01882836 | BI5: 0.0055376846 | BJ5: 0.0019644722 | BK5: 0.001320812 | BL5: 0.0037562995 | BM5: 0.0045398034 | BN5: 0.00059121618 | BO5: 0.0081034014
A6: 1971 | B6: 0.0036202572 | C6: 0.0037332912 | D6: 0.0046696013 | E6: 0.00064433624 | F6: 0.00047552649 | G6: 0.0015442743 | H6: 0.0031385717 | I6: 0.00096693314 | J6: 0.015720979 | K6: 0.0025828085 | L6: 0.0034568273 | M6: 0.0059139223 | N6: 0.0031080776 | O6: 0.0028419485 | P6: 0.0047209326 | Q6: 0.0079356396 | R6: 0.0022653214 | S6: 0.0070956922 | T6: 0.0044266285 | U6: 0.0044266285 | V6: 0.002683286 | W6: 0.0059012444 | X6: 0.036453309 | Y6: 0.0037460294 | Z6: 0.0063178686 | AA6: 7.6992827e-05 | AB6: 0.00028281329 | AC6: 0.0014650027 | AD6: 8.748627e-05 | AE6: 0.00098072657 | AF6: 0.00038436496 | AG6: 0.0034606841 | AH6: 0.00081291207 | AI6: 0.00010882676 | AJ6: 0.00081291207 | AK6: 0.00019678902 | AL6: 0.00072999972 | AM6: 0.00016825909 | AN6: 0.00081291207 | AO6: 0.0043243688 | AP6: 0.00061719053 | AQ6: 0.0024855462 | AR6: 0.0024855462 | AS6: 0.0024855462 | AT6: 0.0024855462 | AU6: 0.00044907745 | AV6: 0.0024855462 | AW6: 0.0024855462 | AX6: 0.0024855462 | AY6: 0.0024855462 | AZ6: 0.0031385717 | BA6: 0.0024218496 | BB6: 0 | BC6: 0.0012902618 | BD6: 0.0020984407 | BE6: 0.00035344 | BF6: 0.001034548 | BG6: 0.0030193145 | BH6: 0.023689093 | BI6: 0.0069672942 | BJ6: 0.0024716206 | BK6: 0.001661793 | BL6: 0.0047260264 | BM6: 0.0057117998 | BN6: 0.00074384465 | BO6: 0.010195377
